Workbook

Sheet 03.10.25
A1: FABRIC OLD STOCK CUTTING
A3: No | B3: Item Code | C3: YEAR | D3: Description | E3: Customer | F3: Quantity | G3: Unit | H3: PO | I3: STYLE
A4: 1 | B4: TCF0130 | C4: 2024 | D4: 4.5OZ/T150-72.5" (OB26*OB26) #ALSCO WHITE | E4: TA CHIANG SPINNING | F4: 179 | G4: YARD | H4: 200995
A5: 2 | B5: TCF0525 | C5: 2024 | D5: 7.1OZ-64.5" (SD12*SD12) #MAG003 BLACK | E5: TA CHIANG SPINNING | F5: 856 | G5: YARD | H5: 5605 | I5: CP123,BLACK
A6: 3 | B6: TCF0362 | C6: 2024 | D6: 7.1OZ/SDHV-67" (SD12*OB12) NAVY/WHITE STRIPE | E6: TA CHIANG SPINNING | F6: 491 | G6: YARD | H6: SORD44542 | I6: AP154-NWP
A7: 4 | B7: TCF0717 | C7: 2024 | D7: 6.35OZ-91.5" (SD12*300D) NAVY BLUE-WPL | E7: TA CHIANG SPINNING | F7: 1002 | G7: YARD | H7: 201147 | I7: O1113KNBL
A8: 5 | B8: TCF0692 | C8: 2023 | D8: 6.35OZ-64.5" (SD12*300D) NAVY BLUE-WPL | E8: TA CHIANG SPINNING | F8: 1839 | G8: YARD | H8: 201146 | I8: O1113KNBL
A9: 6 | B9: TF0654 | C9: 2023 | D9: 6.35OZ-73" (SD12*300D) RED-WPL | E9: TA CHIANG SPINNING | F9: 446 | G9: YARD | H9: 200541 | I9: O1125GRED
E10: TOTAL: | F10: =SUM(F4:F9) -> 4813 | G10: YARD

Sheet 10.10.25 
A1: FABRIC OLD STOCK CUTTING
A3: No | B3: Item Code | C3: YEAR | D3: Description | E3: Customer | F3: Quantity | G3: Unit | H3: PO | I3: STYLE
A4: 1 | B4: TCF0027 | C4: 2024 | D4: 5.5OZ/SD135-66.5" (OB20*OB20) #AR WHITE | E4: TA CHIANG SPINNING | F4: 39 | G4: YARD | I4: DI-8VPU
A5: 2 | B5: TCF0744 | C5: 2024 | D5: 6.35OZ-109.5" (SD12*300D) NAVY BLUE-WPL | E5: TA CHIANG SPINNING | F5: 445 | G5: YARD | H5: 201147 | I5: O1113KNBL
A6: 3 | B6: TCF0362 | C6: 2024 | D6: 7.1OZ/SDHV-67" (SD12*OB12) NAVY/WHITE STRIPE | E6: TA CHIANG SPINNING | F6: 46 | G6: YARD | H6: RECUT
A7: 4 | B7: TCF0708 | C7: 2023 | D7: 6.35OZ-54" (SD12*300D) RED-WPL | E7: TA CHIANG SPINNING | F7: 200 | G7: YARD | H7: 200541 | I7: O1125GRED
A8: 5 | B8: TCF0745 | C8: 2023 | D8: 3.5OZ/SD170-67" (SD30*T100D) #AR L.PINK | E8: TA CHIANG SPINNING | F8: 5 | G8: YARD | H8: RECUT
A9: 6 | B9: TCF0293 | C9: 2023 | D9: 3.5OZ-SD170-67" (OB30*T100D) #AR WHITE | E9: TA CHIANG SPINNING | F9: 11 | G9: YARD | H9: A416222 | I9: GO2134
A10: 7 | B10: TCF0714 | C10: 2023 | D10: 6.35OZ-73" (SD12*300D) NAVY BLUE-WPL | E10: TA CHIANG SPINNING | F10: 50 | G10: YARD | H10: RECUT
A11: 8 | B11: TCF0182 | C11: 2020 | D11: 3.5OZ/SD170-67" (SD30*T75D) #AR YELLOW | E11: TA CHIANG SPINNING | F11: 10 | G11: YARD | H11: A416222 | I11: GSC978
A12: 9 | B12: TCF0144 | C12: 2018 | D12: 3.5OZ/SD170-66" (SD30*T75D) #AR APUA | E12: TA CHIANG SPINNING | F12: 1 | G12: YARD | H12: A416222 | I12: GO2134
A13: 10 | B13: TCF0040 | C13: 2015 | D13: 8.46OZ/FH21-64.5" (300D/1*SP12/1) YELLOW | E13: TA CHIANG SPINNING | F13: 2 | G13: YARD | H13: TES | I13: 6137-R
E15: TOTAL: | F15: =SUM(F4:F13) -> 809 | G15: YARD

Sheet 17.10.25 
A1: FABRIC OLD STOCK CUTTING
A3: No | B3: Item Code | C3: YEAR | D3: Description | E3: Customer | F3: Quantity | G3: Unit | H3: PO | I3: STYLE
A4: 1 | B4: TCF0124 | C4: 2024 | D4: 7.1OZ/SDHV-67" (SD12*OB12) NAVY/WHITE STRIPE | E4: TA CHIANG SPINNING | F4: 164 | G4: YARD | H4: SFOR1404
A5: 2 | B5: TCF0714 | C5: 2023 | D5: 6.35OZ-73" (SD12*300D) NAVY BLUE-WPL | E5: TA CHIANG SPINNING | F5: 69 | G5: YARD | H5: 201147-03 | I5: O1113KNBL
A6: 3 | B6: GRB0001 | C6: 2021 | D6: 7.1OZ/SDHV-55.5" (OB12*OB12) #ALSCO WHITE | E6: TA CHIANG SPINNING | F6: 149 | G6: YARD | H6: S26-1107 | I6: 6137-R
A7: 4 | B7: GRB0010 | C7: 2021 | D7: 7.1OZ/SDHV-92.5" (OB12*OB12) #ALSCO WHITE | E7: TA CHIANG SPINNING | F7: 606 | G7: YARD | H7: S26-1107 | I7: 6137-R
A8: 5 | B8: GRB0020 | C8: 2021 | D8: 7.1OZ/SDHV-121" (OB12*OB12) #ALSCO WHITE | E8: TA CHIANG SPINNING | F8: 128 | G8: YARD | H8: S26-1107 | I8: 6137-R
A9: 6 | B9: TCF0075 | C9: 2020 | D9: 3.5OZ/SD170-67" (SD30*T75D) #AR YELLOW | E9: TA CHIANG SPINNING | F9: 105 | G9: YARD | H9: SORD44550 | I9: P207-BG
A10: 7 | B10: TCF0040 | C10: 2015 | D10: 8.46OZ/FH21-64.5" (300D/1*SP12/1) YELLOW | E10: TA CHIANG SPINNING | F10: 1747 | G10: YARD | H10: S26-1107 | I10: 6137-R
E12: TOTAL: | F12: =SUM(F4:F10) -> 2968 | G12: YARD

Sheet 24.10.25 
A1: FABRIC OLD STOCK CUTTING
A3: No | B3: Item Code | C3: YEAR | D3: Description | E3: Customer | F3: Quantity | G3: Unit | H3: PO | I3: STYLE
A4: 1 | B4: TCF0362 | C4: 2024 | D4: 7.1OZ/SDHV-67" (SD12*OB12) NAVY/WHITE STRIPE | E4: TA CHIANG SPINNING | F4: 1120 | G4: YARD | H4: SORD44594 | I4: AP154-NWP
A5: 2 | B5: TCF0124 | C5: 2024 | D5: 7.1OZ/SDHV-121" (SD12*SD12) #0155 NAVY | E5: TA CHIANG SPINNING | F5: 165 | G5: YARD | H5: RECUT | I5: P207-N
A6: 3 | B6: TCF0027 | C6: 2024 | D6: 5.5OZ/SD135-66.5" (OB20*OB20) #AR WHITE | E6: TA CHIANG SPINNING | F6: 3731 | G6: YARD | H6: S26-1107 | I6: 6137-T
A7: 4 | B7: TCF0061 | C7: 2022 | D7: 7.1OZ/SDHV-111" (SD12*SD12) #0614 DARK GREY | E7: TA CHIANG SPINNING | F7: 123 | G7: YARD | H7: SORD44594 | I7: P207-GR
E9: TOTAL: | F9: =SUM(F4:F7) -> 5139 | G9: YARD

Sheet 31.10.25 
A1: FABRIC OLD STOCK CUTTING
A3: No | B3: Item Code | C3: YEAR | D3: Description | E3: Customer | F3: Quantity | G3: Unit | H3: PO | I3: STYLE
A4: 1 | B4: TCF0027 | C4: 2024 | D4: 5.5OZ/SD135-66.5" (OB20*OB20) #AR WHITE | E4: TA CHIANG SPINNING | F4: 201 | G4: YARD | H4: 201291 | I4: A1316WWHT
A5: 2 | B5: TCF0130 | C5: 2024 | D5: 4.5OZ/T150-72.5" (OB26*OB26) #ALSCO WHITE | E5: TA CHIANG SPINNING | F5: 171 | G5: YARD | H5: 201291 | I5: 2051GWHT
A6: 3 | B6: TCF0104 | C6: 2024 | D6: 5.5OZ/SD135-66.5" (SD20*SD20) #FW457 NAVY | E6: TA CHIANG SPINNING | F6: 252 | G6: YARD | H6: 201291 | I6: A1537BNBL
A7: 4 | B7: TCF0084 | C7: 2024 | D7: 5.5OZ/SD135-66.5" (OB20*OB20) #FW257 L.BLUE | E7: TA CHIANG SPINNING | F7: 123 | G7: YARD | H7: 201291 | I7: A1541GLBL
A8: 5 | B8: TCF0744 | C8: 2024 | D8: 6.35OZ-109.5" (SD12*300D) NAVY BLUE-WPL | E8: TA CHIANG SPINNING | F8: 20 | G8: YARD | H8: 201147 | I8: O1113KNBL
A9: 6 | B9: TCF0020 | C9: 2024 | D9: 5.5OZ/SD135-66.5" (OB20*OB20) #AR WHITE | E9: Australia Return | F9: 990 | G9: YARD | H9: S26-1107 | I9: 6137-T
A10: 7 | B10: TCF0007 | C10: 2022 | D10: 7.1OZ/SDHV-111" (SD12*SD12) #0614 DARK GREY | E10: Australia Return | F10: 1080 | G10: YARD | H10: SORD44594 | I10: P207-GR
E12: TOTAL: | F12: =SUM(F4:F10) -> 2837 | G12: YARD

Sheet 07.11.25 
A1: FABRIC OLD STOCK CUTTING
A3: No | B3: Item Code | C3: YEAR | D3: Description | E3: Customer | F3: Quantity | G3: Unit | H3: PO | I3: STYLE
A4: 1 | B4: TCF0525 | C4: 2024 | D4: 7.1OZ-64.5" (SD12*SD12) #MAG003 BLACK | E4: TA CHIANG SPINNING | F4: 75 | G4: YARD | H4: 5694 | I4: CP123BK
E7: TOTAL: | F7: =SUM(F4:F5) -> 75 | G7: YARD

Sheet 14.11.25 
A1: FABRIC OLD STOCK CUTTING
A3: No | B3: Item Code | C3: YEAR | D3: Description | E3: Customer | F3: Quantity | G3: Unit | H3: PO | I3: STYLE
A4: 1 | B4: TCF0820 | C4: 2024 | D4: 6.14OZ-66" (OB12*300D) #AR WHITE | E4: TA CHIANG SPINNING | F4: 6032 | G4: YARD | H4: 201669 | I4: 1200KWHT
A5: 2 | B5: TCF0826 | C5: 2024 | D5: 6.14OZ-66" (SD12*300D) #K397 BLACK | E5: TA CHIANG SPINNING | F5: 2177 | G5: YARD | H5: 201645 | I5: O1113KBLK
A6: 3 | B6: TCF0821 | C6: 2024 | D6: 6.14OZ-66" (SD12*300D) #K153 NAVY | E6: TA CHIANG SPINNING | F6: 953 | G6: YARD | H6: 201642 | I6: HA1521NBL
A7: 4 | B7: TCF0822 | C7: 2024 | D7: 6.14OZ-66" (SD12*300D) #K156 WEDGEWOOD BLUE | E7: TA CHIANG SPINNING | F7: 250 | G7: YARD | H7: 201689 | I7: HA1072WBL
A8: 5 | B8: TCF0823 | C8: 2024 | D8: 6.14OZ-66" (SD12*300D) #K797 RED | E8: TA CHIANG SPINNING | F8: 934 | G8: YARD | H8: 201689 | I8: 1037GRED
A9: 6 | B9: TCF0824 | C9: 2024 | D9: 6.14OZ-66" (SD12*300D) #K796 MAROON | E9: TA CHIANG SPINNING | F9: 183 | G9: YARD | H9: 201642 | I9: HA1521MRN
A10: 7 | B10: TCF0825 | C10: 2024 | D10: 6.14OZ-66" (SD12*300D) #K396 MADRITE GREY | E10: TA CHIANG SPINNING | F10: 2111 | G10: YARD | H10: 201689 | I10: 1200KMGY
A11: 8 | B11: TCF0826 | C11: 2024 | D11: 6.14OZ-66" (SD12*300D) #K397 BLACK | E11: TA CHIANG SPINNING | F11: 65 | G11: YARD | H11: 201645 | I11: Recut
A12: 9 | B12: TCF0204 | C12: 2022 | D12: 7.1OZ/SDHV-65" (SD12*SD12) #K326 BROWN | E12: TA CHIANG SPINNING | F12: 301 | G12: YARD | H12: 201715 | I12: A7756BRN
A13: 10 | B13: TCF0058 | C13: 2016 | D13: 7.1OZ/SDHV-121" (SD12*SD12) #7946 MAROON | E13: TA CHIANG SPINNING | F13: 124 | G13: YARD | H13: SSNG13881 | I13: NASP20-MN
E14: TOTAL: | F14: =SUM(F4:F13) -> 13130 | G14: YARD

Sheet 21.11.25
A1: FABRIC OLD STOCK CUTTING
A3: No | B3: Item Code | C3: YEAR | D3: Description | E3: Customer | F3: Quantity | G3: Unit | H3: PO | I3: STYLE
A4: 1 | B4: TCF0820 | C4: 2024 | D4: 6.14OZ-66" (OB12*300D) #AR WHITE | E4: TA CHIANG SPINNING | F4: 115 | G4: YARD | H4: SAMPLE | I4: 3269S
A5: 2 | B5: TCF0130 | C5: 2024 | D5: 4.5OZ/T150-72.5" (OB26*OB26) #ALSCO WHITE | E5: TA CHIANG SPINNING | F5: 90 | G5: YARD | H5: RECUT | I5: BL06272025
A6: 3 | B6: TCF0820 | C6: 2024 | D6: 6.14OZ-66" (OB12*300D) #AR WHITE | E6: TA CHIANG SPINNING | F6: 4757 | G6: YARD | H6: 201656 | I6: 0882KWHT
A7: 4 | B7: TCF0823 | C7: 2024 | D7: 6.14OZ-66" (SD12*300D) #K797 RED | E7: TA CHIANG SPINNING | F7: 124 | G7: YARD | H7: 201689 | I7: 1037GRED
A8: 5 | B8: TCF0825 | C8: 2024 | D8: 6.14OZ-66" (SD12*300D) #K396 MADRITE GREY | E8: TA CHIANG SPINNING | F8: 96 | G8: YARD | H8: 201656 | I8: 0882KMGY
E9: TOTAL: | F9: =SUM(F4:F8) -> 5182 | G9: YARD

Sheet 28.11.25 
A1: FABRIC OLD STOCK CUTTING
A3: No | B3: Item Code | C3: YEAR | D3: Description | E3: Customer | F3: Quantity | G3: Unit | H3: PO | I3: STYLE
A4: 1 | B4: TCF0027 | C4: 2024 | D4: 5.5OZ/SD135-66.5" (OB20*OB20) #AR WHITE | E4: TA CHIANG SPINNING | F4: 31 | G4: YARD | H4: SAMPLE | I4: DI-860
A5: 2 | B5: TCF0027 | C5: 2024 | D5: 5.5OZ/SD135-66.5" (OB20*OB20) #AR WHITE | E5: TA CHIANG SPINNING | F5: 139 | G5: YARD | H5: 201785 | I5: O1544GWHT
A6: 3 | B6: TCF0130 | C6: 2024 | D6: 4.5OZ/T150-72.5" (OB26*OB26) #ALSCO WHITE | E6: TA CHIANG SPINNING | F6: 1203 | G6: YARD | H6: 201785 | I6: 2051GWHT
A7: 4 | B7: TCF0214 | C7: 2024 | D7: 7.1OZ/SDHV-65" (SD12*SD12) #K320 BURGUNDY | E7: TA CHIANG SPINNING | F7: 99 | G7: YARD | H7: 201785 | I7: A1037GMRN
A8: 5 | B8: TCF0214 | C8: 2024 | D8: 7.1OZ/SDHV-65" (SD12*SD12) #K320 BURGUNDY | E8: TA CHIANG SPINNING | F8: 109 | G8: YARD | H8: 201832 | I8: O1114KMRN
A9: 6 | B9: TCF0413 | C9: 2024 | D9: 7.1OZ/SDHV-65.5" (SD12*SD12) #HMD KELLY GREEN | E9: TA CHIANG SPINNING | F9: 175 | G9: YARD | H9: 201715 | I9: A1037GKGN
A10: 7 | B10: TCF0427 | C10: 2024 | D10: 4.5OZ/T150-72.5" (SD26*SD26) #800 BLACK | E10: TA CHIANG SPINNING | F10: 140 | G10: YARD | H10: 201785 | I10: 2090BLK
A11: 8 | B11: TCF0525 | C11: 2024 | D11: 7.1OZ-64.5" (SD12*SD12) #MAG003 BLACK | E11: TA CHIANG SPINNING | F11: 20 | G11: YARD | H11: 5694(RECUT) | I11: CP123BK
A12: 9 | B12: TCF0526 | C12: 2024 | D12: 4.5OZ-72.5" (OB26*OB26) #MAG002 WHITE | E12: TA CHIANG SPINNING | F12: 148 | G12: YARD | H12: 5694 | I12: CS122WH
A13: 10 | B13: TCF0820 | C13: 2024 | D13: 6.14OZ-66" (OB12*300D) #AR WHITE | E13: TA CHIANG SPINNING | F13: 154 | G13: YARD | H13: 201656(recut) | I13: 0882KWHT
A14: 11 | B14: TCF0820 | C14: 2024 | D14: 6.14OZ-66" (OB12*300D) #AR WHITE | E14: TA CHIANG SPINNING | F14: 798 | G14: YARD | H14: 201785 | I14: 4426WHT
A15: 12 | B15: TCF0820 | C15: 2024 | D15: 6.14OZ-66" (OB12*300D) #AR WHITE | E15: TA CHIANG SPINNING | F15: 259 | G15: YARD | H15: 201832 | I15: 4426WHT
A16: 13 | B16: TCF0823 | C16: 2024 | D16: 6.14OZ-66" (SD12*300D) #K797 RED | E16: TA CHIANG SPINNING | F16: 874 | G16: YARD | H16: 201785 | I16: C1438RED
A17: 14 | B17: TCF0823 | C17: 2024 | D17: 6.14OZ-66" (SD12*300D) #K797 RED | E17: TA CHIANG SPINNING | F17: 30 | G17: YARD | H17: 201689(recut) | I17: 1037GRED
A18: 15 | B18: TCF0823 | C18: 2024 | D18: 6.14OZ-66" (SD12*300D) #K797 RED | E18: TA CHIANG SPINNING | F18: 60 | G18: YARD | H18: 201832 | I18: 1037GRED
A19: 16 | B19: TCF0824 | C19: 2024 | D19: 6.14OZ-66" (SD12*300D) #K796 MAROON | E19: TA CHIANG SPINNING | F19: 5 | G19: YARD | H19: 201642(recut) | I19: HA1521MRN
A20: 17 | B20: TCF0824 | C20: 2024 | D20: 6.14OZ-66" (SD12*300D) #K796 MAROON | E20: TA CHIANG SPINNING | F20: 133 | G20: YARD | H20: 76104F | I20: GO2488
A21: 18 | B21: TCF0824 | C21: 2024 | D21: 6.14OZ-66" (SD12*300D) #K796 MAROON | E21: TA CHIANG SPINNING | F21: 127 | G21: YARD | H21: 201832 | I21: HA1521MRN
A22: 19 | B22: TCF0825 | C22: 2024 | D22: 6.14OZ-66" (SD12*300D) #K396 MADRITE GREY | E22: TA CHIANG SPINNING | F22: 30 | G22: YARD | H22: 201656(recut) | I22: 0882KMGY
A23: 20 | B23: TCF0825 | C23: 2024 | D23: 6.14OZ-66" (SD12*300D) #K396 MADRITE GREY | E23: TA CHIANG SPINNING | F23: 123 | G23: YARD | H23: 201832 | I23: 1855RED
A24: 21 | B24: TCF0809 | C24: 2024 | D24: 6.14OZ-68" (SD12*300D) #K153 NAVY | E24: TA CHIANG SPINNING | F24: 273 | G24: YARD | H24: 201642 | I24: HA1521NBL
A25: 22 | B25: TCF0708 | C25: 2023 | D25: 6.35OZ-54" (SD12*300D) RED-WPL | E25: TA CHIANG SPINNING | F25: 144 | G25: YARD | H25: 201832 | I25: O1125GRED
A26: 23 | B26: TCF0769 | C26: 2023 | D26: 7.1OZ-92.5" (SD12*SD12) RED-WPL | E26: TA CHIANG SPINNING | F26: 310 | G26: YARD | H26: 201832 | I26: O1114KRED
A27: 24 | B27: TCF0569 | C27: 2021 | D27: 6.9OZ-59" (TC22*TC16 1/3 TWILL) 235gsm #HMD-KGREEN | E27: TA CHIANG SPINNING | F27: 109 | G27: YARD | H27: SKUL4953 | I27: GPPC733-BTG
A28: 25 | B28: TCF0327 | C28: 2017 | D28: 7.1OZ/SDHV-64.5" (SD12*SD12) #HMD GOLD | E28: TA CHIANG SPINNING | F28: 147 | G28: YARD | H28: 201832 | I28: O1114KGLD
A29: 26 | B29: TCF0019 | C29: 2014 | D29: 7.1OZ/SDHV-111" (SD12*SD12) #3580 YELLOW LEMON | E29: TA CHIANG SPINNING | F29: 126 | G29: YARD | H29: 201715 | I29: O1114YEL
E30: TOTAL: | F30: =SUM(F4:F29) -> 5766 | G30: YARD

Sheet 05.12.25 
A1: FABRIC OLD STOCK CUTTING
A3: No | B3: Item Code | C3: YEAR | D3: Description | E3: Customer | F3: Quantity | G3: Unit | H3: PO | I3: STYLE
A4: 1 | B4: TCF0214 | C4: 2024 | D4: 7.1OZ/SDHV-65" (SD12*SD12) #K320 BURGUNDY | E4: TA CHIANG SPINNING | F4: 27 | G4: YARD | H4: 201785 (RECUT) | I4: A1037GMRN
A5: 2 | B5: TCF0820 | C5: 2024 | D5: 6.14OZ-66" (OB12*300D) #AR WHITE | E5: TA CHIANG SPINNING | F5: 15 | G5: YARD | H5: SAMPLE | I5: 1037G
A6: 3 | B6: TCF0496 | C6: 2021 | D6: 6.1OZ-68" (T300D*SD12) #K749 RED | E6: TA CHIANG SPINNING | F6: 3 | G6: YARD | H6: SAMPLE | I6: TABLE CLOTH
A7: 4 | B7: TCF0019 | C7: 2014 | D7: 7.1OZ/SDHV-111" (SD12*SD12) #3580 YELLOW LEMON | E7: TA CHIANG SPINNING | F7: 10 | G7: YARD | H7: 201715(recut) | I7: O1114YEL
E8: TOTAL: | F8: =SUM(F4:F7) -> 55 | G8: YARD

Sheet 12.12.25 
A1: FABRIC OLD STOCK CUTTING
A3: No | B3: Item Code | C3: YEAR | D3: Description | E3: Customer | F3: Quantity | G3: Unit | H3: PO | I3: STYLE
A4: 1 | B4: TCF0831 | C4: 2024 | D4: 7.1OZ/SDHV-65" (SD12*SD12) #K320 BURGUNDY | E4: TA CHIANG SPINNING | F4: 95 | G4: YARD | H4: SSNG13650 | I4: GCRCSS320BF-WH
A5: 2 | B5: TCF0820 | C5: 2024 | D5: 6.14OZ-66" (OB12*300D) #AR WHITE | E5: TA CHIANG SPINNING | F5: 10 | G5: YARD | H5: 201785 (RECUT) | I5: 4426WHT
E6: TOTAL: | F6: =SUM(F4:F5) -> 105 | G6: YARD

Sheet 19.12.25
A1: FABRIC OLD STOCK CUTTING
A3: No | B3: Item Code | C3: YEAR | D3: Description | E3: Customer | F3: Quantity | G3: Unit | H3: PO | I3: STYLE
A4: 1 | B4: TCF0130 | C4: 2024 | D4: 4.5OZ/T150-72.5" (OB26*OB26) #ALSCO WHITE | E4: TA CHIANG SPINNING | F4: 15 | G4: YARD | H4: 201785(recut) | I4: 2051GWHT
A5: 2 | B5: TCF0820 | C5: 2024 | D5: 6.14OZ-66" (OB12*300D) #AR WHITE | E5: TA CHIANG SPINNING | F5: 20 | G5: YARD | H5: SAMPLE | I5: O1113K 1425 1119G 1054B
A6: 3 | B6: TCF0592 | C6: 2024 | D6: 5.5OZ-66.5" (SD20*SD20) #MAG008 RED | E6: TA CHIANG SPINNING | F6: 1131 | G6: YARD | H6: 10824 | I6: CC133-RD
A7: 4 | B7: TCF0591 | C7: 2024 | D7: 5.5OZ-66.5" (SD20*SD20) #MAG007 BURGUNDY | E7: TA CHIANG SPINNING | F7: 1064 | G7: YARD | H7: 10824 | I7: CC133-BY
A8: 5 | B8: TCF0591 | C8: 2023 | D8: 5.5OZ-66.5" (SD20*SD20) #MAG007 BURGUNDY | E8: TA CHIANG SPINNING | F8: 605 | G8: YARD | H8: 10824 | I8: CC133-BY
E9: TOTAL: | F9: =SUM(F4:F8) -> 2835 | G9: YARD

Sheet 26.12.25 
A1: FABRIC OLD STOCK CUTTING
A3: No | B3: Item Code | C3: YEAR | D3: Description | E3: Customer | F3: Quantity | G3: Unit | H3: PO | I3: STYLE
A4: 1 | B4: TCF0820 | C4: 2024 | D4: 6.14OZ-66" (OB12*300D) #AR WHITE | E4: TA CHIANG SPINNING | F4: 5 | G4: YARD | H4: SAMPLE | I4: O1114KCMX
E5: TOTAL: | F5: =SUM(F4:F4) -> 5 | G5: YARD

Sheet 02.01.26 
A1: FABRIC OLD STOCK CUTTING
A3: No | B3: Item Code | C3: YEAR | D3: Description | E3: Customer | F3: Quantity | G3: Unit | H3: PO | I3: STYLE
A4: 1 | B4: TCF0104 | C4: 2024 | D4: 5.5OZ/SD135-66.5" (SD20*SD20) #FW457 NAVY | E4: TA CHIANG SPINNING | F4: 975 | G4: YARD | H4: 10824 | I4: CC133-NB
A5: 2 | B5: TCF0605 | C5: 2024 | D5: 5.75OZ-58.5" (T/C21*T/C21) #433C BLACK | E5: TA CHIANG SPINNING | F5: 41 | G5: YARD | H5: SKUL4962 | I5: GVPCLS320BF-BK
E6: TOTAL: | F6: =SUM(F4:F5) -> 1016 | G6: YARD

Sheet Sumary 
A1: FABRIC OLD STOCK CUTTING (OCT-DEC.2025)
A3: No | B3: Item Code | C3: YEAR | D3: Description | E3: Customer | F3: Quantity | G3: Unit | H3: PO | I3: STYLE
A4: 1 | B4: GRB0001 | C4: 2021 | D4: 7.1OZ/SDHV-55.5" (OB12*OB12) #ALSCO WHITE | E4: TA CHIANG SPINNING | F4: =SUMIF(Sheet2!B4:B93,'Sumary '!B4,Sheet2!F4:F93) -> 149 | G4: YARD | H4: S26-1107 | I4: 6137-R
A5: 2 | B5: GRB0010 | C5: 2021 | D5: 7.1OZ/SDHV-92.5" (OB12*OB12) #ALSCO WHITE | E5: TA CHIANG SPINNING | F5: =SUMIF(Sheet2!B5:B94,'Sumary '!B5,Sheet2!F5:F94) -> 606 | G5: YARD | H5: S26-1107 | I5: 6137-R
A6: 3 | B6: GRB0020 | C6: 2021 | D6: 7.1OZ/SDHV-121" (OB12*OB12) #ALSCO WHITE | E6: TA CHIANG SPINNING | F6: =SUMIF(Sheet2!B6:B95,'Sumary '!B6,Sheet2!F6:F95) -> 128 | G6: YARD | H6: S26-1107 | I6: 6137-R
A7: 4 | B7: TCF0007 | C7: 2022 | D7: 7.1OZ/SDHV-111" (SD12*SD12) #0614 DARK GREY | E7: Australia Return | F7: =SUMIF(Sheet2!B7:B96,'Sumary '!B7,Sheet2!F7:F96) -> 1080 | G7: YARD | H7: SORD44594 | I7: P207-GR
A8: 5 | B8: TCF0019 | C8: 2014 | D8: 7.1OZ/SDHV-111" (SD12*SD12) #3580 YELLOW LEMON | E8: TA CHIANG SPINNING | F8: =SUMIF(Sheet2!B8:B97,'Sumary '!B8,Sheet2!F8:F97) -> 136 | G8: YARD | H8: 201715 | I8: O1114YEL
A9: 6 | B9: TCF0020 | C9: 2024 | D9: 5.5OZ/SD135-66.5" (OB20*OB20) #AR WHITE | E9: Australia Return | F9: =SUMIF(Sheet2!B9:B98,'Sumary '!B9,Sheet2!F9:F98) -> 990 | G9: YARD | H9: S26-1107 | I9: 6137-T
A10: 7 | B10: TCF0027 | C10: 2024 | D10: 5.5OZ/SD135-66.5" (OB20*OB20) #AR WHITE | E10: TA CHIANG SPINNING | F10: =SUMIF(Sheet2!B10:B99,'Sumary '!B10,Sheet2!F10:F99) -> 4141 | G10: YARD | I10: DI-8VPU
A11: 8 | B11: TCF0040 | C11: 2015 | D11: 8.46OZ/FH21-64.5" (300D/1*SP12/1) YELLOW | E11: TA CHIANG SPINNING | F11: =SUMIF(Sheet2!B11:B100,'Sumary '!B11,Sheet2!F11:F100) -> 1749 | G11: YARD | H11: S26-1107 | I11: 6137-R
A12: 9 | B12: TCF0058 | C12: 2016 | D12: 7.1OZ/SDHV-121" (SD12*SD12) #7946 MAROON | E12: TA CHIANG SPINNING | F12: =SUMIF(Sheet2!B12:B101,'Sumary '!B12,Sheet2!F12:F101) -> 124 | G12: YARD | H12: SSNG13881 | I12: NASP20-MN
A13: 10 | B13: TCF0061 | C13: 2022 | D13: 7.1OZ/SDHV-111" (SD12*SD12) #0614 DARK GREY | E13: TA CHIANG SPINNING | F13: =SUMIF(Sheet2!B13:B102,'Sumary '!B13,Sheet2!F13:F102) -> 123 | G13: YARD | H13: SORD44594 | I13: P207-GR
A14: 11 | B14: TCF0075 | C14: 2020 | D14: 3.5OZ/SD170-67" (SD30*T75D) #AR YELLOW | E14: TA CHIANG SPINNING | F14: =SUMIF(Sheet2!B14:B103,'Sumary '!B14,Sheet2!F14:F103) -> 105 | G14: YARD | H14: SORD44550 | I14: P207-BG
A15: 12 | B15: TCF0084 | C15: 2024 | D15: 5.5OZ/SD135-66.5" (OB20*OB20) #FW257 L.BLUE | E15: TA CHIANG SPINNING | F15: =SUMIF(Sheet2!B15:B104,'Sumary '!B15,Sheet2!F15:F104) -> 123 | G15: YARD | H15: 201291 | I15: A1541GLBL
A16: 13 | B16: TCF0104 | C16: 2024 | D16: 5.5OZ/SD135-66.5" (SD20*SD20) #FW457 NAVY | E16: TA CHIANG SPINNING | F16: =SUMIF(Sheet2!B16:B105,'Sumary '!B16,Sheet2!F16:F105) -> 1227 | G16: YARD | H16: 201291 | I16: A1537BNBL
A17: 14 | B17: TCF0124 | C17: 2024 | D17: 7.1OZ/SDHV-121" (SD12*SD12) #0155 NAVY | E17: TA CHIANG SPINNING | F17: =SUMIF(Sheet2!B17:B106,'Sumary '!B17,Sheet2!F17:F106) -> 329 | G17: YARD | H17: RECUT | I17: P207-N
A18: 15 | B18: TCF0130 | C18: 2024 | D18: 4.5OZ/T150-72.5" (OB26*OB26) #ALSCO WHITE | E18: TA CHIANG SPINNING | F18: =SUMIF(Sheet2!B18:B107,'Sumary '!B18,Sheet2!F18:F107) -> 1658 | G18: YARD | H18: 200995
A19: 16 | B19: TCF0144 | C19: 2018 | D19: 3.5OZ/SD170-66" (SD30*T75D) #AR APUA | E19: TA CHIANG SPINNING | F19: =SUMIF(Sheet2!B19:B108,'Sumary '!B19,Sheet2!F19:F108) -> 1 | G19: YARD | H19: A416222 | I19: GO2134
A20: 17 | B20: TCF0182 | C20: 2020 | D20: 3.5OZ/SD170-67" (SD30*T75D) #AR YELLOW | E20: TA CHIANG SPINNING | F20: =SUMIF(Sheet2!B20:B109,'Sumary '!B20,Sheet2!F20:F109) -> 10 | G20: YARD | H20: A416222 | I20: GSC978
A21: 18 | B21: TCF0204 | C21: 2022 | D21: 7.1OZ/SDHV-65" (SD12*SD12) #K326 BROWN | E21: TA CHIANG SPINNING | F21: =SUMIF(Sheet2!B21:B110,'Sumary '!B21,Sheet2!F21:F110) -> 301 | G21: YARD | H21: 201715 | I21: A7756BRN
A22: 19 | B22: TCF0214 | C22: 2024 | D22: 7.1OZ/SDHV-65" (SD12*SD12) #K320 BURGUNDY | E22: TA CHIANG SPINNING | F22: =SUMIF(Sheet2!B22:B111,'Sumary '!B22,Sheet2!F22:F111) -> 235 | G22: YARD | H22: 201785 | I22: A1037GMRN
A23: 20 | B23: TCF0293 | C23: 2023 | D23: 3.5OZ-SD170-67" (OB30*T100D) #AR WHITE | E23: TA CHIANG SPINNING | F23: =SUMIF(Sheet2!B23:B112,'Sumary '!B23,Sheet2!F23:F112) -> 11 | G23: YARD | H23: A416222 | I23: GO2134
A24: 21 | B24: TCF0327 | C24: 2017 | D24: 7.1OZ/SDHV-64.5" (SD12*SD12) #HMD GOLD | E24: TA CHIANG SPINNING | F24: =SUMIF(Sheet2!B24:B113,'Sumary '!B24,Sheet2!F24:F113) -> 147 | G24: YARD | H24: 201832 | I24: O1114KGLD
A25: 22 | B25: TCF0362 | C25: 2024 | D25: 7.1OZ/SDHV-67" (SD12*OB12) NAVY/WHITE STRIPE | E25: TA CHIANG SPINNING | F25: =SUMIF(Sheet2!B25:B114,'Sumary '!B25,Sheet2!F25:F114) -> 1657 | G25: YARD | H25: SORD44542 | I25: AP154-NWP
A26: 23 | B26: TCF0413 | C26: 2024 | D26: 7.1OZ/SDHV-65.5" (SD12*SD12) #HMD KELLY GREEN | E26: TA CHIANG SPINNING | F26: =SUMIF(Sheet2!B26:B115,'Sumary '!B26,Sheet2!F26:F115) -> 175 | G26: YARD | H26: 201715 | I26: A1037GKGN
A27: 24 | B27: TCF0427 | C27: 2024 | D27: 4.5OZ/T150-72.5" (SD26*SD26) #800 BLACK | E27: TA CHIANG SPINNING | F27: =SUMIF(Sheet2!B27:B116,'Sumary '!B27,Sheet2!F27:F116) -> 140 | G27: YARD | H27: 201785 | I27: 2090BLK
A28: 25 | B28: TCF0496 | C28: 2021 | D28: 6.1OZ-68" (T300D*SD12) #K749 RED | E28: TA CHIANG SPINNING | F28: =SUMIF(Sheet2!B28:B117,'Sumary '!B28,Sheet2!F28:F117) -> 3 | G28: YARD | H28: SAMPLE | I28: TABLE CLOTH
A29: 26 | B29: TCF0525 | C29: 2024 | D29: 7.1OZ-64.5" (SD12*SD12) #MAG003 BLACK | E29: TA CHIANG SPINNING | F29: =SUMIF(Sheet2!B29:B118,'Sumary '!B29,Sheet2!F29:F118) -> 951 | G29: YARD | H29: 5605 | I29: CP123,BLACK
A30: 27 | B30: TCF0526 | C30: 2024 | D30: 4.5OZ-72.5" (OB26*OB26) #MAG002 WHITE | E30: TA CHIANG SPINNING | F30: =SUMIF(Sheet2!B30:B119,'Sumary '!B30,Sheet2!F30:F119) -> 148 | G30: YARD | H30: 5694 | I30: CS122WH
A31: 28 | B31: TCF0569 | C31: 2021 | D31: 6.9OZ-59" (TC22*TC16 1/3 TWILL) 235gsm #HMD-KGREEN | E31: TA CHIANG SPINNING | F31: =SUMIF(Sheet2!B31:B120,'Sumary '!B31,Sheet2!F31:F120) -> 109 | G31: YARD | H31: SKUL4953 | I31: GPPC733-BTG
A32: 29 | B32: TCF0591 | C32: 2024 | D32: 5.5OZ-66.5" (SD20*SD20) #MAG007 BURGUNDY | E32: TA CHIANG SPINNING | F32: =SUMIF(Sheet2!B32:B121,'Sumary '!B32,Sheet2!F32:F121) -> 1669 | G32: YARD | H32: 10824 | I32: CC133-BY
A33: 30 | B33: TCF0592 | C33: 2024 | D33: 5.5OZ-66.5" (SD20*SD20) #MAG008 RED | E33: TA CHIANG SPINNING | F33: =SUMIF(Sheet2!B33:B122,'Sumary '!B33,Sheet2!F33:F122) -> 1131 | G33: YARD | H33: 10824 | I33: CC133-RD
A34: 31 | B34: TCF0605 | C34: 2024 | D34: 5.75OZ-58.5" (T/C21*T/C21) #433C BLACK | E34: TA CHIANG SPINNING | F34: =SUMIF(Sheet2!B34:B123,'Sumary '!B34,Sheet2!F34:F123) -> 41 | G34: YARD | H34: SKUL4962 | I34: GVPCLS320BF-BK
A35: 32 | B35: TCF0692 | C35: 2023 | D35: 6.35OZ-64.5" (SD12*300D) NAVY BLUE-WPL | E35: TA CHIANG SPINNING | F35: =SUMIF(Sheet2!B35:B124,'Sumary '!B35,Sheet2!F35:F124) -> 1839 | G35: YARD | H35: 201146 | I35: O1113KNBL
A36: 33 | B36: TCF0708 | C36: 2023 | D36: 6.35OZ-54" (SD12*300D) RED-WPL | E36: TA CHIANG SPINNING | F36: =SUMIF(Sheet2!B36:B125,'Sumary '!B36,Sheet2!F36:F125) -> 344 | G36: YARD | H36: 200541 | I36: O1125GRED
A37: 34 | B37: TCF0714 | C37: 2023 | D37: 6.35OZ-73" (SD12*300D) NAVY BLUE-WPL | E37: TA CHIANG SPINNING | F37: =SUMIF(Sheet2!B37:B126,'Sumary '!B37,Sheet2!F37:F126) -> 119 | G37: YARD | H37: 201147-03 | I37: O1113KNBL
A38: 35 | B38: TCF0717 | C38: 2024 | D38: 6.35OZ-91.5" (SD12*300D) NAVY BLUE-WPL | E38: TA CHIANG SPINNING | F38: =SUMIF(Sheet2!B38:B127,'Sumary '!B38,Sheet2!F38:F127) -> 1002 | G38: YARD | H38: 201147 | I38: O1113KNBL
A39: 36 | B39: TCF0744 | C39: 2024 | D39: 6.35OZ-109.5" (SD12*300D) NAVY BLUE-WPL | E39: TA CHIANG SPINNING | F39: =SUMIF(Sheet2!B39:B128,'Sumary '!B39,Sheet2!F39:F128) -> 465 | G39: YARD | H39: 201147 | I39: O1113KNBL
A40: 37 | B40: TCF0745 | C40: 2023 | D40: 3.5OZ/SD170-67" (SD30*T100D) #AR L.PINK | E40: TA CHIANG SPINNING | F40: =SUMIF(Sheet2!B40:B129,'Sumary '!B40,Sheet2!F40:F129) -> 5 | G40: YARD | H40: RECUT
A41: 38 | B41: TCF0769 | C41: 2023 | D41: 7.1OZ-92.5" (SD12*SD12) RED-WPL | E41: TA CHIANG SPINNING | F41: =SUMIF(Sheet2!B41:B130,'Sumary '!B41,Sheet2!F41:F130) -> 310 | G41: YARD | H41: 201832 | I41: O1114KRED
...

Sheet 09.01.26
A1: FABRIC OLD STOCK CUTTING
A3: No | B3: Item Code | C3: YEAR | D3: Description | E3: Customer | F3: Quantity | G3: Unit | H3: PO | I3: STYLE
A4: 1 | B4: TCF0130 | C4: 2024 | D4: 4.5OZ/T150-72.5" (OB26*OB26) #ALSCO WHITE | E4: TA CHIANG SPINNING | F4: 77 | G4: YARD | H4: 201785(RECUT) | I4: 2048GWHT
A5: 2 | B5: TCF0820 | C5: 2024 | D5: 6.14OZ-66" (OB12*300D) #AR WHITE | E5: TA CHIANG SPINNING | F5: 6126 | G5: YARD | H5: 201965 202019 201661 201867 | I5: 3125KWHT HA1521WHT O1113KWHT 4426WHT A0953BWHT
E6: TOTAL: | F6: =SUM(F4:F5) -> 6203 | G6: YARD

Sheet 16.01.26
A1: FABRIC OLD STOCK CUTTING
A3: No | B3: Item Code | C3: YEAR | D3: Description | E3: Customer | F3: Quantity | G3: Unit | H3: PO | I3: STYLE
A4: 1 | B4: TCF0554 | C4: 2024 | D4: 4.5OZ/T150-72.5" (OB26*OB26) #ALSCO WHITE | E4: TA CHIANG SPINNING | F4: 18 | G4: YARD | H4: 20976 | I4: MANX45981
A5: 2 | B5: TCF0820 | C5: 2024 | D5: 6.14OZ-66" (OB12*300D) #AR WHITE | E5: TA CHIANG SPINNING | F5: 129 | G5: YARD | H5: 201965 | I5: 3125KWHT
E6: TOTAL: | F6: =SUM(F4:F5) -> 147 | G6: YARD

Sheet 23.01.26 
A1: FABRIC OLD STOCK CUTTING
A3: No | B3: Item Code | C3: YEAR | D3: Description | E3: Customer | F3: Quantity | G3: Unit | H3: PO | I3: STYLE
A4: 1 | B4: TCF0820 | C4: 2024 | D4: 6.14OZ-66" (OB12*300D) #AR WHITE | E4: TA CHIANG SPINNING | F4: 29949 | G4: YARD | H4: 201943 201979 202047 201943 201965 | I4: 0811KWHT 1087BWHT 3125KWHT A1544GWHT A1544GWHT
A5: 2 | B5: TCF0820 | C5: 2024 | D5: 6.14OZ-66" (OB12*300D) #AR WHITE | E5: TA CHIANG SPINNING | F5: 3886 | G5: YARD | H5: 201943 201943 201943 201943 201943 201943 201943 | I5: O1114KCMX10WHT O1114KCMX11WHT O1114KCMX15WHT O1114KCMX12WHT O1114KCMX14WHT O1114KCMX13WHT 3269SWHT
A6: 3 | B6: TCF0825 | C6: 2024 | D6: 6.14OZ-66" (SD12*300D) #K396 MADRITE GREY | E6: TA CHIANG SPINNING | F6: 417 | G6: YARD | H6: 201979 | I6: 1734MGY
A7: 4 | B7: TCF0828 | C7: 2024 | D7: 6.14OZ-66" (SD12*300D) #K555 KELLY GREEN | E7: TA CHIANG SPINNING | F7: 142 | G7: YARD | H7: 201979 | I7: 1734KGN
E8: TOTAL: | F8: =SUM(F4:F7) -> 34394 | G8: YARD

Sheet 30.01.26 
A1: FABRIC OLD STOCK CUTTING
A3: No | B3: Item Code | C3: YEAR | D3: Description | E3: Customer | F3: Quantity | G3: Unit | H3: PO | I3: STYLE
A4: 1 | B4: TCF0162 | C4: 2020 | D4: 7.1OZ/SDHV-66" (SD12*SD12) #K226 DARK NAVY | E4: TA CHIANG SPINNING | F4: 85 | G4: YARD | H4: 260017 | I4: DI8V-NP
A5: 2 | B5: TCF0537 | C5: 2022 | D5: 6.2OZ-59" (TC21*TC17 1/2 TWILL) 210gsm #425 DNAVY | E5: TA CHIANG SPINNING | F5: 90 | G5: YARD | H5: SSNG14248 | I5: GPPC397CVT-NV
A6: 3 | B6: TCF0820 | C6: 2024 | D6: 6.14OZ-66" (OB12*300D) #AR WHITE | E6: TA CHIANG SPINNING | F6: 15 | G6: YARD | H6: 201943 | I6: RECUT
A7: 4 | B7: TCF0820 | C7: 2024 | D7: 6.14OZ-66" (OB12*300D) #AR WHITE | E7: TA CHIANG SPINNING | F7: 1124 | G7: YARD | H7: 201979 | I7: 2558GWHT
A8: 5 | B8: TCF0101 | C8: 2024 | D8: 5.5OZ/SD135-66.5" (SD20*SD20) #FW357 RED | E8: TA CHIANG SPINNING | F8: 376 | G8: YARD | H8: 201965 | I8: A1317WRED
A9: 6 | B9: TCF0084 | C9: 2024 | D9: 5.5OZ/SD135-66.5" (OB20*OB20) #FW257 L.BLUE | E9: TA CHIANG SPINNING | F9: 132 | G9: YARD | H9: 201965 | I9: A1317WLBL
A10: 7 | B10: TCF0823 | C10: 2024 | D10: 6.14OZ-66" (SD12*300D) #K797 RED | E10: TA CHIANG SPINNING | F10: 542 | G10: YARD | H10: 201886 | I10: A1095BRED
A11: 8 | B11: TCF0825 | C11: 2024 | D11: 6.14OZ-66" (SD12*300D) #K396 MADRITE GREY | E11: TA CHIANG SPINNING | F11: 241 | G11: YARD | H11: 201979 | I11: 1734MGY
A12: 9 | B12: TCF0828 | C12: 2024 | D12: 6.14OZ-66" (SD12*300D) #K555 KELLY GREEN | E12: TA CHIANG SPINNING | F12: 2161 | G12: YARD | H12: 201886 | I12: A1095BKGN
E13: TOTAL: | F13: =SUM(F4:F12) -> 4766 | G13: YARD

Sheet 06.02.26
A1: FABRIC OLD STOCK CUTTING
A3: No | B3: Item Code | C3: YEAR | D3: Description | E3: Customer | F3: Quantity | G3: Unit | H3: PO | I3: STYLE
A4: 1 | B4: TCF0612 | C4: 2022 | D4: 6.35OZ-116" (OB12*300D) #AA WHITE | E4: TA CHIANG SPINNING | F4: 452 | G4: YARD | H4: 5474 | I4: NPS021021WHS
A5: 2 | B5: TCF0603 | C5: 2022 | D5: 6.35OZ-121.5" (OB12*T300D) #AA WHITE | E5: TA CHIANG SPINNING | F5: 829 | G5: YARD | H5: 5474 | I5: TO52S120RWH
A6: 3 | B6: TCF0611 | C6: 2023 | D6: 6.35OZ-91.5" (SD12*300D) #AA BLACK | E6: TA CHIANG SPINNING | F6: 486 | G6: YARD | H6: 5474 | I6: TO52S9015BK
A7: 4 | B7: TCF0752 | C7: 2023 | D7: 6.35OZ-132" (SD12*300D) NAVY BLUE-WPL | E7: TA CHIANG SPINNING | F7: 137 | G7: YARD | H7: 5474 | I7: TO52S132RNV
A8: 5 | B8: TCF0602 | C8: 2023 | D8: 6.35OZ-86.5" (OB12*T300D) #AA WHITE | E8: TA CHIANG SPINNING | F8: 363 | G8: YARD | H8: 5474 | I8: TPS042042WHS
A9: 6 | B9: TCF0460 | C9: 2022 2024 | D9: 6.35OZ/SDMD-73" (OB12*T300D) #AA WHITE | E9: TA CHIANG SPINNING | F9: 5928 | G9: YARD | H9: 0005474 | I9: TPS071071WHS
A10: 7 | B10: TCF0592 | C10: 2022 2023 2024 | D10: 5.5OZ-66.5" (SD20*SD20) #MAG008 RED | E10: TA CHIANG SPINNING | F10: 1515 | G10: YARD | H10: 5926 | I10: CC133RD
A11: 8 | B11: TCF0820 | C11: 2024 | D11: 6.14OZ-66" (OB12*300D) #AR WHITE | E11: TA CHIANG SPINNING | F11: 645 | G11: YARD | H11: 201943 | I11: 2369GWHT
A12: 9 | B12: TCF0027 | C12: 2024 | D12: 5.5OZ/SD135-66.5" (OB20*OB20) #AR WHITE | E12: TA CHIANG SPINNING | F12: 274 | G12: YARD | H12: 10824 5926 5970 | I12: CC133WH CC133WH CC133WH-GL
A13: 10 | B13: TCF0591 | C13: 2024 | D13: 5.5OZ-66.5" (SD20*SD20) #MAG007 BURGUNDY | E13: TA CHIANG SPINNING | F13: 1971 | G13: YARD | H13: 201965 | I13: A1317WRED
A14: 11 | B14: TCF0593 | C14: 2024 | D14: 5.5OZ-66.5" (SD20*SD20) #MAG009 GREEN | E14: TA CHIANG SPINNING | F14: 77 | G14: YARD | H14: 10824 | I14: CC133GR
E15: TOTAL: | F15: =SUM(F4:F14) -> 12677 | G15: YARD

Sheet 13.02.26 
A1: FABRIC OLD STOCK CUTTING
A3: No | B3: Item Code | C3: YEAR | D3: Description | E3: Customer | F3: Quantity | G3: Unit | H3: PO | I3: STYLE
A4: 3 | B4: TCF0104 | C4: 2023 | D4: 5.5OZ/SD135-66.5" (SD20*SD20) #FW457 NAVY | E4: TA CHIANG SPINNING | F4: 932 | G4: YARD | H4: 10824 5926 | I4: CC133NB
A5: 8 | B5: TCF0820 | C5: 2024 | D5: 6.14OZ-66" (OB12*300D) #AR WHITE | E5: TA CHIANG SPINNING | F5: 55 | G5: YARD | H5: 201965 (RECUT | I5: A1544
A6: 10 | B6: TCF0591 | C6: 2024 | D6: 5.5OZ-66.5" (SD20*SD20) #MAG007 BURGUNDY | E6: TA CHIANG SPINNING | F6: 462 | G6: YARD | H6: 10824 | I6: CC133BY
E7: TOTAL: | F7: =SUM(F4:F6) -> 1449 | G7: YARD

Sheet 20.02.26
A1: FABRIC OLD STOCK CUTTING
A3: No | B3: Item Code | C3: YEAR | D3: Description | E3: Customer | F3: Quantity | G3: Unit | H3: PO | I3: STYLE
A4: 1 | B4: TCF0820 | C4: 2024 | D4: 6.14OZ-66" (OB12*300D) #AR WHITE | E4: TA CHIANG SPINNING | F4: 30 | G4: YARD | H4: 201965 (RECUT) | I4: A1544
A5: 2 | B5: TCF0820 | C5: 2024 | D5: 6.14OZ-66" (OB12*300D) #AR WHITE | E5: TA CHIANG SPINNING | F5: 658 | G5: YARD | H5: 202303 | I5: 4426WHT
A6: 3 | B6: TCF0824 | C6: 2024 | D6: 6.14OZ-66" (SD12*300D) #K796 MAROON | E6: TA CHIANG SPINNING | F6: 533 | G6: YARD | H6: 202303 | I6: 1521GMRN
E7: TOTAL: | F7: =SUM(F4:F6) -> 1221 | G7: YARD

Sheet 27.02.26 
A1: FABRIC OLD STOCK CUTTING
A3: No | B3: Item Code | C3: YEAR | D3: Description | E3: Customer | F3: Quantity | G3: Unit | H3: PO | I3: STYLE
A4: 1 | B4: TCF0019 | C4: 2014 | D4: 7.1OZ/SDHV-111" (SD12*SD12) #3580 YELLOW LEMON | E4: TA CHIANG SPINNING | F4: 50 | G4: YARD | H4: 202011 | I4: O1114YEL
A5: 2 | B5: TCF0327 | C5: 2017 | D5: 7.1OZ/SDHV-64.5" (SD12*SD12) #HMD GOLD | E5: TA CHIANG SPINNING | F5: 373 | G5: YARD | H5: 202011 | I5: O1114GLD
A6: 3 | B6: TCF0749 | C6: 2023 | D6: 6.35OZ-62.5" (SD12*300D) PURPLE-WPL | E6: TA CHIANG SPINNING | F6: 139 | G6: YARD | H6: 202086 | I6: 1619GPUR
A7: 4 | B7: TCF0824 | C7: 2024 | D7: 6.14OZ-66" (SD12*300D) #K796 MAROON | E7: TA CHIANG SPINNING | F7: 10 | G7: YARD | H7: 202303 (RECUT) | I7: 1521GMRN
A8: 5 | B8: TCF0814 | C8: 2024 | D8: 6.14OZ-68" (SD12*300D) #K258 SANDALWOOD | E8: TA CHIANG SPINNING | F8: 854 | G8: YARD | H8: 202025 201974 202047 202175 202260 202269 | I8: 0882KSWD 1521GSWD 1754SWD 1734SWD
A9: 6 | B9: TCF0820 | C9: 2024 | D9: 6.14OZ-66" (OB12*300D) #AR WHITE | E9: TA CHIANG SPINNING | F9: 8610 | G9: YARD | H9: 202175 202321 202370 202409 | I9: 3125KWHT
A10: 7 | B10: TCF0820 | C10: 2024 | D10: 6.14OZ-66" (OB12*300D) #AR WHITE | E10: TA CHIANG SPINNING | F10: 1514 | G10: YARD | H10: 202244 202265 202260 202047 | I10: 1117KWHT 1200KWBL 2558GWHT A1536BWHT
A11: 8 | B11: TCF0820 | C11: 2024 | D11: 6.14OZ-66" (OB12*300D) #AR WHITE | E11: TA CHIANG SPINNING | F11: 1953 | G11: YARD | H11: SFOR1414 | I11: AR300-W-SP
E12: TOTAL: | F12: =SUM(F4:F11) -> 13503 | G12: YARD

Sheet 06.03.26 
A1: FABRIC OLD STOCK CUTTING
A3: No | B3: Item Code | C3: YEAR | D3: Description | E3: Customer | F3: Quantity | G3: Unit | H3: PO | I3: STYLE
A4: 1 | B4: TCF0130 | C4: 2024 | D4: 4.5OZ/T150-72.5" (OB26*OB26) #ALSCO WHITE | E4: TA CHIANG SPINNING | F4: 19 | G4: YARD | H4: 5474 | I4: 103-WH
A5: 2 | B5: TCF0487 | C5: 2021 | D5: 6.1OZ-68" (T300D*SD12) #K385 BLACK | E5: TA CHIANG SPINNING | F5: 2665 | G5: YARD | H5: 5474 | I5: 413-BK
A6: 3 | B6: TCF0455 | C6: 2024 | D6: 6.35OZ/SDMD-54" (OB12*T300D) #AA WHITE | E6: TA CHIANG SPINNING | F6: 2971 | G6: YARD | H6: 5474 | I6: TPS052052WHS
A7: 4 | B7: TCF0820 | C7: 2024 | D7: 6.14OZ-66" (OB12*300D) #AR WHITE | E7: TA CHIANG SPINNING | F7: 177 | G7: YARD | H7: 202175(RECUT) | I7: 3125KWHT
E8: TOTAL: | F8: =SUM(F4:F7) -> 5832 | G8: YARD

Sheet 13.03.26 
A1: FABRIC OLD STOCK CUTTING
A3: No | B3: Item Code | C3: YEAR | D3: Description | E3: Customer | F3: Quantity | G3: Unit | H3: PO | I3: STYLE
A4: 1 | B4: TCF0004 | C4: 2024 | D4: 7.1OZ/SDHV-64.5" (OB12*OB12) #ALSCO WHITE | E4: TA CHIANG SPINNING | F4: 113 | G4: YARD | H4: 5474 | I4: 163-PWH
A5: 2 | B5: TCF0826 | C5: 2024 | D5: 6.14OZ-66" (SD12*300D) #K397 BLACK | E5: TA CHIANG SPINNING | F5: 334 | G5: YARD | H5: 202244 | I5: 1112GBLK
A6: 3 | B6: TCF0825 | C6: 2024 | D6: 6.14OZ-66" (SD12*300D) #K396 MADRITE GREY | E6: TA CHIANG SPINNING | F6: 91 | G6: YARD | H6: 202244 | I6: 1112GMGY
A7: 4 | B7: TCF0824 | C7: 2024 | D7: 6.14OZ-66" (SD12*300D) #K796 MAROON | E7: TA CHIANG SPINNING | F7: 1816 | G7: YARD | H7: 201974 | I7: 1521GMRN
A8: 5 | B8: TCF0827 | C8: 2024 | D8: 6.14OZ-66" (SD12*300D) #K942 GOLD | E8: TA CHIANG SPINNING | F8: 829 | G8: YARD | H8: 202244 | I8: 111244-10
A9: 6 | B9: TCF0820 | C9: 2024 | D9: 6.14OZ-66" (OB12*300D) #AR WHITE | E9: TA CHIANG SPINNING | F9: 118 | G9: YARD | H9: 202370(recut) | I9: 3125KWHT
E10: TOTAL: | F10: =SUM(F4:F9) -> 3301 | G10: YARD

Sheet 20.03.26 
A1: FABRIC OLD STOCK CUTTING
A3: No | B3: Item Code | C3: YEAR | D3: Description | E3: Customer | F3: Quantity | G3: Unit | H3: PO | I3: STYLE
A4: 1 | B4: TCF0019 | C4: 2014 | D4: 7.1OZ/SDHV-111" (SD12*SD12) #3580 YELLOW LEMON | E4: TA CHIANG SPINNING | F4: 156 | G4: YARD | H4: 202011 | I4: O1114YEL
A5: 2 | B5: TCF0752 | C5: 2023 | D5: 6.35OZ-132" (SD12*300D) NAVY BLUE-WPL | E5: TA CHIANG SPINNING | F5: 20 | G5: YARD | H5: 5474(recut) | I5: TO52S132RNV
A6: 3 | B6: TCF0160 | C6: 2024 | D6: 7.1OZ/SDHV-64.5" (OB12*OB12) #ALSCO WHITE | E6: TA CHIANG SPINNING | F6: 59 | G6: YARD | H6: Sample cutting | I6: DI8V-NO PKT
E7: TOTAL: | F7: =SUM(F4:F6) -> 235 | G7: YARD

Sheet 27.03.26 
A1: FABRIC OLD STOCK CUTTING
A3: No | B3: Item Code | C3: YEAR | D3: Description | E3: Customer | F3: Quantity | G3: Unit | H3: PO | I3: STYLE
A4: 1 | B4: TCF0182 | C4: 2020 | D4: 3.5OZ/SD170-67" (SD30*T75D) #AR YELLOW | E4: TA CHIANG SPINNING | F4: 90 | G4: YARD | H4: STOCK | I4: GS1818
A5: 2 | B5: TCF0293 | C5: 2023 | D5: 3.5OZ-SD170-67" (OB30*T100D) #AR WHITE | E5: TA CHIANG SPINNING | F5: 106 | G5: YARD | H5: STOCK | I5: GS1818
A6: 3 | B6: TCF0027 | C6: 2024 | D6: 5.5OZ/SD135-66.5" (OB20*OB20) #AR WHITE | E6: TA CHIANG SPINNING | F6: 1990 | G6: YARD | H6: S26-1542 | I6: 4458NU
A7: 4 | B7: TCF0717 | C7: 2024 | D7: 6.35OZ-91.5" (SD12*300D) NAVY BLUE-WPL | E7: TA CHIANG SPINNING | F7: 55 | G7: YARD | H7: 5474 | I7: T052S9015BK
A8: 5 | B8: TCF0717 | C8: 2024 | D8: 6.35OZ-91.5" (SD12*300D) NAVY BLUE-WPL | E8: TA CHIANG SPINNING | F8: 1123 | G8: YARD | H8: 201147 | I8: T052S9015NV
A9: 6 | B9: TCF0506 | C9: 2024 | D9: 5.75OZ-58.5" (T/C21*T/C21) #433C BLACK | E9: TA CHIANG SPINNING | F9: 37 | G9: YARD | H9: SKUL5013 | I9: GCPCLS320BF
A10: 7 | B10: TCF0084 | C10: 2024 | D10: 5.5OZ/SD135-66.5" (OB20*OB20) #FW257 L.BLUE | E10: TA CHIANG SPINNING | F10: 131 | G10: YARD | H10: BL11072025 | I10: LS03855
A11: 8 | B11: TCF0101 | C11: 2024 | D11: 5.5OZ/SD135-66.5" (SD20*SD20) #FW357 RED | E11: TA CHIANG SPINNING | F11: 778 | G11: YARD | H11: BL11072025 | I11: LS037C55
A12: 9 | B12: TCF0744 | C12: 2024 | D12: 6.35OZ-109.5" (SD12*300D) NAVY BLUE-WPL | E12: TA CHIANG SPINNING | F12: 81 | G12: YARD | H12: 5474 | I12: T052S96-RNV
A13: 10 | B13: TCF0820 | C13: 2024 | D13: 6.14OZ-66" (OB12*300D) #AR WHITE | E13: TA CHIANG SPINNING | F13: 2887 | G13: YARD | H13: 202517 | I13: 4426WHT
A14: 11 | B14: TCF0820 | C14: 2024 | D14: 6.14OZ-66" (OB12*300D) #AR WHITE | E14: TA CHIANG SPINNING | F14: 157 | G14: YARD | H14: 202047 | I14: 1426WHT
A15: 12 | B15: TCF0826 | C15: 2024 | D15: 6.14OZ-66" (SD12*300D) #K397 BLACK | E15: TA CHIANG SPINNING | F15: 15 | G15: YARD | H15: 202244(RECUT) | I15: 1112GBLK
E16: TOTAL: | F16: =SUM(F4:F15) -> 7450 | G16: YARD

Sheet 03.04.26 
A1: FABRIC OLD STOCK CUTTING
A3: No | B3: Item Code | C3: YEAR | D3: Description | E3: Customer | F3: Quantity | G3: Unit | H3: PO | I3: STYLE
A4: 1 | B4: TCF0019 | C4: 2014 | D4: 7.1OZ/SDHV-111" (SD12*SD12) #3580 YELLOW LEMON | E4: TA CHIANG SPINNING | F4: 3 | G4: YARD | H4: 202011(RECUT) | I4: O1114YEL
A5: 2 | B5: TCF0607 | C5: 2024 | D5: 6.35OZ-54" (SD12*300D) CHAMP-WPL | E5: TA CHIANG SPINNING | F5: 4 | G5: YARD | H5: Sample | I5: TABLE CLOTH
A6: 3 | B6: TCF0824 | C6: 2024 | D6: 6.14OZ-66" (SD12*300D) #K796 MAROON | E6: TA CHIANG SPINNING | F6: 10 | G6: YARD | H6: 201974(RECUT) | I6: 1521GMRN
A7: 4 | B7: TCF0827 | C7: 2024 | D7: 6.14OZ-66" (SD12*300D) #K942 GOLD | E7: TA CHIANG SPINNING | F7: 15 | G7: YARD | H7: Sample | I7: VOLUNTEER VEST WOMEN
A8: 5 | B8: TCF0696 | C8: 2024 | D8: 6.35OZ-91.5" (SD12*300D) NAVY BLUE-WPL | E8: TA CHIANG SPINNING | F8: 115 | G8: YARD | H8: 201965 | I8: O1125GRED
A9: 6 | B9: TCF0506 | C9: 2024 | D9: 5.75OZ-58.5" (T/C21*T/C21) #433C BLACK | E9: TA CHIANG SPINNING | F9: 11 | G9: YARD | H9: SKUL5013 | I9: GCPCLS320BF
A10: 7 | B10: TCF0736 | C10: 2023 | D10: 5.5OZ/SD135-66.5" (OB20*OB20) #FW257 L.BLUE | E10: TA CHIANG SPINNING | F10: 117 | G10: YARD | H10: 201965 | I10: HA1521ORG
A11: 8 | B11: TCF0818 | C11: 2024 | D11: 4.25OZ-72" (26*200D) FHOSS ORANGE | E11: TA CHIANG SPINNING | F11: 311 | G11: YARD | H11: S26-1749 | I11: 6120
E12: TOTAL: | F12: =SUM(F4:F11) -> 586 | G12: YARD

Sheet 10.04.26
A1: FABRIC OLD STOCK CUTTING
A3: No | B3: Item Code | C3: YEAR | D3: Description | E3: Customer | F3: Quantity | G3: Unit | H3: PO | I3: STYLE
A4: 1 | B4: TCF0769 | C4: 2023 | D4: 7.1OZ-92.5" (SD12*SD12) RED-WPL | E4: TA CHIANG SPINNING | F4: 662 | G4: YARD | H4: 202011 | I4: O1114KRED
A5: 2 | B5: TCF0827 | C5: 2024 | D5: 6.14OZ-66" (SD12*300D) #K942 GOLD | E5: TA CHIANG SPINNING | F5: 311 | G5: YARD | H5: 202025 | I5: 0882KGLD
A6: 3 | B6: TCF0827 | C6: 2024 | D6: 6.14OZ-66" (SD12*300D) #K942 GOLD | E6: TA CHIANG SPINNING | F6: 103 | G6: YARD | H6: 202643 | I6: 1734GLD
A7: 4 | B7: TCF0828 | C7: 2024 | D7: 6.14OZ-66" (SD12*300D) #K555 KELLY GREEN | E7: TA CHIANG SPINNING | F7: 306 | G7: YARD | H7: 201979 | I7: 1754KGN
A8: 5 | B8: TCF0696 | C8: 2024 | D8: 6.35OZ-91.5" (SD12*300D) NAVY BLUE-WPL | E8: TA CHIANG SPINNING | F8: 3 | G8: YARD | H8: 201965(RECUT) | I8: O1125GRED
A9: 6 | B9: TCF0820 | C9: 2024 | D9: 6.14OZ-66" (OB12*300D) #AR WHITE | E9: TA CHIANG SPINNING | F9: 60 | G9: YARD | H9: 202517(RECUT) | I9: 4426WHT
A10: 7 | B10: TCF0820 | C10: 2024 | D10: 6.14OZ-66" (OB12*300D) #AR WHITE | E10: TA CHIANG SPINNING | F10: 13219 | G10: YARD | H10: 202047 202244 | I10: HA1521WHT A1536BWHT A1544GWHT 1117KG2PWHT 1117KWHT 1112GWHT
E11: TOTAL: | F11: =SUM(F4:F10) -> 14664 | G11: YARD

Sheet 24.04.26 
A1: FABRIC OLD STOCK CUTTING
A3: No | B3: Item Code | C3: YEAR | D3: Description | E3: Customer | F3: Quantity | G3: Unit | H3: PO | I3: STYLE
A4: 1 | B4: TCF0154 | C4: 2015 | D4: 3.5OZ/SD170-66" (SD30*T75D) #AR GREY | E4: TA CHIANG SPINNING | F4: 479 | G4: YARD | H4: TAIWAI | I4: CUSTOMER
A5: 2 | B5: TCF0144 | C5: 2018 | D5: 3.5OZ/SD170-66" (SD30*T75D) #AR APUA | E5: TA CHIANG SPINNING | F5: 500 | G5: YARD | H5: TAIWAI | I5: CUSTOMER
A6: 3 | B6: TCF0147 | C6: 2019 2020 | D6: 3.5OZ/SD170-66" (SD30*T75D) #AR ORANGE | E6: TA CHIANG SPINNING | F6: 500 | G6: YARD | H6: TAIWAI | I6: CUSTOMER
A7: 4 | B7: TCF0293 | C7: 2023 2021 2020 | D7: 3.5OZ-SD170-67" (OB30*T100D) #AR WHITE | E7: TA CHIANG SPINNING | F7: 500 | G7: YARD | H7: TAIWAI | I7: CUSTOMER
A8: 5 | B8: TCF0485 | C8: 2023 | D8: 3.5OZ/SD170-67" (SD30*T100D) #AR L.PINK | E8: TA CHIANG SPINNING | F8: 500 | G8: YARD | H8: TAIWAI | I8: CUSTOMER
A9: 6 | B9: TCF0297 | C9: 2024 | D9: 3.5OZ-SD170-67" (SD30*T100D) BROWN | E9: TA CHIANG SPINNING | F9: 414 | G9: YARD | H9: TAIWAI | I9: CUSTOMER
A10: 7 | B10: TCF0162 | C10: 2020 | D10: 7.1OZ/SDHV-66" (SD12*SD12) #K226 DARK NAVY | E10: TA CHIANG SPINNING | F10: 4 | G10: YARD | H10: SAMPLE | I10: COLD ROOM JACKET-DI3HD
A11: 8 | B11: TCF0569 | C11: 2021 | D11: 6.9OZ-59" (TC22*TC16 1/3 TWILL) 235gsm #HMD-KGREEN | E11: TA CHIANG SPINNING | F11: 25 | G11: YARD | H11: SUKL5072 | I11: GPPC733
E12: TOTAL: | F12: =SUM(F4:F11) -> 2922 | G12: YARD

Sheet 01.05.26 
A1: FABRIC OLD STOCK CUTTING
A3: No | B3: Item Code | C3: YEAR | D3: Description | E3: Customer | F3: Quantity | G3: Unit | H3: PO | I3: STYLE
A4: 1 | B4: TCF0075 | C4: 2016 | D4: 7.1OZ/SDHV-121" (SD12*SD12) #50105 BISCUIT | E4: TA CHIANG SPINNING | F4: 35 | G4: YARD | H4: SORD45314 | I4: P207-BG
A5: 2 | B5: TCF0487 | C5: 2021 | D5: 6.1OZ-68" (T300D*SD12) #K385 BLACK | E5: TA CHIANG SPINNING | F5: 146 | G5: YARD | H5: 6103 | I5: NPAP003034BLK-GL (AP10928)
A6: 3 | B6: TCF0518 | C6: 2023 | D6: 6.1OZ-68" (T300D*SD12) #K500 WHITE | E6: TA CHIANG SPINNING | F6: 232 | G6: YARD | H6: 6103 | I6: NPAP003034WHT-GL (AP10928)
A7: 4 | B7: TCF0061 | C7: 2023 | D7: 7.1OZ/SDHV-111" (SD12*SD12) #0614 DARK GREY | E7: TA CHIANG SPINNING | F7: 92 | G7: YARD | H7: SORD45314 | I7: P207-GR
A8: 5 | B8: TCF0591 | C8: 2024 | D8: 5.5OZ-66.5" (SD20*SD20) #MAG007 BURGUNDY | E8: TA CHIANG SPINNING | F8: 1813 | G8: YARD | H8: 6103 | I8: CC133XSMR-GL
A9: 6 | B9: TCF0594 | C9: 2024 | D9: 6.1OZ-68" (300D*SD12) #MAG007 BURGUNDY | E9: TA CHIANG SPINNING | F9: 158 | G9: YARD | H9: 6103 | I9: NPAP003034MR-GL (AP10928)
A10: 7 | B10: TCF0595 | C10: 2024 | D10: 6.1OZ-68" (300D*SD12) #MAG009 GREEN | E10: TA CHIANG SPINNING | F10: 74 | G10: YARD | H10: 6103 | I10: NPAP003034GR-GL (AP10928)
A11: 8 | B11: TCF0824 | C11: 2024 | D11: 6.14OZ-66" (SD12*300D) #K796 MAROON | E11: TA CHIANG SPINNING | F11: 2 | G11: YARD | H11: 201974(RECUT) | I11: 1521GMRN
E12: TOTAL: | F12: =SUM(F4:F11) -> 2552 | G12: YARD

Sheet 08.05.26 
A1: FABRIC OLD STOCK CUTTING
A3: No | B3: Item Code | C3: YEAR | D3: Description | E3: Customer | F3: Quantity | G3: Unit | H3: PO | I3: STYLE
A4: 1 | B4: TCF0162 | C4: 2020 | D4: 7.1OZ/SDHV-66" (SD12*SD12) #K226 DARK NAVY | E4: TA CHIANG SPINNING | F4: 3 | G4: YARD | H4: SAMPLE | I4: COLD ROOM JACKET-DI3HD
A5: 2 | B5: TCF0831 | C5: 2024 | D5: 7.1OZ/SDHV-111" (SD12*SD12) #0614 DARK GREY | E5: TA CHIANG SPINNING | F5: 3 | G5: YARD | H5: SAMPLE | I5: FOR CUSTOMER
A6: 3 | B6: TCF0104 | C6: 2024 | D6: 5.5OZ/SD135-66.5" (SD20*SD20) #FW457 NAVY | E6: TA CHIANG SPINNING | F6: 34 | G6: YARD | H6: 202394 | I6: A1317WNBL
A7: 4 | B7: TCF0824 | C7: 2024 | D7: 6.14OZ-66" (SD12*300D) #K796 MAROON | E7: TA CHIANG SPINNING | F7: 8 | G7: YARD | H7: SAMPLE | I7: 1744SS
A8: 5 | B8: TCF0827 | C8: 2024 | D8: 6.14OZ-66" (SD12*300D) #K942 GOLD | E8: TA CHIANG SPINNING | F8: 435 | G8: YARD | H8: 202746 | I8: 1425GLD
E9: TOTAL: | F9: =SUM(F4:F8) -> 483 | G9: YARD

Sheet 15.05.26
A1: FABRIC OLD STOCK CUTTING
A3: No | B3: Item Code | C3: YEAR | D3: Description | E3: Customer | F3: Quantity | G3: Unit | H3: PO | I3: STYLE
A4: 1 | B4: TCF0591 | C4: 2024 | D4: 5.5OZ-66.5" (SD20*SD20) #MAG007 BURGUNDY | E4: TA CHIANG SPINNING | F4: 220 | G4: YARD | H4: 6103 | I4: CC133XSMR-GL
E5: TOTAL: | F5: =SUM(F4:F4) -> 220 | G5: YARD

Sheet 22.05.26 
A1: FABRIC OLD STOCK CUTTING
A3: No | B3: Item Code | C3: YEAR | D3: Description | E3: Customer | F3: Quantity | G3: Unit | H3: PO | I3: STYLE
A4: 1 | B4: TCF0487 | C4: 2021 | D4: 6.1OZ-68" (T300D*SD12) #K385 BLACK | E4: TA CHIANG SPINNING | F4: 2443 | G4: YARD | H4: 5163 | I4: 413-BK
A5: 2 | B5: TCF0104 | C5: 2023 | D5: 5.5OZ/SD135-66.5" (SD20*SD20) #FW457 NAVY | E5: TA CHIANG SPINNING | F5: 316 | G5: YARD | H5: 202260 | I5: A1535BNBL
A6: 3 | B6: TCF0646 | C6: 2023 | D6: 6.35OZ-64.5" (SD12*300D) GRAY WPL | E6: TA CHIANG SPINNING | F6: 145 | G6: YARD | H6: 6274 | I6: DF133GY-GL
A7: 4 | B7: TCF0828 | C7: 2024 | D7: 6.14OZ-66" (SD12*300D) #K555 KELLY GREEN | E7: TA CHIANG SPINNING | F7: 248 | G7: YARD | H7: 202260 | I7: 0882GKGN
A8: 5 | B8: TCF0824 | C8: 2024 | D8: 6.14OZ-66" (SD12*300D) #K796 MAROON | E8: TA CHIANG SPINNING | F8: 337 | G8: YARD | H8: 202578 | I8: 1518CBMGY
A9: 6 | B9: TCF0658 | C9: 2024 | D9: 6.35OZ-109.5" (SD12*300D) GRAY WPL | E9: TA CHIANG SPINNING | F9: 500 | G9: YARD | H9: 6274 | I9: DF133GY-GL
A10: 7 | B10: TCF0747 | C10: 2024 | D10: 6.35OZ-132" (SD12*300D) GRAY WPL | E10: TA CHIANG SPINNING | F10: 237 | G10: YARD | H10: 6274 | I10: DF133GY-GL
A11: 8 | B11: TCF0027 | C11: 2024 | D11: 5.5OZ/SD135-66.5" (OB20*OB20) #AR WHITE | E11: TA CHIANG SPINNING | F11: 132 | G11: YARD | H11: S26-1542 | I11: 4458NU
A12: 9 | B12: TCF0591 | C12: 2024 | D12: 5.5OZ-66.5" (SD20*SD20) #MAG007 BURGUNDY | E12: TA CHIANG SPINNING | F12: 7 | G12: YARD | H12: 6103 | I12: CC133MR-GL
A13: 10 | B13: TCF0130 | C13: 2024 | D13: 4.5OZ/T150-72.5" (OB26*OB26) #ALSCO WHITE | E13: TA CHIANG SPINNING | F13: 23 | G13: YARD | H13: 5474 | I13: 103WPL
A14: 11 | B14: TCF0823 | C14: 2024 | D14: 6.14OZ-66" (SD12*300D) #K797 RED | E14: TA CHIANG SPINNING | F14: 194 | G14: YARD | H14: 202578 | I14: 1754RED
E15: TOTAL: | F15: =SUM(F4:F14) -> 4582 | G15: YARD

Sheet 29.05.26 
A1: FABRIC OLD STOCK CUTTING
A3: No | B3: Item Code | C3: YEAR | D3: Description | E3: Customer | F3: Quantity | G3: Unit | H3: PO | I3: STYLE
A4: 1 | B4: TCF0075 | C4: 2017 | D4: 6.1OZ-68" (T300D*SD12) #K385 BLACK | E4: TA CHIANG SPINNING | F4: 138 | G4: YARD | H4: SORD45410 | I4: P207-BG
A5: 2 | B5: TCF0214 | C5: 2021(NIS) | D5: 7.1OZ/SDHV-65" (SD12*SD12) #K320 BURGUNDY | E5: TA CHIANG SPINNING | F5: 102 | G5: YARD | H5: 6274 | I5: DF133GY-GL(CONTRAST COLLAR & CUFFS)
A6: 3 | B6: TCF0104 | C6: 2023 2024 | D6: 5.5OZ/SD135-66.5" (SD20*SD20) #FW457 NAVY | E6: TA CHIANG SPINNING | F6: 351 | G6: YARD | H6: 202260 202643 202979 | I6: A1535BNBL
A7: 4 | B7: TCF0820 | C7: 2024 | D7: 6.14OZ-66" (OB12*300D) #AR WHITE | E7: TA CHIANG SPINNING | F7: 34 | G7: YARD | H7: 20244623 | I7: HA1521
A8: 5 | B8: TCF0831 | C8: 2024 | D8: 4.1OZ-60" EYE MESH DOUBLE KNIT (RECYCLE) #AR WHITE | E8: TA CHIANG SPINNING | F8: 10 | G8: YARD | H8: SAMPLE | I8: FOR CUSTOMER
A9: 6 | B9: TCF0747 | C9: 2024 | D9: 6.35OZ-132" (SD12*300D) GRAY WPL | E9: TA CHIANG SPINNING | F9: 108 | G9: YARD | H9: 6274 | I9: DF133GY-GL
E10: TOTAL: | F10: =SUM(F4:F9) -> 743 | G10: YARD

Sheet 05.06.26 
A1: FABRIC OLD STOCK CUTTING
A3: No | B3: Item Code | C3: YEAR | D3: Description | E3: Customer | F3: Quantity | G3: Unit | H3: PO | I3: STYLE
A4: 1 | B4: TCF0130 | C4: 2024 | D4: 4.5OZ/T150-72.5" (OB26*OB26) #ALSCO WHITE | E4: TA CHIANG SPINNING | F4: 10 | G4: YARD | H4: 5474(RECUT) | I4: 103WPL
A5: 2 | B5: TCF0056 | C5: 2023 | D5: 7.1OZ/SDHV-111" (SD12*SD12) #5966 IVORY | E5: TA CHIANG SPINNING | F5: 310 | G5: YARD | H5: SSNG14604 | I5: NASP20-IV
A6: 3 | B6: TCF0820 | C6: 2024 | D6: 6.14OZ-66" (OB12*300D) #AR WHITE | E6: TA CHIANG SPINNING | F6: 15 | G6: YARD | H6: 20244623(RECUT) | I6: HA1521
A7: 4 | B7: TCF0828 | C7: 2024 | D7: 6.14OZ-66" (SD12*300D) #K555 KELLY GREEN | E7: TA CHIANG SPINNING | F7: 11 | G7: YARD | H7: 202260(RECUT) | I7: 0882GKGN
A8: 5 | B8: TCF0747 | C8: 2024 | D8: 6.35OZ-132" (SD12*300D) GRAY WPL | E8: TA CHIANG SPINNING | F8: 10 | G8: YARD | H8: 6274(RECUT) | I8: DF133GY-GL
E9: TOTAL: | F9: =SUM(F4:F8) -> 356 | G9: YARD

Sheet 12.06.26 
A1: FABRIC OLD STOCK CUTTING
A3: No | B3: Item Code | C3: YEAR | D3: Description | E3: Customer | F3: Quantity | G3: Unit | H3: PO | I3: STYLE
A4: 1 | B4: TCF0104 | C4: 2024 | D4: 5.5OZ/SD135-66.5" (SD20*SD20) #FW457 NAVY | E4: TA CHIANG SPINNING | F4: 10 | G4: YARD | H4: 202260(RECUT) | I4: A1535BNBL
A5: 2 | B5: TCF0607 | C5: 2023 | D5: 6.35OZ-54" (SD12*300D) CHAMP-WPL | E5: TA CHIANG SPINNING | F5: 1 | G5: YARD | H5: SAMPLE | I5: ORANGE PANTS
A6: 3 | B6: TCF0160 | C6: 2024 | D6: 7.1OZ/SDHV-65" (SD12*SD12) #K126 NAVY | E6: TA CHIANG SPINNING | F6: 88 | G6: YARD | H6: 202517 | I6: A0882GNBL
A7: 4 | B7: TCF0820 | C7: 2024 | D7: 6.14OZ-66" (OB12*300D) #AR WHITE | E7: TA CHIANG SPINNING | F7: 17 | G7: YARD | H7: 20244623(RECUT) | I7: HA1521
A8: 5 | B8: TCF0824 | C8: 2024 | D8: 6.14OZ-66" (SD12*300D) #K796 MAROON | E8: TA CHIANG SPINNING | F8: 1007 | G8: YARD | H8: 202517 | I8: HA1521MRN
A9: 6 | B9: TCF0827 | C9: 2024 | D9: 6.14OZ-66" (SD12*300D) #K942 GOLD | E9: TA CHIANG SPINNING | F9: 419 | G9: YARD | H9: 2028 | I9: 4438GLD
A10: 7 | B10: TCF0827 | C10: 2024 | D10: 6.14OZ-66" (SD12*300D) #K942 GOLD | E10: TA CHIANG SPINNING | F10: 964 | G10: YARD | H10: 202578 | I10: 1112GGLD
A11: 8 | B11: TCF0831 | C11: 2024 | D11: 4.1OZ-60" EYE MESH DOUBLE KNIT (RECYCLE) #AR WHITE | E11: TA CHIANG SPINNING | F11: 10 | G11: YARD | H11: SAMPLE | I11: LS250MH
A12: 9 | B12: TCF0831 | C12: 2024 | D12: 4.1OZ-60" EYE MESH DOUBLE KNIT (RECYCLE) #AR WHITE | E12: TA CHIANG SPINNING | F12: 66 | G12: YARD | H12: SSNG14645 | I12: GCRCLS320ZF
E13: TOTAL: | F13: =SUM(F4:F12) -> 2582 | G13: YARD

Sheet 19.06.26 
A1: FABRIC OLD STOCK CUTTING
A3: No | B3: Item Code | C3: YEAR | D3: Description | E3: Customer | F3: Quantity | G3: Unit | H3: PO | I3: STYLE
A4: 1 | B4: TCF0233 | C4: 2022 | D4: 6.35OZ-54" (SD12*300D) CHAMP-WPL | E4: TA CHIANG SPINNING | F4: 4 | G4: YARD | H4: SAMPLE | I4: VRT875
A5: 2 | B5: TCF0820 | C5: 2024 | D5: 6.14OZ-66" (OB12*300D) #AR WHITE | E5: TA CHIANG SPINNING | F5: 10 | G5: YARD | H5: 20232117(RECUT) | I5: HA1521
A6: 3 | B6: TCF0824 | C6: 2024 | D6: 6.14OZ-66" (SD12*300D) #K796 MAROON | E6: TA CHIANG SPINNING | F6: 253 | G6: YARD | H6: 202727 | I6: 1119SMRN
E7: TOTAL: | F7: =SUM(F4:F6) -> 267 | G7: YARD

Sheet 26.06.26 
A1: FABRIC OLD STOCK CUTTING
A3: No | B3: Item Code | C3: YEAR | D3: Description | E3: Customer | F3: Quantity | G3: Unit | H3: PO | I3: STYLE
A4: 1 | B4: TCF0027 | C4: 2024 | D4: 7.1OZ/SDHV-65" (SD12*SD12) #K126 NAVY | E4: TA CHIANG SPINNING | F4: 3193 | G4: YARD | H4: 202517 | I4: A0882GNBL
A5: 2 | B5: TCF0605 | C5: 2024 | D5: 5.75OZ-58.5" (T/C21*T/C21) #433C BLACK | E5: TA CHIANG SPINNING | F5: 108 | G5: YARD | H5: SSNG14474 | I5: GPPC393SF
A6: 3 | B6: TCF0820 | C6: 2024 | D6: 6.14OZ-66" (OB12*300D) #AR WHITE | E6: TA CHIANG SPINNING | F6: 15 | G6: YARD | H6: 20232117(RECUT) | I6: HA1521
E7: TOTAL: | F7: =SUM(F4:F6) -> 3316 | G7: YARD

Sheet Sheet2
A1: FABRIC OLD STOCK CUTTING
A3: No | B3: Item Code | C3: YEAR | D3: Description | E3: Customer | F3: Quantity | G3: Unit | H3: PO | I3: STYLE
A4: 1 | B4: GRB0001 | C4: 2021 | D4: 7.1OZ/SDHV-55.5" (OB12*OB12) #ALSCO WHITE | E4: TA CHIANG SPINNING | F4: 149 | G4: YARD | H4: S26-1107 | I4: 6137-R
A5: 2 | B5: GRB0010 | C5: 2021 | D5: 7.1OZ/SDHV-92.5" (OB12*OB12) #ALSCO WHITE | E5: TA CHIANG SPINNING | F5: 606 | G5: YARD | H5: S26-1107 | I5: 6137-R
A6: 3 | B6: GRB0020 | C6: 2021 | D6: 7.1OZ/SDHV-121" (OB12*OB12) #ALSCO WHITE | E6: TA CHIANG SPINNING | F6: 128 | G6: YARD | H6: S26-1107 | I6: 6137-R
A7: 4 | B7: TCF0007 | C7: 2022 | D7: 7.1OZ/SDHV-111" (SD12*SD12) #0614 DARK GREY | E7: Australia Return | F7: 1080 | G7: YARD | H7: SORD44594 | I7: P207-GR
A8: 5 | B8: TCF0019 | C8: 2014 | D8: 7.1OZ/SDHV-111" (SD12*SD12) #3580 YELLOW LEMON | E8: TA CHIANG SPINNING | F8: 126 | G8: YARD | H8: 201715 | I8: O1114YEL
A9: 6 | B9: TCF0019 | C9: 2014 | D9: 7.1OZ/SDHV-111" (SD12*SD12) #3580 YELLOW LEMON | E9: TA CHIANG SPINNING | F9: 10 | G9: YARD | H9: 201715(recut) | I9: O1114YEL
A10: 7 | B10: TCF0020 | C10: 2024 | D10: 5.5OZ/SD135-66.5" (OB20*OB20) #AR WHITE | E10: Australia Return | F10: 990 | G10: YARD | H10: S26-1107 | I10: 6137-T
A11: 8 | B11: TCF0027 | C11: 2024 | D11: 5.5OZ/SD135-66.5" (OB20*OB20) #AR WHITE | E11: TA CHIANG SPINNING | F11: 39 | G11: YARD | I11: DI-8VPU
A12: 9 | B12: TCF0027 | C12: 2024 | D12: 5.5OZ/SD135-66.5" (OB20*OB20) #AR WHITE | E12: TA CHIANG SPINNING | F12: 3731 | G12: YARD | H12: S26-1107 | I12: 6137-T
A13: 10 | B13: TCF0027 | C13: 2024 | D13: 5.5OZ/SD135-66.5" (OB20*OB20) #AR WHITE | E13: TA CHIANG SPINNING | F13: 201 | G13: YARD | H13: 201291 | I13: A1316WWHT
A14: 11 | B14: TCF0027 | C14: 2024 | D14: 5.5OZ/SD135-66.5" (OB20*OB20) #AR WHITE | E14: TA CHIANG SPINNING | F14: 31 | G14: YARD | H14: SAMPLE | I14: DI-860
A15: 12 | B15: TCF0027 | C15: 2024 | D15: 5.5OZ/SD135-66.5" (OB20*OB20) #AR WHITE | E15: TA CHIANG SPINNING | F15: 139 | G15: YARD | H15: 201785 | I15: O1544GWHT
A16: 13 | B16: TCF0040 | C16: 2015 | D16: 8.46OZ/FH21-64.5" (300D/1*SP12/1) YELLOW | E16: TA CHIANG SPINNING | F16: 2 | G16: YARD | H16: TES | I16: 6137-R
A17: 14 | B17: TCF0040 | C17: 2015 | D17: 8.46OZ/FH21-64.5" (300D/1*SP12/1) YELLOW | E17: TA CHIANG SPINNING | F17: 1747 | G17: YARD | H17: S26-1107 | I17: 6137-R
A18: 15 | B18: TCF0058 | C18: 2016 | D18: 7.1OZ/SDHV-121" (SD12*SD12) #7946 MAROON | E18: TA CHIANG SPINNING | F18: 124 | G18: YARD | H18: SSNG13881 | I18: NASP20-MN
A19: 16 | B19: TCF0061 | C19: 2022 | D19: 7.1OZ/SDHV-111" (SD12*SD12) #0614 DARK GREY | E19: TA CHIANG SPINNING | F19: 123 | G19: YARD | H19: SORD44594 | I19: P207-GR
A20: 17 | B20: TCF0075 | C20: 2020 | D20: 3.5OZ/SD170-67" (SD30*T75D) #AR YELLOW | E20: TA CHIANG SPINNING | F20: 105 | G20: YARD | H20: SORD44550 | I20: P207-BG
A21: 18 | B21: TCF0084 | C21: 2024 | D21: 5.5OZ/SD135-66.5" (OB20*OB20) #FW257 L.BLUE | E21: TA CHIANG SPINNING | F21: 123 | G21: YARD | H21: 201291 | I21: A1541GLBL
A22: 19 | B22: TCF0104 | C22: 2024 | D22: 5.5OZ/SD135-66.5" (SD20*SD20) #FW457 NAVY | E22: TA CHIANG SPINNING | F22: 252 | G22: YARD | H22: 201291 | I22: A1537BNBL
A23: 20 | B23: TCF0104 | C23: 2024 | D23: 5.5OZ/SD135-66.5" (SD20*SD20) #FW457 NAVY | E23: TA CHIANG SPINNING | F23: 975 | G23: YARD | H23: 10824 | I23: CC133-NB
A24: 21 | B24: TCF0124 | C24: 2024 | D24: 7.1OZ/SDHV-67" (SD12*OB12) NAVY/WHITE STRIPE | E24: TA CHIANG SPINNING | F24: 164 | G24: YARD | H24: SFOR1404
A25: 22 | B25: TCF0124 | C25: 2024 | D25: 7.1OZ/SDHV-121" (SD12*SD12) #0155 NAVY | E25: TA CHIANG SPINNING | F25: 165 | G25: YARD | H25: RECUT | I25: P207-N
A26: 23 | B26: TCF0130 | C26: 2024 | D26: 4.5OZ/T150-72.5" (OB26*OB26) #ALSCO WHITE | E26: TA CHIANG SPINNING | F26: 179 | G26: YARD | H26: 200995
A27: 24 | B27: TCF0130 | C27: 2024 | D27: 4.5OZ/T150-72.5" (OB26*OB26) #ALSCO WHITE | E27: TA CHIANG SPINNING | F27: 171 | G27: YARD | H27: 201291 | I27: 2051GWHT
A28: 25 | B28: TCF0130 | C28: 2024 | D28: 4.5OZ/T150-72.5" (OB26*OB26) #ALSCO WHITE | E28: TA CHIANG SPINNING | F28: 90 | G28: YARD | H28: RECUT | I28: BL06272025
A29: 26 | B29: TCF0130 | C29: 2024 | D29: 4.5OZ/T150-72.5" (OB26*OB26) #ALSCO WHITE | E29: TA CHIANG SPINNING | F29: 1203 | G29: YARD | H29: 201785 | I29: 2051GWHT
A30: 27 | B30: TCF0130 | C30: 2024 | D30: 4.5OZ/T150-72.5" (OB26*OB26) #ALSCO WHITE | E30: TA CHIANG SPINNING | F30: 15 | G30: YARD | H30: 201785(recut) | I30: 2051GWHT
A31: 28 | B31: TCF0144 | C31: 2018 | D31: 3.5OZ/SD170-66" (SD30*T75D) #AR APUA | E31: TA CHIANG SPINNING | F31: 1 | G31: YARD | H31: A416222 | I31: GO2134
A32: 29 | B32: TCF0182 | C32: 2020 | D32: 3.5OZ/SD170-67" (SD30*T75D) #AR YELLOW | E32: TA CHIANG SPINNING | F32: 10 | G32: YARD | H32: A416222 | I32: GSC978
A33: 30 | B33: TCF0204 | C33: 2022 | D33: 7.1OZ/SDHV-65" (SD12*SD12) #K326 BROWN | E33: TA CHIANG SPINNING | F33: 301 | G33: YARD | H33: 201715 | I33: A7756BRN
A34: 31 | B34: TCF0214 | C34: 2024 | D34: 7.1OZ/SDHV-65" (SD12*SD12) #K320 BURGUNDY | E34: TA CHIANG SPINNING | F34: 99 | G34: YARD | H34: 201785 | I34: A1037GMRN
A35: 32 | B35: TCF0214 | C35: 2024 | D35: 7.1OZ/SDHV-65" (SD12*SD12) #K320 BURGUNDY | E35: TA CHIANG SPINNING | F35: 109 | G35: YARD | H35: 201832 | I35: O1114KMRN
A36: 33 | B36: TCF0214 | C36: 2024 | D36: 7.1OZ/SDHV-65" (SD12*SD12) #K320 BURGUNDY | E36: TA CHIANG SPINNING | F36: 27 | G36: YARD | H36: 201785 (RECUT) | I36: A1037GMRN
A37: 34 | B37: TCF0293 | C37: 2023 | D37: 3.5OZ-SD170-67" (OB30*T100D) #AR WHITE | E37: TA CHIANG SPINNING | F37: 11 | G37: YARD | H37: A416222 | I37: GO2134
A38: 35 | B38: TCF0327 | C38: 2017 | D38: 7.1OZ/SDHV-64.5" (SD12*SD12) #HMD GOLD | E38: TA CHIANG SPINNING | F38: 147 | G38: YARD | H38: 201832 | I38: O1114KGLD
A39: 36 | B39: TCF0362 | C39: 2024 | D39: 7.1OZ/SDHV-67" (SD12*OB12) NAVY/WHITE STRIPE | E39: TA CHIANG SPINNING | F39: 491 | G39: YARD | H39: SORD44542 | I39: AP154-NWP
A40: 37 | B40: TCF0362 | C40: 2024 | D40: 7.1OZ/SDHV-67" (SD12*OB12) NAVY/WHITE STRIPE | E40: TA CHIANG SPINNING | F40: 46 | G40: YARD | H40: RECUT
A41: 38 | B41: TCF0362 | C41: 2024 | D41: 7.1OZ/SDHV-67" (SD12*OB12) NAVY/WHITE STRIPE | E41: TA CHIANG SPINNING | F41: 1120 | G41: YARD | H41: SORD44594 | I41: AP154-NWP
...
