Workbook

Sheet 9-10
B1: ​​​ របាយការណ៏ដូរ​បន្លាស់ប្រចាំថ្ងៃ Daily Spare Part Change Report 每日备件更换报告 | G1: 46304 | J1: ការផ្លាស់ប្តូរគ្រឿងបន្លាស់សម្រាប់ខ្សែសង្វាក់ផលិតកម្មដេរ, Spare Part Change For Sewing Line , 缝纫线备件更换
A2: លរ​ No. 数字 | B2: ប្រភេទគ្រឿងបន្លាស់ Sparepart Type 备件类型 | C2: ទំហំ​ SIZE 尺寸 | D2: ចំនួននៅសល់ Stock Left 剩余库存 | E2: ម្ជុលដែលបានផ្តល់ជូន, Issued Needle, 已发放的针头 | F2: តុល្យភាព Balance 平衡 | G2: សំគាល់ Remark 评论 | J2: # 1 | K2: # 2 | L2: # 3 | M2: # 4 | N2: # 5 | O2: # 6 | P2: # 7 | Q2: # 8 | R2: # 9 | S2: # 10 | T2: # 11 | U2: # 12
A3: =IF(B3="","",COUNTA($B$3:B3)) -> 1 | B3: សំបុក Rotary Hook 旋梭 | C3: តូច small​ 小 | D3: 8 | E3: =SUM(J3:U3) -> 0 | F3: =D3-E3 -> 8 | X3: ខូច​ Damage 损害
A4: =IF(B4="","",COUNTA($B$3:B4)) -> 2 | B4: ធ្មេញរង្វើល Feed Dog 送布牙 | C4: តូច small​ 小 | D4: 60 | E4: =SUM(J4:U4) -> 0 | F4: =D4-E4 -> 60 | X4: បាក់​ Broken 破碎的
A5: =IF(B5="","",COUNTA($B$3:B5)) -> 3 | B5: ធ្មេញញឺក Feed Dog fits适用于送布牙 | C5: តូច small​ 小 | D5: 8 | E5: =SUM(J5:U5) -> 0 | F5: =D5-E5 -> 8 | X5: ប្តូរម៉ូដ Change Style, 更改样式
A6: =IF(B6="","",COUNTA($B$3:B6)) -> 4 | B6: សន្ទះធ្មេញ Needle Plate 针板 | C6: តូច small​ 小 | D6: 13 | E6: =SUM(J6:U6) -> 0 | F6: =D6-E6 -> 13 | X6: បាត់​ Lost 迷失
A7: =IF(B7="","",COUNTA($B$3:B7)) -> 5 | B7: សន្ទះធ្មេញទុន Needle Plate 针板 | C7: តូច small​ 小 | D7: 3 | E7: =SUM(J7:U7) -> 0 | F7: =D7-E7 -> 3 | X7: ផ្សេងៗ​ Other 其他
A8: =IF(B8="","",COUNTA($B$3:B8)) -> 6 | B8: កាំបិទលើJ Fixed Knife for JUKI JUKI用固定刀 | C8: តូច small​ 小 | D8: 25 | E8: =SUM(J8:U8) -> 0 | F8: =D8-E8 -> 25
A9: =IF(B9="","",COUNTA($B$3:B9)) -> 7 | B9: កាំបិទក្រោមS, Thread Cutter Blade For Sirubar, Sirubar 切线刀片 | C9: តូច small​ 小 | D9: 15 | E9: =SUM(J9:U9) -> 0 | F9: =D9-E9 -> 15
A10: =IF(B10="","",COUNTA($B$3:B10)) -> 8 | B10: សន្លឺកស្រូវJ Thread Guide For JUKI,JUKI 穿线导向器 | C10: តូច small​ 小 | D10: 2 | E10: =SUM(J10:U10) -> 0 | F10: =D10-E10 -> 2
A11: =IF(B11="","",COUNTA($B$3:B11)) -> 9 | B11: សន្លឺកស្រូវS Thread Finger For Sirubar,适用于 Siruba 的过线指 | C11: តូច small​ 小 | D11: 4 | E11: =SUM(J11:U11) -> 0 | F11: =D11-E11 -> 4
A12: =IF(B12="","",COUNTA($B$3:B12)) -> 10 | B12: កាំបិទលើS Fixed Knif For Sirubar,Sirubar 固定刀片 | C12: តូច small​ 小 | D12: 0 | E12: =SUM(J12:U12) -> 0 | F12: =D12-E12 -> 0
A13: =IF(B13="","",COUNTA($B$3:B13)) -> 11 | B13: កាំបិទក្រោមS,Movable Knife For Sirubar,Siruba 动刀 Sirubar | C13: តូច small​ 小 | D13: 0 | E13: =SUM(J13:U13) -> 0 | F13: =D13-E13 -> 0
A14: =IF(B14="","",COUNTA($B$3:B14)) -> 12 | B14: ដែកបុកកាក់ Dowel Pin,定位销 | C14: តូច small​ 小 | D14: 7 | E14: =SUM(J14:U14) -> 0 | F14: =D14-E14 -> 7
A15: =IF(B15="","",COUNTA($B$3:B15)) -> 13 | B15: ផ្ទាំងបញ្ជាខៀវJ,Blue control Panel JUKI,JUKI 蓝色控制面板 | C15: តូច small​ 小 | D15: 6 | E15: =SUM(J15:U15) -> 0 | F15: =D15-E15 -> 6
A16: =IF(B16="","",COUNTA($B$3:B16)) -> 14 | B16: ផ្ទាំងបញ្ជាសJ White color control Panel JUKI,JUKI 白色控制面板 | C16: តូច small​ 小 | D16: 3 | E16: =SUM(J16:U16) -> 0 | F16: =D16-E16 -> 3
A17: =IF(B17="","",COUNTA($B$3:B17)) -> 15 | B17: ផ្ទាំងបញ្ជាជំនាន់ចាស់J, Old Verson Board JUKI,JUKI 旧版电路板 | C17: តូច small​ 小 | D17: 3 | E17: =SUM(J17:U17) -> 0 | F17: =D17-E17 -> 3
A18: =IF(B18="","",COUNTA($B$3:B18)) -> 16 | B18: ខ្សែរទាញកាក់,CABLE ASSY, HOOD LOCK CONTROL,发动机罩锁控制拉索组件 | C18: តូច small​ 小 | D18: 2 | E18: =SUM(J18:U18) -> 0 | F18: =D18-E18 -> 2
A19: =IF(B19="","",COUNTA($B$3:B19)) -> 17 | B19: ជ័រខារអំបោះ,Bobbin winder rubber ring,绕线器橡胶圈 | C19: តូច small​ 小 | D19: 42 | E19: =SUM(J19:U19) -> 0 | F19: =D19-E19 -> 42
... A81: =IF(B81="","",COUNTA($B$3:B81)) -> 79 | B81: កាំបិតក្រោម, Bottom Thread Trimmer, 底线切线器 | C81: តូច small​ 小 | D81: 0 | E81: =SUM(J81:U81) -> 0 | F81: =D81-E81 -> 0
A82: =IF(B82="","",COUNTA($B$3:B82))

Sheet 9-11
B1: ​​​ របាយការណ៏ដូរ​បន្លាស់ប្រចាំថ្ងៃ Daily Spare Part Change Report 每日备件更换报告 | G1: 46335 | J1: ការផ្លាស់ប្តូរគ្រឿងបន្លាស់សម្រាប់ខ្សែសង្វាក់ផលិតកម្មដេរ, Spare Part Change For Sewing Line , 缝纫线备件更换
A2: លរ​ No. 数字 | B2: ប្រភេទគ្រឿងបន្លាស់ Sparepart Type 备件类型 | C2: ទំហំ​ SIZE 尺寸 | D2: ចំនួននៅសល់ Stock Left 剩余库存 | E2: ម្ជុលដែលបានផ្តល់ជូន, Issued Needle, 已发放的针头 | F2: តុល្យភាព Balance 平衡 | G2: សំគាល់ Remark 评论 | J2: # 1 | K2: # 2 | L2: # 3 | M2: # 4 | N2: # 5 | O2: # 6 | P2: # 7 | Q2: # 8 | R2: # 9 | S2: # 10 | T2: # 11 | U2: # 12
A3: =IF(B3="","",COUNTA($B$3:B3)) -> 1 | B3: សំបុក Rotary Hook 旋梭 | C3: តូច small​ 小 | D3: ='9-10'!F3 -> 8 | E3: =SUM(J3:U3) -> 2 | F3: =D3-E3 -> 6 | G3: ខូច​ Damage 损害 | J3: 1 | L3: 1 | X3: ខូច​ Damage 损害
A4: =IF(B4="","",COUNTA($B$3:B4)) -> 2 | B4: ធ្មេញរង្វើល Feed Dog 送布牙 | C4: តូច small​ 小 | D4: ='9-10'!F4 -> 60 | E4: =SUM(J4:U4) -> 0 | F4: =D4-E4 -> 60 | G4: ខូច​ Damage 损害 | X4: បាក់​ Broken 破碎的
A5: =IF(B5="","",COUNTA($B$3:B5)) -> 3 | B5: ធ្មេញញឺក Feed Dog fits适用于送布牙 | C5: តូច small​ 小 | D5: ='9-10'!F5 -> 8 | E5: =SUM(J5:U5) -> 0 | F5: =D5-E5 -> 8 | X5: ប្តូរម៉ូដ Change Style, 更改样式
A6: =IF(B6="","",COUNTA($B$3:B6)) -> 4 | B6: សន្ទះធ្មេញ Needle Plate 针板 | C6: តូច small​ 小 | D6: ='9-10'!F6 -> 13 | E6: =SUM(J6:U6) -> 1 | F6: =D6-E6 -> 12 | G6: ខូច​ Damage 损害 | J6: 1 | X6: បាត់​ Lost 迷失
A7: =IF(B7="","",COUNTA($B$3:B7)) -> 5 | B7: សន្ទះធ្មេញទុន Needle Plate 针板 | C7: តូច small​ 小 | D7: ='9-10'!F7 -> 3 | E7: =SUM(J7:U7) -> 0 | F7: =D7-E7 -> 3 | X7: ផ្សេងៗ​ Other 其他
A8: =IF(B8="","",COUNTA($B$3:B8)) -> 6 | B8: កាំបិទលើJ Fixed Knife for JUKI JUKI用固定刀 | C8: តូច small​ 小 | D8: ='9-10'!F8 -> 25 | E8: =SUM(J8:U8) -> 2 | F8: =D8-E8 -> 23 | M8: 1 | P8: 1
A9: =IF(B9="","",COUNTA($B$3:B9)) -> 7 | B9: កាំបិទក្រោមS, Thread Cutter Blade For Sirubar, Sirubar 切线刀片 | C9: តូច small​ 小 | D9: ='9-10'!F9 -> 15 | E9: =SUM(J9:U9) -> 1 | F9: =D9-E9 -> 14 | O9: 1
A10: =IF(B10="","",COUNTA($B$3:B10)) -> 8 | B10: សន្លឺកស្រូវJ Thread Guide For JUKI,JUKI 穿线导向器 | C10: តូច small​ 小 | D10: ='9-10'!F10 -> 2 | E10: =SUM(J10:U10) -> 0 | F10: =D10-E10 -> 2
A11: =IF(B11="","",COUNTA($B$3:B11)) -> 9 | B11: សន្លឺកស្រូវS Thread Finger For Sirubar,适用于 Siruba 的过线指 | C11: តូច small​ 小 | D11: ='9-10'!F11 -> 4 | E11: =SUM(J11:U11) -> 0 | F11: =D11-E11 -> 4
A12: =IF(B12="","",COUNTA($B$3:B12)) -> 10 | B12: កាំបិទលើS Fixed Knif For Sirubar,Sirubar 固定刀片 | C12: តូច small​ 小 | D12: ='9-10'!F12 -> 0 | E12: =SUM(J12:U12) -> 0 | F12: =D12-E12 -> 0
A13: =IF(B13="","",COUNTA($B$3:B13)) -> 11 | B13: កាំបិទក្រោមS,Movable Knife For Sirubar,Siruba 动刀 Sirubar | C13: តូច small​ 小 | D13: ='9-10'!F13 -> 0 | E13: =SUM(J13:U13) -> 0 | F13: =D13-E13 -> 0
A14: =IF(B14="","",COUNTA($B$3:B14)) -> 12 | B14: ដែកបុកកាក់ Dowel Pin,定位销 | C14: តូច small​ 小 | D14: ='9-10'!F14 -> 7 | E14: =SUM(J14:U14) -> 0 | F14: =D14-E14 -> 7
A15: =IF(B15="","",COUNTA($B$3:B15)) -> 13 | B15: ផ្ទាំងបញ្ជាខៀវJ,Blue control Panel JUKI,JUKI 蓝色控制面板 | C15: តូច small​ 小 | D15: ='9-10'!F15 -> 6 | E15: =SUM(J15:U15) -> 1 | F15: =D15-E15 -> 5 | M15: 1
A16: =IF(B16="","",COUNTA($B$3:B16)) -> 14 | B16: ផ្ទាំងបញ្ជាសJ White color control Panel JUKI,JUKI 白色控制面板 | C16: តូច small​ 小 | D16: ='9-10'!F16 -> 3 | E16: =SUM(J16:U16) -> 0 | F16: =D16-E16 -> 3
A17: =IF(B17="","",COUNTA($B$3:B17)) -> 15 | B17: ផ្ទាំងបញ្ជាជំនាន់ចាស់J, Old Verson Board JUKI,JUKI 旧版电路板 | C17: តូច small​ 小 | D17: ='9-10'!F17 -> 3 | E17: =SUM(J17:U17) -> 0 | F17: =D17-E17 -> 3
A18: =IF(B18="","",COUNTA($B$3:B18)) -> 16 | B18: ខ្សែរទាញកាក់,CABLE ASSY, HOOD LOCK CONTROL,发动机罩锁控制拉索组件 | C18: តូច small​ 小 | D18: ='9-10'!F18 -> 2 | E18: =SUM(J18:U18) -> 0 | F18: =D18-E18 -> 2
A19: =IF(B19="","",COUNTA($B$3:B19)) -> 17 | B19: ជ័រខារអំបោះ,Bobbin winder rubber ring,绕线器橡胶圈 | C19: តូច small​ 小 | D19: ='9-10'!F19 -> 42 | E19: =SUM(J19:U19) -> 0 | F19: =D19-E19 -> 42
A20: =IF(B20="","",COUNTA($B$3:B20)) -> 18 | B20: កាក់ធំ,Thread Tention Assembly,张力调节组件 | C20: ធំ Big 大的 | D20: ='9-10'!F20 -> 2 | E20: =SUM(J20:U20) -> 0 | F20: =D20-E20 -> 2
A21: =IF(B21="","",COUNTA($B$3:B21)) -> 19 | B21: កាក់តូច,Thread Tension Assembly Small,小型线张力组件 | C21: តូច small​ 小 | D21: ='9-10'!F21 -> 20 | E21: =SUM(J21:U21) -> 1 | F21: =D21-E21 -> 19 | Q21: 1
A22: =IF(B22="","",COUNTA($B$3:B22)) -> 20 | B22: ដងម្ជុល,Needle Bar,针杆 | C22: តូច small​ 小 | D22: ='9-10'!F22 -> 5 | E22: =SUM(J22:U22) -> 0 | F22: =D22-E22 -> 5
A23: =IF(B23="","",COUNTA($B$3:B23)) -> 21 | B23: ជើងទាឆុត,Teeth Presser Foot and Needle Plate Kit, 齿形压脚与针板套件 | C23: តូច small​ 小 | D23: ='9-10'!F23 -> 3 | E23: =SUM(J23:U23) -> 0 | F23: =D23-E23 -> 3
A24: =IF(B24="","",COUNTA($B$3:B24)) -> 22 | B24: ដែកវាត់អំបោះ,Thread Tension Spring,线张力弹簧 | C24: តូច small​ 小 | D24: ='9-10'!F24 -> 25 | E24: =SUM(J24:U24) -> 0 | F24: =D24-E24 -> 25
A25: =IF(B25="","",COUNTA($B$3:B25)) -> 23 | B25: ឈើកាវក្រោម,Upper looper, 上弯针 | C25: តូច small​ 小 | D25: ='9-10'!F25 -> 10 | E25: =SUM(J25:U25) -> 0 | F25: =D25-E25 -> 10
A26: =IF(B26="","",COUNTA($B$3:B26)) -> 24 | B26: ឈើកាវលើ, Lower Looper,下弯针 | C26: តូច small​ 小 | D26: ='9-10'!F26 -> 0 | E26: =SUM(J26:U26) -> 0 | F26: =D26-E26 -> 0
A27: =IF(B27="","",COUNTA($B$3:B27)) -> 25 | B27: ដងជើងទា,calcador overlock,包缝压脚 | C27: តូច small​ 小 | D27: ='9-10'!F27 -> 3 | E27: =SUM(J27:U27) -> 1 | F27: =D27-E27 -> 2 | L27: 1
A28: =IF(B28="","",COUNTA($B$3:B28)) -> 26 | B28: ធ្មេញក្រោយ,God feed Overlock Machine,差动送料包缝机 | C28: តូច small​ 小 | D28: ='9-10'!F28 -> 0 | E28: =SUM(J28:U28) -> 0 | F28: =D28-E28 -> 0
A29: =IF(B29="","",COUNTA($B$3:B29)) -> 27 | B29: សន្ទះធ្មេញ, Needle Plate Fit,针板适配 | C29: តូច small​ 小 | D29: ='9-10'!F29 -> 9 | E29: =SUM(J29:U29) -> 0 | F29: =D29-E29 -> 9
A30: =IF(B30="","",COUNTA($B$3:B30)) -> 28 | B30: កាំបិតក្រោម,Lower Bottom Knife to Fit Overlock Machine,降低包缝机下刀位置 | C30: តូច small​ 小 | D30: ='9-10'!F30 -> 4 | E30: =SUM(J30:U30) -> 0 | F30: =D30-E30 -> 4
A31: =IF(B31="","",COUNTA($B$3:B31)) -> 29 | B31: កាំបិតលើ,Top Knife for Overlock,包缝机上刀 | C31: តូច small​ 小 | D31: ='9-10'!F31 -> 0 | E31: =SUM(J31:U31) -> 0 | F31: =D31-E31 -> 0
A32: =IF(B32="","",COUNTA($B$3:B32)) -> 30 | B32: ដងម្ជុល,Needle Clamp Holder Fitsr,适配机针夹持器 | C32: តូច small​ 小 | D32: ='9-10'!F32 -> 8 | E32: =SUM(J32:U32) -> 0 | F32: =D32-E32 -> 8
A33: =IF(B33="","",COUNTA($B$3:B33)) -> 31 | B33: ឈើកាវផ្កាដូង,Chainstitch Looper 5 Thread,五线链式缝弯针 | C33: តូច small​ 小 | D33: ='9-10'!F33 -> 0 | E33: =SUM(J33:U33) -> 0 | F33: =D33-E33 -> 0
A34: =IF(B34="","",COUNTA($B$3:B34)) -> 32 | B34: រុន្ធម្ជុលសាប់,Needle Hole Guide Bartack Machine, 针孔定位套结机 | C34: តូច small​ 小 | D34: ='9-10'!F34 -> 7 | E34: =SUM(J34:U34) -> 0 | F34: =D34-E34 -> 7
A35: =IF(B35="","",COUNTA($B$3:B35)) -> 33 | B35: សំបុកសាប់, Shuttle Hook Fit Bartack Machine, 适用于套结机的摆梭旋梭 | C35: តូច small​ 小 | D35: ='9-10'!F35 -> 0 | E35: =SUM(J35:U35) -> 0 | F35: =D35-E35 -> 0
A36: =IF(B36="","",COUNTA($B$3:B36)) -> 34 | B36: ដែកបុកកាក់, Thread Tension Release Pin, 线张力释放销 | C36: តូច small​ 小 | D36: ='9-10'!F36 -> 8 | E36: =SUM(J36:U36) -> 0 | F36: =D36-E36 -> 8
A37: =IF(B37="","",COUNTA($B$3:B37)) -> 35 | B37: កាំបិតក្រោមសាប់, Movable Knife Bartack Machine, 动刀式套结机 | C37: តូច small​ 小 | D37: ='9-10'!F37 -> 3 | E37: =SUM(J37:U37) -> 1 | F37: =D37-E37 -> 2 | P37: 1
A38: =IF(B38="","",COUNTA($B$3:B38)) -> 36 | B38: កាំបិតលើសាប់, Fixed Knife Bartack Machine, 固定刀片式套结机 | C38: តូច small​ 小 | D38: ='9-10'!F38 -> 1 | E38: =SUM(J38:U38) -> 0 | F38: =D38-E38 -> 1
A39: =IF(B39="","",COUNTA($B$3:B39)) -> 37 | B39: ជើងទាសាប់, work clamp set bartack machine, 套结机工件夹具组 | C39: តូច small​ 小 | D39: ='9-10'!F39 -> 3 | E39: =SUM(J39:U39) -> 0 | F39: =D39-E39 -> 3
A40: =IF(B40="","",COUNTA($B$3:B40)) -> 38 | B40: សំបុក Rotary Hook 旋梭 | C40: តូច small​ 小 | D40: ='9-10'!F40 -> 1 | E40: =SUM(J40:U40) -> 1 | F40: =D40-E40 -> 0 | O40: 1
...

Sheet 9-12
B1: ​​​ របាយការណ៏ដូរ​បន្លាស់ប្រចាំថ្ងៃ Daily Spare Part Change Report 每日备件更换报告 | G1: 46365 | J1: ការផ្លាស់ប្តូរគ្រឿងបន្លាស់សម្រាប់ខ្សែសង្វាក់ផលិតកម្មដេរ, Spare Part Change For Sewing Line , 缝纫线备件更换
A2: លរ​ No. 数字 | B2: ប្រភេទគ្រឿងបន្លាស់ Sparepart Type 备件类型 | C2: ទំហំ​ SIZE 尺寸 | D2: ចំនួននៅសល់ Stock Left 剩余库存 | E2: ម្ជុលដែលបានផ្តល់ជូន, Issued Needle, 已发放的针头 | F2: តុល្យភាព Balance 平衡 | G2: សំគាល់ Remark 评论 | J2: # 1 | K2: # 2 | L2: # 3 | M2: # 4 | N2: # 5 | O2: # 6 | P2: # 7 | Q2: # 8 | R2: # 9 | S2: # 10 | T2: # 11 | U2: # 12
A3: =IF(B3="","",COUNTA($B$3:B3)) -> 1 | B3: សំបុក Rotary Hook 旋梭 | C3: តូច small​ 小 | D3: ='9-11'!F3 -> 6 | E3: =SUM(J3:U3) -> 1 | F3: =D3-E3 -> 5 | O3: 1 | X3: ខូច​ Damage 损害
A4: =IF(B4="","",COUNTA($B$3:B4)) -> 2 | B4: ធ្មេញរង្វើល Feed Dog 送布牙 | C4: តូច small​ 小 | D4: ='9-11'!F4 -> 60 | E4: =SUM(J4:U4) -> 0 | F4: =D4-E4 -> 60 | X4: បាក់​ Broken 破碎的
A5: =IF(B5="","",COUNTA($B$3:B5)) -> 3 | B5: ធ្មេញញឺក Feed Dog fits适用于送布牙 | C5: តូច small​ 小 | D5: ='9-11'!F5 -> 8 | E5: =SUM(J5:U5) -> 0 | F5: =D5-E5 -> 8 | X5: ប្តូរម៉ូដ Change Style, 更改样式
A6: =IF(B6="","",COUNTA($B$3:B6)) -> 4 | B6: សន្ទះធ្មេញ Needle Plate 针板 | C6: តូច small​ 小 | D6: ='9-11'!F6 -> 12 | E6: =SUM(J6:U6) -> 0 | F6: =D6-E6 -> 12 | X6: បាត់​ Lost 迷失
A7: =IF(B7="","",COUNTA($B$3:B7)) -> 5 | B7: សន្ទះធ្មេញទុន Needle Plate 针板 | C7: តូច small​ 小 | D7: ='9-11'!F7 -> 3 | E7: =SUM(J7:U7) -> 0 | F7: =D7-E7 -> 3 | X7: ផ្សេងៗ​ Other 其他
A8: =IF(B8="","",COUNTA($B$3:B8)) -> 6 | B8: កាំបិទលើJ Fixed Knife for JUKI JUKI用固定刀 | C8: តូច small​ 小 | D8: ='9-11'!F8 -> 23 | E8: =SUM(J8:U8) -> 1 | F8: =D8-E8 -> 22 | N8: 1
A9: =IF(B9="","",COUNTA($B$3:B9)) -> 7 | B9: កាំបិទក្រោមS, Thread Cutter Blade For Sirubar, Sirubar 切线刀片 | C9: តូច small​ 小 | D9: ='9-11'!F9 -> 14 | E9: =SUM(J9:U9) -> 1 | F9: =D9-E9 -> 13 | Q9: 1
A10: =IF(B10="","",COUNTA($B$3:B10)) -> 8 | B10: សន្លឺកស្រូវJ Thread Guide For JUKI,JUKI 穿线导向器 | C10: តូច small​ 小 | D10: ='9-11'!F10 -> 2 | E10: =SUM(J10:U10) -> 0 | F10: =D10-E10 -> 2
A11: =IF(B11="","",COUNTA($B$3:B11)) -> 9 | B11: សន្លឺកស្រូវS Thread Finger For Sirubar,适用于 Siruba 的过线指 | C11: តូច small​ 小 | D11: ='9-11'!F11 -> 4 | E11: =SUM(J11:U11) -> 0 | F11: =D11-E11 -> 4
A12: =IF(B12="","",COUNTA($B$3:B12)) -> 10 | B12: កាំបិទលើS Fixed Knif For Sirubar,Sirubar 固定刀片 | C12: តូច small​ 小 | D12: ='9-11'!F12 -> 0 | E12: =SUM(J12:U12) -> 0 | F12: =D12-E12 -> 0
A13: =IF(B13="","",COUNTA($B$3:B13)) -> 11 | B13: កាំបិទក្រោមS,Movable Knife For Sirubar,Siruba 动刀 Sirubar | C13: តូច small​ 小 | D13: ='9-11'!F13 -> 0 | E13: =SUM(J13:U13) -> 0 | F13: =D13-E13 -> 0
A14: =IF(B14="","",COUNTA($B$3:B14)) -> 12 | B14: ដែកបុកកាក់ Dowel Pin,定位销 | C14: តូច small​ 小 | D14: ='9-11'!F14 -> 7 | E14: =SUM(J14:U14) -> 0 | F14: =D14-E14 -> 7
A15: =IF(B15="","",COUNTA($B$3:B15)) -> 13 | B15: ផ្ទាំងបញ្ជាខៀវJ,Blue control Panel JUKI,JUKI 蓝色控制面板 | C15: តូច small​ 小 | D15: ='9-11'!F15 -> 5 | E15: =SUM(J15:U15) -> 0 | F15: =D15-E15 -> 5
A16: =IF(B16="","",COUNTA($B$3:B16)) -> 14 | B16: ផ្ទាំងបញ្ជាសJ White color control Panel JUKI,JUKI 白色控制面板 | C16: តូច small​ 小 | D16: ='9-11'!F16 -> 3 | E16: =SUM(J16:U16) -> 0 | F16: =D16-E16 -> 3
A17: =IF(B17="","",COUNTA($B$3:B17)) -> 15 | B17: ផ្ទាំងបញ្ជាជំនាន់ចាស់J, Old Verson Board JUKI,JUKI 旧版电路板 | C17: តូច small​ 小 | D17: ='9-11'!F17 -> 3 | E17: =SUM(J17:U17) -> 0 | F17: =D17-E17 -> 3
A18: =IF(B18="","",COUNTA($B$3:B18)) -> 16 | B18: ខ្សែរទាញកាក់,CABLE ASSY, HOOD LOCK CONTROL,发动机罩锁控制拉索组件 | C18: តូច small​ 小 | D18: ='9-11'!F18 -> 2 | E18: =SUM(J18:U18) -> 0 | F18: =D18-E18 -> 2
A19: =IF(B19="","",COUNTA($B$3:B19)) -> 17 | B19: ជ័រខារអំបោះ,Bobbin winder rubber ring,绕线器橡胶圈 | C19: តូច small​ 小 | D19: ='9-11'!F19 -> 42 | E19: =SUM(J19:U19) -> 0 | F19: =D19-E19 -> 42
A20: =IF(B20="","",COUNTA($B$3:B20)) -> 18 | B20: កាក់ធំ,Thread Tention Assembly,张力调节组件 | C20: ធំ Big 大的 | D20: ='9-11'!F20 -> 2 | E20: =SUM(J20:U20) -> 0 | F20: =D20-E20 -> 2
A21: =IF(B21="","",COUNTA($B$3:B21)) -> 19 | B21: កាក់តូច,Thread Tension Assembly Small,小型线张力组件 | C21: តូច small​ 小 | D21: ='9-11'!F21 -> 19 | E21: =SUM(J21:U21) -> 0 | F21: =D21-E21 -> 19
... A23: =IF(B23="","",COUNTA($B$3:B23)) -> 21 | B23: ជើងទាឆុត,Teeth Presser Foot and Needle Plate Kit, 齿形压脚与针板套件 | C23: តូច small​ 小 | D23: ='9-11'!F23 -> 3 | E23: =SUM(J23:U23) -> 0 | F23: =D23-E23 -> 3
A24: =IF(B24="","",COUNTA($B$3:B24)) -> 22 | B24: ដែកវាត់អំបោះ,Thread Tension Spring,线张力弹簧 | C24: តូច small​ 小 | D24: ='9-11'!F24 -> 25 | E24: =SUM(J24:U24) -> 2 | F24: =D24-E24 -> 23 | L24: 2
A25: =IF(B25="","",COUNTA($B$3:B25)) -> 23 | B25: ឈើកាវក្រោម,Upper looper, 上弯针 | C25: តូច small​ 小 | D25: ='9-11'!F25 -> 10 | E25: =SUM(J25:U25) -> 0 | F25: =D25-E25 -> 10
A26: =IF(B26="","",COUNTA($B$3:B26)) -> 24 | B26: ឈើកាវលើ, Lower Looper,下弯针 | C26: តូច small​ 小 | D26: ='9-11'!F26 -> 0 | E26: =SUM(J26:U26) -> 0 | F26: =D26-E26 -> 0
A27: =IF(B27="","",COUNTA($B$3:B27)) -> 25 | B27: ដងជើងទា,calcador overlock,包缝压脚 | C27: តូច small​ 小 | D27: ='9-11'!F27 -> 2 | E27: =SUM(J27:U27) -> 0 | F27: =D27-E27 -> 2
A28: =IF(B28="","",COUNTA($B$3:B28)) -> 26 | B28: ធ្មេញក្រោយ,God feed Overlock Machine,差动送料包缝机 | C28: តូច small​ 小 | D28: ='9-11'!F28 -> 0 | E28: =SUM(J28:U28) -> 0 | F28: =D28-E28 -> 0
A29: =IF(B29="","",COUNTA($B$3:B29)) -> 27 | B29: សន្ទះធ្មេញ, Needle Plate Fit,针板适配 | C29: តូច small​ 小 | D29: ='9-11'!F29 -> 9 | E29: =SUM(J29:U29) -> 0 | F29: =D29-E29 -> 9
A30: =IF(B30="","",COUNTA($B$3:B30)) -> 28 | B30: កាំបិតក្រោម,Lower Bottom Knife to Fit Overlock Machine,降低包缝机下刀位置 | C30: តូច small​ 小 | D30: ='9-11'!F30 -> 4 | E30: =SUM(J30:U30) -> 0 | F30: =D30-E30 -> 4
A31: =IF(B31="","",COUNTA($B$3:B31)) -> 29 | B31: កាំបិតលើ,Top Knife for Overlock,包缝机上刀 | C31: តូច small​ 小 | D31: ='9-11'!F31 -> 0 | E31: =SUM(J31:U31) -> 0 | F31: =D31-E31 -> 0
A32: =IF(B32="","",COUNTA($B$3:B32)) -> 30 | B32: ដងម្ជុល,Needle Clamp Holder Fitsr,适配机针夹持器 | C32: តូច small​ 小 | D32: ='9-11'!F32 -> 8 | E32: =SUM(J32:U32) -> 0 | F32: =D32-E32 -> 8
A33: =IF(B33="","",COUNTA($B$3:B33)) -> 31 | B33: ឈើកាវផ្កាដូង,Chainstitch Looper 5 Thread,五线链式缝弯针 | C33: តូច small​ 小 | D33: ='9-11'!F33 -> 0 | E33: =SUM(J33:U33) -> 0 | F33: =D33-E33 -> 0
A34: =IF(B34="","",COUNTA($B$3:B34)) -> 32 | B34: រុន្ធម្ជុលសាប់,Needle Hole Guide Bartack Machine, 针孔定位套结机 | C34: តូច small​ 小 | D34: ='9-11'!F34 -> 7 | E34: =SUM(J34:U34) -> 0 | F34: =D34-E34 -> 7
A35: =IF(B35="","",COUNTA($B$3:B35)) -> 33 | B35: សំបុកសាប់, Shuttle Hook Fit Bartack Machine, 适用于套结机的摆梭旋梭 | C35: តូច small​ 小 | D35: ='9-11'!F35 -> 0 | E35: =SUM(J35:U35) -> 0 | F35: =D35-E35 -> 0
A36: =IF(B36="","",COUNTA($B$3:B36)) -> 34 | B36: ដែកបុកកាក់, Thread Tension Release Pin, 线张力释放销 | C36: តូច small​ 小 | D36: ='9-11'!F36 -> 8 | E36: =SUM(J36:U36) -> 0 | F36: =D36-E36 -> 8
... A47: =IF(B47="","",COUNTA($B$3:B47)) -> 45 | B47: ខ្សែរម៉ែត្រ,Tape Measure,卷尺 | C47: តូច small​ 小 | D47: ='9-11'!F47 -> 0 | E47: =SUM(J47:U47) -> 0 | F47: =D47-E47 -> 0
A48: =IF(B48="","",COUNTA($B$3:B48)) -> 46 | B48: ថ្នាំបាញ់លាងម៉ាស៊ីន,Engine spray,发动机喷剂 | C48: តូច small​ 小 | D48: ='9-11'!F48 -> 4 | E48: =SUM(J48:U48) -> 1 | F48: =D48-E48 -> 3 | N48: 1
A49: =IF(B49="","",COUNTA($B$3:B49)) -> 47 | B49: ថ្នាំបាញ់ច្រេះ,Rust-removing spray,除锈喷雾 | C49: តូច small​ 小 | D49: ='9-11'!F49 -> 2 | E49: =SUM(J49:U49) -> 0 | F49: =D49-E49 -> 2
A50: =IF(B50="","",COUNTA($B$3:B50)) -> 48 | B50: កង់បង្វិលម៉ាស៊ីនផុង,Spinning wheel of overlock machine,包缝机手轮 | C50: តូច small​ 小 | D50: ='9-11'!F50 -> 3 | E50: =SUM(J50:U50) -> 0 | F50: =D50-E50 -> 3
A51: =IF(B51="","",COUNTA($B$3:B51)) -> 49 | B51: ប៊ិចវាស់ភ្លើង,Voltage tester pen,测电笔 | C51: តូច small​ 小 | D51: ='9-11'!F51 -> 0 | E51: =SUM(J51:U51) -> 0 | F51: =D51-E51 -> 0
...

Sheet 9-14
B1: ​​​ របាយការណ៏ដូរ​បន្លាស់ប្រចាំថ្ងៃ Daily Spare Part Change Report 每日备件更换报告 | G1: 14/9/2026 | J1: ការផ្លាស់ប្តូរគ្រឿងបន្លាស់សម្រាប់ខ្សែសង្វាក់ផលិតកម្មដេរ, Spare Part Change For Sewing Line , 缝纫线备件更换
A2: លរ​ No. 数字 | B2: ប្រភេទគ្រឿងបន្លាស់ Sparepart Type 备件类型 | C2: ទំហំ​ SIZE 尺寸 | D2: ចំនួននៅសល់ Stock Left 剩余库存 | E2: ម្ជុលដែលបានផ្តល់ជូន, Issued Needle, 已发放的针头 | F2: តុល្យភាព Balance 平衡 | G2: សំគាល់ Remark 评论 | J2: # 1 | K2: # 2 | L2: # 3 | M2: # 4 | N2: # 5 | O2: # 6 | P2: # 7 | Q2: # 8 | R2: # 9 | S2: # 10 | T2: # 11 | U2: # 12
A3: =IF(B3="","",COUNTA($B$3:B3)) -> 1 | B3: សំបុក Rotary Hook 旋梭 | C3: តូច small​ 小 | D3: ='9-12'!F3 -> 5 | E3: =SUM(J3:U3) -> 0 | F3: =D3-E3 -> 5 | X3: ខូច​ Damage 损害
A4: =IF(B4="","",COUNTA($B$3:B4)) -> 2 | B4: ធ្មេញរង្វើល Feed Dog 送布牙 | C4: តូច small​ 小 | D4: ='9-12'!F4 -> 60 | E4: =SUM(J4:U4) -> 0 | F4: =D4-E4 -> 60 | X4: បាក់​ Broken 破碎的
A5: =IF(B5="","",COUNTA($B$3:B5)) -> 3 | B5: ធ្មេញញឺក Feed Dog fits适用于送布牙 | C5: តូច small​ 小 | D5: ='9-12'!F5 -> 8 | E5: =SUM(J5:U5) -> 0 | F5: =D5-E5 -> 8 | X5: ប្តូរម៉ូដ Change Style, 更改样式
A6: =IF(B6="","",COUNTA($B$3:B6)) -> 4 | B6: សន្ទះធ្មេញ Needle Plate 针板 | C6: តូច small​ 小 | D6: ='9-12'!F6 -> 12 | E6: =SUM(J6:U6) -> 1 | F6: =D6-E6 -> 11 | M6: 1 | X6: បាត់​ Lost 迷失
A7: =IF(B7="","",COUNTA($B$3:B7)) -> 5 | B7: សន្ទះធ្មេញទុន Needle Plate 针板 | C7: តូច small​ 小 | D7: ='9-12'!F7 -> 3 | E7: =SUM(J7:U7) -> 0 | F7: =D7-E7 -> 3 | X7: ផ្សេងៗ​ Other 其他
A8: =IF(B8="","",COUNTA($B$3:B8)) -> 6 | B8: កាំបិទលើJ Fixed Knife for JUKI JUKI用固定刀 | C8: តូច small​ 小 | D8: ='9-12'!F8 -> 22 | E8: =SUM(J8:U8) -> 0 | F8: =D8-E8 -> 22
A9: =IF(B9="","",COUNTA($B$3:B9)) -> 7 | B9: កាំបិទក្រោមS, Thread Cutter Blade For Sirubar, Sirubar 切线刀片 | C9: តូច small​ 小 | D9: ='9-12'!F9 -> 13 | E9: =SUM(J9:U9) -> 0 | F9: =D9-E9 -> 13
A10: =IF(B10="","",COUNTA($B$3:B10)) -> 8 | B10: សន្លឺកស្រូវJ Thread Guide For JUKI,JUKI 穿线导向器 | C10: តូច small​ 小 | D10: ='9-12'!F10 -> 2 | E10: =SUM(J10:U10) -> 0 | F10: =D10-E10 -> 2
A11: =IF(B11="","",COUNTA($B$3:B11)) -> 9 | B11: សន្លឺកស្រូវS Thread Finger For Sirubar,适用于 Siruba 的过线指 | C11: តូច small​ 小 | D11: ='9-12'!F11 -> 4 | E11: =SUM(J11:U11) -> 0 | F11: =D11-E11 -> 4
A12: =IF(B12="","",COUNTA($B$3:B12)) -> 10 | B12: កាំបិទលើS Fixed Knif For Sirubar,Sirubar 固定刀片 | C12: តូច small​ 小 | D12: ='9-12'!F12 -> 0 | E12: =SUM(J12:U12) -> 0 | F12: =D12-E12 -> 0
A13: =IF(B13="","",COUNTA($B$3:B13)) -> 11 | B13: កាំបិទក្រោមS,Movable Knife For Sirubar,Siruba 动刀 Sirubar | C13: តូច small​ 小 | D13: ='9-12'!F13 -> 0 | E13: =SUM(J13:U13) -> 0 | F13: =D13-E13 -> 0
A14: =IF(B14="","",COUNTA($B$3:B14)) -> 12 | B14: ដែកបុកកាក់ Dowel Pin,定位销 | C14: តូច small​ 小 | D14: ='9-12'!F14 -> 7 | E14: =SUM(J14:U14) -> 0 | F14: =D14-E14 -> 7
A15: =IF(B15="","",COUNTA($B$3:B15)) -> 13 | B15: ផ្ទាំងបញ្ជាខៀវJ,Blue control Panel JUKI,JUKI 蓝色控制面板 | C15: តូច small​ 小 | D15: ='9-12'!F15 -> 5 | E15: =SUM(J15:U15) -> 0 | F15: =D15-E15 -> 5
A16: =IF(B16="","",COUNTA($B$3:B16)) -> 14 | B16: ផ្ទាំងបញ្ជាសJ White color control Panel JUKI,JUKI 白色控制面板 | C16: តូច small​ 小 | D16: ='9-12'!F16 -> 3 | E16: =SUM(J16:U16) -> 0 | F16: =D16-E16 -> 3
A17: =IF(B17="","",COUNTA($B$3:B17)) -> 15 | B17: ផ្ទាំងបញ្ជាជំនាន់ចាស់J, Old Verson Board JUKI,JUKI 旧版电路板 | C17: តូច small​ 小 | D17: ='9-12'!F17 -> 3 | E17: =SUM(J17:U17) -> 0 | F17: =D17-E17 -> 3
A18: =IF(B18="","",COUNTA($B$3:B18)) -> 16 | B18: ខ្សែរទាញកាក់,CABLE ASSY, HOOD LOCK CONTROL,发动机罩锁控制拉索组件 | C18: តូច small​ 小 | D18: ='9-12'!F18 -> 2 | E18: =SUM(J18:U18) -> 0 | F18: =D18-E18 -> 2
A19: =IF(B19="","",COUNTA($B$3:B19)) -> 17 | B19: ជ័រខារអំបោះ,Bobbin winder rubber ring,绕线器橡胶圈 | C19: តូច small​ 小 | D19: ='9-12'!F19 -> 42 | E19: =SUM(J19:U19) -> 0 | F19: =D19-E19 -> 42
... A80: =IF(B80="","",COUNTA($B$3:B80)) -> 78 | B80: កាំបិតក្រោម, Bottom Thread Trimmer, 底线切线器 | C80: តូច small​ 小 | D80: ='9-12'!F80 -> 1 | E80: =SUM(J80:U80) -> 0 | F80: =D80-E80 -> 1
A81: =IF(B81="","",COUNTA($B$3:B81))
A82: =IF(B82="","",COUNTA($B$3:B82))

Sheet 9-15
B1: ​​​ របាយការណ៏ដូរ​បន្លាស់ប្រចាំថ្ងៃ Daily Spare Part Change Report 每日备件更换报告 | G1: 15/9/2026 | J1: ការផ្លាស់ប្តូរគ្រឿងបន្លាស់សម្រាប់ខ្សែសង្វាក់ផលិតកម្មដេរ, Spare Part Change For Sewing Line , 缝纫线备件更换
A2: លរ​ No. 数字 | B2: ប្រភេទគ្រឿងបន្លាស់ Sparepart Type 备件类型 | C2: ទំហំ​ SIZE 尺寸 | D2: ចំនួននៅសល់ Stock Left 剩余库存 | E2: ម្ជុលដែលបានផ្តល់ជូន, Issued Needle, 已发放的针头 | F2: តុល្យភាព Balance 平衡 | G2: សំគាល់ Remark 评论 | H2: Column1 | J2: # 1 | K2: # 2 | L2: # 3 | M2: # 4 | N2: # 5 | O2: # 6 | P2: # 7 | Q2: # 8 | R2: # 9 | S2: # 10 | T2: # 11 | U2: # 12
A3: =IF(B3="","",COUNTA($B$3:B3)) -> 1 | B3: សំបុក Rotary Hook 旋梭 | C3: តូច small​ 小 | D3: ='9-14'!F3 -> 5 | E3: =SUM(J3:U3) -> 2 | F3: =D3-E3 -> 3 | G3: =D3-F3 -> 2 | M3: 1 | Q3: 1 | X3: ខូច​ Damage 损害
A4: =IF(B4="","",COUNTA($B$3:B4)) -> 2 | B4: ធ្មេញរង្វើល Feed Dog 送布牙 | C4: តូច small​ 小 | D4: ='9-14'!F4 -> 60 | E4: =SUM(J4:U4) -> 2 | F4: =D4-E4 -> 58 | G4: =D4-F4 -> 2 | K4: 1 | O4: 1 | X4: បាក់​ Broken 破碎的
A5: =IF(B5="","",COUNTA($B$3:B5)) -> 3 | B5: ធ្មេញញឺក Feed Dog fits适用于送布牙 | C5: តូច small​ 小 | D5: ='9-14'!F5 -> 8 | E5: =SUM(J5:U5) -> 0 | F5: =D5-E5 -> 8 | G5: =D5-F5 -> 0 | X5: ប្តូរម៉ូដ Change Style, 更改样式
A6: =IF(B6="","",COUNTA($B$3:B6)) -> 4 | B6: សន្ទះធ្មេញ Needle Plate 针板 | C6: តូច small​ 小 | D6: ='9-14'!F6 -> 11 | E6: =SUM(J6:U6) -> 0 | F6: =D6-E6 -> 11 | G6: =D6-F6 -> 0 | X6: បាត់​ Lost 迷失
A7: =IF(B7="","",COUNTA($B$3:B7)) -> 5 | B7: សន្ទះធ្មេញទុន Needle Plate 针板 | C7: តូច small​ 小 | D7: ='9-14'!F7 -> 3 | E7: =SUM(J7:U7) -> 0 | F7: =D7-E7 -> 3 | G7: =D7-F7 -> 0 | X7: ផ្សេងៗ​ Other 其他
A8: =IF(B8="","",COUNTA($B$3:B8)) -> 6 | B8: កាំបិទលើJ Fixed Knife for JUKI JUKI用固定刀 | C8: តូច small​ 小 | D8: ='9-14'!F8 -> 22 | E8: =SUM(J8:U8) -> 2 | F8: =D8-E8 -> 20 | G8: =D8-F8 -> 2 | L8: 1 | P8: 1
A9: =IF(B9="","",COUNTA($B$3:B9)) -> 7 | B9: កាំបិទក្រោមS, Thread Cutter Blade For Sirubar, Sirubar 切线刀片 | C9: តូច small​ 小 | D9: ='9-14'!F9 -> 13 | E9: =SUM(J9:U9) -> 0 | F9: =D9-E9 -> 13 | G9: =D9-F9 -> 0
A10: =IF(B10="","",COUNTA($B$3:B10)) -> 8 | B10: សន្លឺកស្រូវJ Thread Guide For JUKI,JUKI 穿线导向器 | C10: តូច small​ 小 | D10: ='9-14'!F10 -> 2 | E10: =SUM(J10:U10) -> 0 | F10: =D10-E10 -> 2 | G10: =D10-F10 -> 0
A11: =IF(B11="","",COUNTA($B$3:B11)) -> 9 | B11: សន្លឺកស្រូវS Thread Finger For Sirubar,适用于 Siruba 的过线指 | C11: តូច small​ 小 | D11: ='9-14'!F11 -> 4 | E11: =SUM(J11:U11) -> 0 | F11: =D11-E11 -> 4 | G11: =D11-F11 -> 0
A12: =IF(B12="","",COUNTA($B$3:B12)) -> 10 | B12: កាំបិទលើS Fixed Knif For Sirubar,Sirubar 固定刀片 | C12: តូច small​ 小 | D12: ='9-14'!F12 -> 0 | E12: =SUM(J12:U12) -> 0 | F12: =D12-E12 -> 0 | G12: =D12-F12 -> 0
A13: =IF(B13="","",COUNTA($B$3:B13)) -> 11 | B13: កាំបិទក្រោមS,Movable Knife For Sirubar,Siruba 动刀 Sirubar | C13: តូច small​ 小 | D13: ='9-14'!F13 -> 0 | E13: =SUM(J13:U13) -> 0 | F13: =D13-E13 -> 0 | G13: =D13-F13 -> 0
A14: =IF(B14="","",COUNTA($B$3:B14)) -> 12 | B14: ដែកបុកកាក់ Dowel Pin,定位销 | C14: តូច small​ 小 | D14: ='9-14'!F14 -> 7 | E14: =SUM(J14:U14) -> 0 | F14: =D14-E14 -> 7 | G14: =D14-F14 -> 0
A15: =IF(B15="","",COUNTA($B$3:B15)) -> 13 | B15: ផ្ទាំងបញ្ជាខៀវJ,Blue control Panel JUKI,JUKI 蓝色控制面板 | C15: តូច small​ 小 | D15: ='9-14'!F15 -> 5 | E15: =SUM(J15:U15) -> 0 | F15: =D15-E15 -> 5 | G15: =D15-F15 -> 0
A16: =IF(B16="","",COUNTA($B$3:B16)) -> 14 | B16: ផ្ទាំងបញ្ជាសJ White color control Panel JUKI,JUKI 白色控制面板 | C16: តូច small​ 小 | D16: ='9-14'!F16 -> 3 | E16: =SUM(J16:U16) -> 0 | F16: =D16-E16 -> 3 | G16: =D16-F16 -> 0
A17: =IF(B17="","",COUNTA($B$3:B17)) -> 15 | B17: ផ្ទាំងបញ្ជាជំនាន់ចាស់J, Old Verson Board JUKI,JUKI 旧版电路板 | C17: តូច small​ 小 | D17: ='9-14'!F17 -> 3 | E17: =SUM(J17:U17) -> 0 | F17: =D17-E17 -> 3 | G17: =D17-F17 -> 0
A18: =IF(B18="","",COUNTA($B$3:B18)) -> 16 | B18: ខ្សែរទាញកាក់,CABLE ASSY, HOOD LOCK CONTROL,发动机罩锁控制拉索组件 | C18: តូច small​ 小 | D18: ='9-14'!F18 -> 2 | E18: =SUM(J18:U18) -> 0 | F18: =D18-E18 -> 2 | G18: =D18-F18 -> 0
A19: =IF(B19="","",COUNTA($B$3:B19)) -> 17 | B19: ជ័រខារអំបោះ,Bobbin winder rubber ring,绕线器橡胶圈 | C19: តូច small​ 小 | D19: ='9-14'!F19 -> 42 | E19: =SUM(J19:U19) -> 0 | F19: =D19-E19 -> 42 | G19: =D19-F19 -> 0
A20: =IF(B20="","",COUNTA($B$3:B20)) -> 18 | B20: កាក់ធំ,Thread Tention Assembly,张力调节组件 | C20: ធំ Big 大的 | D20: ='9-14'!F20 -> 2 | E20: =SUM(J20:U20) -> 0 | F20: =D20-E20 -> 2 | G20: =D20-F20 -> 0
... A26: =IF(B26="","",COUNTA($B$3:B26)) -> 24 | B26: ឈើកាវលើ, Lower Looper,下弯针 | C26: តូច small​ 小 | D26: ='9-14'!F26 -> 0 | E26: =SUM(J26:U26) -> 0 | F26: =D26-E26 -> 0 | G26: =D26-F26 -> 0
A27: =IF(B27="","",COUNTA($B$3:B27)) -> 25 | B27: ដងជើងទា,calcador overlock,包缝压脚 | C27: តូច small​ 小 | D27: ='9-14'!F27 -> 2 | E27: =SUM(J27:U27) -> 1 | F27: =D27-E27 -> 1 | G27: =D27-F27 -> 1 | R27: 1
A28: =IF(B28="","",COUNTA($B$3:B28)) -> 26 | B28: ធ្មេញក្រោយ,God feed Overlock Machine,差动送料包缝机 | C28: តូច small​ 小 | D28: ='9-14'!F28 -> 0 | E28: =SUM(J28:U28) -> 0 | F28: =D28-E28 -> 0 | G28: =D28-F28 -> 0
A29: =IF(B29="","",COUNTA($B$3:B29)) -> 27 | B29: សន្ទះធ្មេញ, Needle Plate Fit,针板适配 | C29: តូច small​ 小 | D29: ='9-14'!F29 -> 9 | E29: =SUM(J29:U29) -> 0 | F29: =D29-E29 -> 9 | G29: =D29-F29 -> 0
A30: =IF(B30="","",COUNTA($B$3:B30)) -> 28 | B30: កាំបិតក្រោម,Lower Bottom Knife to Fit Overlock Machine,降低包缝机下刀位置 | C30: តូច small​ 小 | D30: ='9-14'!F30 -> 4 | E30: =SUM(J30:U30) -> 0 | F30: =D30-E30 -> 4 | G30: =D30-F30 -> 0
A31: =IF(B31="","",COUNTA($B$3:B31)) -> 29 | B31: កាំបិតលើ,Top Knife for Overlock,包缝机上刀 | C31: តូច small​ 小 | D31: ='9-14'!F31 -> 0 | E31: =SUM(J31:U31) -> 0 | F31: =D31-E31 -> 0 | G31: =D31-F31 -> 0
A32: =IF(B32="","",COUNTA($B$3:B32)) -> 30 | B32: ដងម្ជុល,Needle Clamp Holder Fitsr,适配机针夹持器 | C32: តូច small​ 小 | D32: ='9-14'!F32 -> 8 | E32: =SUM(J32:U32) -> 0 | F32: =D32-E32 -> 8 | G32: =D32-F32 -> 0
A33: =IF(B33="","",COUNTA($B$3:B33)) -> 31 | B33: ឈើកាវផ្កាដូង,Chainstitch Looper 5 Thread,五线链式缝弯针 | C33: តូច small​ 小 | D33: ='9-14'!F33 -> 0 | E33: =SUM(J33:U33) -> 0 | F33: =D33-E33 -> 0 | G33: =D33-F33 -> 0
A34: =IF(B34="","",COUNTA($B$3:B34)) -> 32 | B34: រុន្ធម្ជុលសាប់,Needle Hole Guide Bartack Machine, 针孔定位套结机 | C34: តូច small​ 小 | D34: ='9-14'!F34 -> 7 | E34: =SUM(J34:U34) -> 0 | F34: =D34-E34 -> 7 | G34: =D34-F34 -> 0
A35: =IF(B35="","",COUNTA($B$3:B35)) -> 33 | B35: សំបុកសាប់, Shuttle Hook Fit Bartack Machine, 适用于套结机的摆梭旋梭 | C35: តូច small​ 小 | D35: ='9-14'!F35 -> 0 | E35: =SUM(J35:U35) -> 0 | F35: =D35-E35 -> 0 | G35: =D35-F35 -> 0
A36: =IF(B36="","",COUNTA($B$3:B36)) -> 34 | B36: ដែកបុកកាក់, Thread Tension Release Pin, 线张力释放销 | C36: តូច small​ 小 | D36: ='9-14'!F36 -> 8 | E36: =SUM(J36:U36) -> 0 | F36: =D36-E36 -> 8 | G36: =D36-F36 -> 0
A37: =IF(B37="","",COUNTA($B$3:B37)) -> 35 | B37: កាំបិតក្រោមសាប់, Movable Knife Bartack Machine, 动刀式套结机 | C37: តូច small​ 小 | D37: ='9-14'!F37 -> 2 | E37: =SUM(J37:U37) -> 0 | F37: =D37-E37 -> 2 | G37: =D37-F37 -> 0
A38: =IF(B38="","",COUNTA($B$3:B38)) -> 36 | B38: កាំបិតលើសាប់, Fixed Knife Bartack Machine, 固定刀片式套结机 | C38: តូច small​ 小 | D38: ='9-14'!F38 -> 1 | E38: =SUM(J38:U38) -> 0 | F38: =D38-E38 -> 1 | G38: =D38-F38 -> 0
A39: =IF(B39="","",COUNTA($B$3:B39)) -> 37 | B39: ជើងទាសាប់, work clamp set bartack machine, 套结机工件夹具组 | C39: តូច small​ 小 | D39: ='9-14'!F39 -> 3 | E39: =SUM(J39:U39) -> 0 | F39: =D39-E39 -> 3 | G39: =D39-F39 -> 0
... A80: =IF(B80="","",COUNTA($B$3:B80)) -> 78 | B80: កាំបិតក្រោម, Bottom Thread Trimmer, 底线切线器 | C80: តូច small​ 小 | D80: ='9-14'!F80 -> 1 | E80: =SUM(J80:U80) -> 0 | F80: =D80-E80 -> 1 | G80: =D80-F80 -> 0
A81: =IF(B81="","",COUNTA($B$3:B81)) -> 79 | B81: ប្រេងម៉ាស៊ីនខ្យល់ Air_Compressor Oil 空气压缩机油 | C81: ធំ Big 大的 | D81: 1 | F81: 1
A82: =IF(B82="","",COUNTA($B$3:B82)) | G82: =D82-F82 -> 0
G83: =D83-F83 -> 0
G84: =D84-F84 -> 0

Sheet 9-16
B1: ​​​ របាយការណ៏ដូរ​បន្លាស់ប្រចាំថ្ងៃ Daily Spare Part Change Report 每日备件更换报告 | G1: 16/9/2026 | J1: ការផ្លាស់ប្តូរគ្រឿងបន្លាស់សម្រាប់ខ្សែសង្វាក់ផលិតកម្មដេរ, Spare Part Change For Sewing Line , 缝纫线备件更换
A2: លរ​ No. 数字 | B2: ប្រភេទគ្រឿងបន្លាស់ Sparepart Type 备件类型 | C2: ទំហំ​ SIZE 尺寸 | D2: ចំនួននៅសល់ Stock Left 剩余库存 | E2: ម្ជុលដែលបានផ្តល់ជូន, Issued Needle, 已发放的针头 | F2: តុល្យភាព Balance 平衡 | G2: សំគាល់ Remark 评论 | H2: Column1 | J2: # 1 | K2: # 2 | L2: # 3 | M2: # 4 | N2: # 5 | O2: # 6 | P2: # 7 | Q2: # 8 | R2: # 9 | S2: # 10 | T2: # 11 | U2: # 12
A3: =IF(B3="","",COUNTA($B$3:B3)) -> 1 | B3: សំបុក Rotary Hook 旋梭 | C3: តូច small​ 小 | D3: ='9-15'!F3 -> 3 | E3: =SUM(J3:U3) -> 1 | F3: =D3-E3 -> 2 | G3: =D3-F3 -> 1 | R3: 1 | X3: ខូច​ Damage 损害
A4: =IF(B4="","",COUNTA($B$3:B4)) -> 2 | B4: ធ្មេញរង្វើល Feed Dog 送布牙 | C4: តូច small​ 小 | D4: ='9-15'!F4 -> 58 | E4: =SUM(J4:U4) -> 1 | F4: =D4-E4 -> 57 | G4: =D4-F4 -> 1 | S4: 1 | X4: បាក់​ Broken 破碎的
A5: =IF(B5="","",COUNTA($B$3:B5)) -> 3 | B5: ធ្មេញញឺក Feed Dog fits适用于送布牙 | C5: តូច small​ 小 | D5: ='9-15'!F5 -> 8 | E5: =SUM(J5:U5) -> 0 | F5: =D5-E5 -> 8 | G5: =D5-F5 -> 0 | X5: ប្តូរម៉ូដ Change Style, 更改样式
A6: =IF(B6="","",COUNTA($B$3:B6)) -> 4 | B6: សន្ទះធ្មេញ Needle Plate 针板 | C6: តូច small​ 小 | D6: ='9-15'!F6 -> 11 | E6: =SUM(J6:U6) -> 0 | F6: =D6-E6 -> 11 | G6: =D6-F6 -> 0 | X6: បាត់​ Lost 迷失
A7: =IF(B7="","",COUNTA($B$3:B7)) -> 5 | B7: សន្ទះធ្មេញទុន Needle Plate 针板 | C7: តូច small​ 小 | D7: ='9-15'!F7 -> 3 | E7: =SUM(J7:U7) -> 0 | F7: =D7-E7 -> 3 | G7: =D7-F7 -> 0 | X7: ផ្សេងៗ​ Other 其他
A8: =IF(B8="","",COUNTA($B$3:B8)) -> 6 | B8: កាំបិទលើJ Fixed Knife for JUKI JUKI用固定刀 | C8: តូច small​ 小 | D8: ='9-15'!F8 -> 20 | E8: =SUM(J8:U8) -> 0 | F8: =D8-E8 -> 20 | G8: =D8-F8 -> 0
A9: =IF(B9="","",COUNTA($B$3:B9)) -> 7 | B9: កាំបិទក្រោមS, Thread Cutter Blade For Sirubar, Sirubar 切线刀片 | C9: តូច small​ 小 | D9: ='9-15'!F9 -> 13 | E9: =SUM(J9:U9) -> 0 | F9: =D9-E9 -> 13 | G9: =D9-F9 -> 0
A10: =IF(B10="","",COUNTA($B$3:B10)) -> 8 | B10: សន្លឺកស្រូវJ Thread Guide For JUKI,JUKI 穿线导向器 | C10: តូច small​ 小 | D10: ='9-15'!F10 -> 2 | E10: =SUM(J10:U10) -> 0 | F10: =D10-E10 -> 2 | G10: =D10-F10 -> 0
A11: =IF(B11="","",COUNTA($B$3:B11)) -> 9 | B11: សន្លឺកស្រូវS Thread Finger For Sirubar,适用于 Siruba 的过线指 | C11: តូច small​ 小 | D11: ='9-15'!F11 -> 4 | E11: =SUM(J11:U11) -> 0 | F11: =D11-E11 -> 4 | G11: =D11-F11 -> 0
A12: =IF(B12="","",COUNTA($B$3:B12)) -> 10 | B12: កាំបិទលើS Fixed Knif For Sirubar,Sirubar 固定刀片 | C12: តូច small​ 小 | D12: ='9-15'!F12 -> 0 | E12: =SUM(J12:U12) -> 0 | F12: =D12-E12 -> 0 | G12: =D12-F12 -> 0
A13: =IF(B13="","",COUNTA($B$3:B13)) -> 11 | B13: កាំបិទក្រោមS,Movable Knife For Sirubar,Siruba 动刀 Sirubar | C13: តូច small​ 小 | D13: ='9-15'!F13 -> 0 | E13: =SUM(J13:U13) -> 0 | F13: =D13-E13 -> 0 | G13: =D13-F13 -> 0
A14: =IF(B14="","",COUNTA($B$3:B14)) -> 12 | B14: ដែកបុកកាក់ Dowel Pin,定位销 | C14: តូច small​ 小 | D14: ='9-15'!F14 -> 7 | E14: =SUM(J14:U14) -> 0 | F14: =D14-E14 -> 7 | G14: =D14-F14 -> 0
A15: =IF(B15="","",COUNTA($B$3:B15)) -> 13 | B15: ផ្ទាំងបញ្ជាខៀវJ,Blue control Panel JUKI,JUKI 蓝色控制面板 | C15: តូច small​ 小 | D15: ='9-15'!F15 -> 5 | E15: =SUM(J15:U15) -> 0 | F15: =D15-E15 -> 5 | G15: =D15-F15 -> 0
A16: =IF(B16="","",COUNTA($B$3:B16)) -> 14 | B16: ផ្ទាំងបញ្ជាសJ White color control Panel JUKI,JUKI 白色控制面板 | C16: តូច small​ 小 | D16: ='9-15'!F16 -> 3 | E16: =SUM(J16:U16) -> 0 | F16: =D16-E16 -> 3 | G16: =D16-F16 -> 0
A17: =IF(B17="","",COUNTA($B$3:B17)) -> 15 | B17: ផ្ទាំងបញ្ជាជំនាន់ចាស់J, Old Verson Board JUKI,JUKI 旧版电路板 | C17: តូច small​ 小 | D17: ='9-15'!F17 -> 3 | E17: =SUM(J17:U17) -> 0 | F17: =D17-E17 -> 3 | G17: =D17-F17 -> 0
A18: =IF(B18="","",COUNTA($B$3:B18)) -> 16 | B18: ខ្សែរទាញកាក់,CABLE ASSY, HOOD LOCK CONTROL,发动机罩锁控制拉索组件 | C18: តូច small​ 小 | D18: ='9-15'!F18 -> 2 | E18: =SUM(J18:U18) -> 0 | F18: =D18-E18 -> 2 | G18: =D18-F18 -> 0
A19: =IF(B19="","",COUNTA($B$3:B19)) -> 17 | B19: ជ័រខារអំបោះ,Bobbin winder rubber ring,绕线器橡胶圈 | C19: តូច small​ 小 | D19: ='9-15'!F19 -> 42 | E19: =SUM(J19:U19) -> 1 | F19: =D19-E19 -> 41 | G19: =D19-F19 -> 1 | P19: 1
A20: =IF(B20="","",COUNTA($B$3:B20)) -> 18 | B20: កាក់ធំ,Thread Tention Assembly,张力调节组件 | C20: ធំ Big 大的 | D20: ='9-15'!F20 -> 2 | E20: =SUM(J20:U20) -> 0 | F20: =D20-E20 -> 2 | G20: =D20-F20 -> 0
A21: =IF(B21="","",COUNTA($B$3:B21)) -> 19 | B21: កាក់តូច,Thread Tension Assembly Small,小型线张力组件 | C21: តូច small​ 小 | D21: ='9-15'!F21 -> 19 | E21: =SUM(J21:U21) -> 0 | F21: =D21-E21 -> 19 | G21: =D21-F21 -> 0
A22: =IF(B22="","",COUNTA($B$3:B22)) -> 20 | B22: ដងម្ជុល,Needle Bar,针杆 | C22: តូច small​ 小 | D22: ='9-15'!F22 -> 5 | E22: =SUM(J22:U22) -> 0 | F22: =D22-E22 -> 5 | G22: =D22-F22 -> 0
A23: =IF(B23="","",COUNTA($B$3:B23)) -> 21 | B23: ជើងទាឆុត,Teeth Presser Foot and Needle Plate Kit, 齿形压脚与针板套件 | C23: តូច small​ 小 | D23: ='9-15'!F23 -> 3 | E23: =SUM(J23:U23) -> 0 | F23: =D23-E23 -> 3 | G23: =D23-F23 -> 0
A24: =IF(B24="","",COUNTA($B$3:B24)) -> 22 | B24: ដែកវាត់អំបោះ,Thread Tension Spring,线张力弹簧 | C24: តូច small​ 小 | D24: ='9-15'!F24 -> 23 | E24: =SUM(J24:U24) -> 0 | F24: =D24-E24 -> 23 | G24: =D24-F24 -> 0
A25: =IF(B25="","",COUNTA($B$3:B25)) -> 23 | B25: ឈើកាវក្រោម,Upper looper, 上弯针 | C25: តូច small​ 小 | D25: ='9-15'!F25 -> 10 | E25: =SUM(J25:U25) -> 0 | F25: =D25-E25 -> 10 | G25: =D25-F25 -> 0
A26: =IF(B26="","",COUNTA($B$3:B26)) -> 24 | B26: ឈើកាវលើ, Lower Looper,下弯针 | C26: តូច small​ 小 | D26: ='9-15'!F26 -> 0 | E26: =SUM(J26:U26) -> 0 | F26: =D26-E26 -> 0 | G26: =D26-F26 -> 0
A27: =IF(B27="","",COUNTA($B$3:B27)) -> 25 | B27: ដងជើងទា,calcador overlock,包缝压脚 | C27: តូច small​ 小 | D27: ='9-15'!F27 -> 1 | E27: =SUM(J27:U27) -> 0 | F27: =D27-E27 -> 1 | G27: =D27-F27 -> 0
A28: =IF(B28="","",COUNTA($B$3:B28)) -> 26 | B28: ធ្មេញក្រោយ,God feed Overlock Machine,差动送料包缝机 | C28: តូច small​ 小 | D28: ='9-15'!F28 -> 0 | E28: =SUM(J28:U28) -> 0 | F28: =D28-E28 -> 0 | G28: =D28-F28 -> 0
A29: =IF(B29="","",COUNTA($B$3:B29)) -> 27 | B29: សន្ទះធ្មេញ, Needle Plate Fit,针板适配 | C29: តូច small​ 小 | D29: ='9-15'!F29 -> 9 | E29: =SUM(J29:U29) -> 0 | F29: =D29-E29 -> 9 | G29: =D29-F29 -> 0
A30: =IF(B30="","",COUNTA($B$3:B30)) -> 28 | B30: កាំបិតក្រោម,Lower Bottom Knife to Fit Overlock Machine,降低包缝机下刀位置 | C30: តូច small​ 小 | D30: ='9-15'!F30 -> 4 | E30: =SUM(J30:U30) -> 0 | F30: =D30-E30 -> 4 | G30: =D30-F30 -> 0
A31: =IF(B31="","",COUNTA($B$3:B31)) -> 29 | B31: កាំបិតលើ,Top Knife for Overlock,包缝机上刀 | C31: តូច small​ 小 | D31: ='9-15'!F31 -> 0 | E31: =SUM(J31:U31) -> 0 | F31: =D31-E31 -> 0 | G31: =D31-F31 -> 0
... A80: =IF(B80="","",COUNTA($B$3:B80)) -> 78 | B80: កាំបិតក្រោម, Bottom Thread Trimmer, 底线切线器 | C80: តូច small​ 小 | D80: ='9-15'!F80 -> 1 | E80: =SUM(J80:U80) -> 0 | F80: =D80-E80 -> 1 | G80: =D80-F80 -> 0
A81: =IF(B81="","",COUNTA($B$3:B81)) -> 79 | B81: ប្រេងម៉ាស៊ីនខ្យល់ Air_Compressor Oil 空气压缩机油 | C81: ធំ Big 大的 | D81: 1 | F81: 1
A82: =IF(B82="","",COUNTA($B$3:B82)) | G82: =D82-F82 -> 0
G83: =D83-F83 -> 0
G84: =D84-F84 -> 0

Sheet 9-17
B1: ​​​ របាយការណ៏ដូរ​បន្លាស់ប្រចាំថ្ងៃ Daily Spare Part Change Report 每日备件更换报告 | G1: 17/9/2026 | J1: ការផ្លាស់ប្តូរគ្រឿងបន្លាស់សម្រាប់ខ្សែសង្វាក់ផលិតកម្មដេរ, Spare Part Change For Sewing Line , 缝纫线备件更换
A2: លរ​ No. 数字 | B2: ប្រភេទគ្រឿងបន្លាស់ Sparepart Type 备件类型 | C2: ទំហំ​ SIZE 尺寸 | D2: ចំនួននៅសល់ Stock Left 剩余库存 | E2: ម្ជុលដែលបានផ្តល់ជូន, Issued Needle, 已发放的针头 | F2: តុល្យភាព Balance 平衡 | G2: សំគាល់ Remark 评论 | H2: Column1 | J2: # 1 | K2: # 2 | L2: # 3 | M2: # 4 | N2: # 5 | O2: # 6 | P2: # 7 | Q2: # 8 | R2: # 9 | S2: # 10 | T2: # 11 | U2: # 12
A3: =IF(B3="","",COUNTA($B$3:B3)) -> 1 | B3: សំបុក Rotary Hook 旋梭 | C3: តូច small​ 小 | D3: ='9-16'!F3 -> 2 | E3: =SUM(J3:U3) -> 0 | F3: =D3-E3 -> 2 | X3: ខូច​ Damage 损害
A4: =IF(B4="","",COUNTA($B$3:B4)) -> 2 | B4: ធ្មេញរង្វើល Feed Dog 送布牙 | C4: តូច small​ 小 | D4: ='9-16'!F4 -> 57 | E4: =SUM(J4:U4) -> 3 | F4: =D4-E4 -> 54 | G4: ខូច​ Damage 损害 | M4: 1 | O4: 1 | Q4: 1 | X4: បាក់​ Broken 破碎的
A5: =IF(B5="","",COUNTA($B$3:B5)) -> 3 | B5: ធ្មេញញឺក Feed Dog fits适用于送布牙 | C5: តូច small​ 小 | D5: ='9-16'!F5 -> 8 | E5: =SUM(J5:U5) -> 0 | F5: =D5-E5 -> 8 | X5: ប្តូរម៉ូដ Change Style, 更改样式
A6: =IF(B6="","",COUNTA($B$3:B6)) -> 4 | B6: សន្ទះធ្មេញ Needle Plate 针板 | C6: តូច small​ 小 | D6: ='9-16'!F6 -> 11 | E6: =SUM(J6:U6) -> 0 | F6: =D6-E6 -> 11 | X6: បាត់​ Lost 迷失
A7: =IF(B7="","",COUNTA($B$3:B7)) -> 5 | B7: សន្ទះធ្មេញទុន Needle Plate 针板 | C7: តូច small​ 小 | D7: ='9-16'!F7 -> 3 | E7: =SUM(J7:U7) -> 0 | F7: =D7-E7 -> 3 | X7: ផ្សេងៗ​ Other 其他
A8: =IF(B8="","",COUNTA($B$3:B8)) -> 6 | B8: កាំបិទលើJ Fixed Knife for JUKI JUKI用固定刀 | C8: តូច small​ 小 | D8: ='9-16'!F8 -> 20 | E8: =SUM(J8:U8) -> 1 | F8: =D8-E8 -> 19 | G8: ខូច​ Damage 损害 | K8: 1
A9: =IF(B9="","",COUNTA($B$3:B9)) -> 7 | B9: កាំបិទក្រោមS, Thread Cutter Blade For Sirubar, Sirubar 切线刀片 | C9: តូច small​ 小 | D9: ='9-16'!F9 -> 13 | E9: =SUM(J9:U9) -> 0 | F9: =D9-E9 -> 13
A10: =IF(B10="","",COUNTA($B$3:B10)) -> 8 | B10: សន្លឺកស្រូវJ Thread Guide For JUKI,JUKI 穿线导向器 | C10: តូច small​ 小 | D10: ='9-16'!F10 -> 2 | E10: =SUM(J10:U10) -> 0 | F10: =D10-E10 -> 2
A11: =IF(B11="","",COUNTA($B$3:B11)) -> 9 | B11: សន្លឺកស្រូវS Thread Finger For Sirubar,适用于 Siruba 的过线指 | C11: តូច small​ 小 | D11: ='9-16'!F11 -> 4 | E11: =SUM(J11:U11) -> 0 | F11: =D11-E11 -> 4
A12: =IF(B12="","",COUNTA($B$3:B12)) -> 10 | B12: កាំបិទលើS Fixed Knif For Sirubar,Sirubar 固定刀片 | C12: តូច small​ 小 | D12: ='9-16'!F12 -> 0 | E12: =SUM(J12:U12) -> 0 | F12: =D12-E12 -> 0
A13: =IF(B13="","",COUNTA($B$3:B13)) -> 11 | B13: កាំបិទក្រោមS,Movable Knife For Sirubar,Siruba 动刀 Sirubar | C13: តូច small​ 小 | D13: ='9-16'!F13 -> 0 | E13: =SUM(J13:U13) -> 0 | F13: =D13-E13 -> 0
A14: =IF(B14="","",COUNTA($B$3:B14)) -> 12 | B14: ដែកបុកកាក់ Dowel Pin,定位销 | C14: តូច small​ 小 | D14: ='9-16'!F14 -> 7 | E14: =SUM(J14:U14) -> 0 | F14: =D14-E14 -> 7
A15: =IF(B15="","",COUNTA($B$3:B15)) -> 13 | B15: ផ្ទាំងបញ្ជាខៀវJ,Blue control Panel JUKI,JUKI 蓝色控制面板 | C15: តូច small​ 小 | D15: ='9-16'!F15 -> 5 | E15: =SUM(J15:U15) -> 0 | F15: =D15-E15 -> 5
A16: =IF(B16="","",COUNTA($B$3:B16)) -> 14 | B16: ផ្ទាំងបញ្ជាសJ White color control Panel JUKI,JUKI 白色控制面板 | C16: តូច small​ 小 | D16: ='9-16'!F16 -> 3 | E16: =SUM(J16:U16) -> 0 | F16: =D16-E16 -> 3
A17: =IF(B17="","",COUNTA($B$3:B17)) -> 15 | B17: ផ្ទាំងបញ្ជាជំនាន់ចាស់J, Old Verson Board JUKI,JUKI 旧版电路板 | C17: តូច small​ 小 | D17: ='9-16'!F17 -> 3 | E17: =SUM(J17:U17) -> 0 | F17: =D17-E17 -> 3
A18: =IF(B18="","",COUNTA($B$3:B18)) -> 16 | B18: ខ្សែរទាញកាក់,CABLE ASSY, HOOD LOCK CONTROL,发动机罩锁控制拉索组件 | C18: តូច small​ 小 | D18: ='9-16'!F18 -> 2 | E18: =SUM(J18:U18) -> 0 | F18: =D18-E18 -> 2
A19: =IF(B19="","",COUNTA($B$3:B19)) -> 17 | B19: ជ័រខារអំបោះ,Bobbin winder rubber ring,绕线器橡胶圈 | C19: តូច small​ 小 | D19: ='9-16'!F19 -> 41 | E19: =SUM(J19:U19) -> 0 | F19: =D19-E19 -> 41
A20: =IF(B20="","",COUNTA($B$3:B20)) -> 18 | B20: កាក់ធំ,Thread Tention Assembly,张力调节组件 | C20: ធំ Big 大的 | D20: ='9-16'!F20 -> 2 | E20: =SUM(J20:U20) -> 1 | F20: =D20-E20 -> 1 | G20: បាក់​ Broken 破碎的 | N20: 1
A21: =IF(B21="","",COUNTA($B$3:B21)) -> 19 | B21: កាក់តូច,Thread Tension Assembly Small,小型线张力组件 | C21: តូច small​ 小 | D21: ='9-16'!F21 -> 19 | E21: =SUM(J21:U21) -> 0 | F21: =D21-E21 -> 19
A22: =IF(B22="","",COUNTA($B$3:B22)) -> 20 | B22: ដងម្ជុល,Needle Bar,针杆 | C22: តូច small​ 小 | D22: ='9-16'!F22 -> 5 | E22: =SUM(J22:U22) -> 0 | F22: =D22-E22 -> 5
A23: =IF(B23="","",COUNTA($B$3:B23)) -> 21 | B23: ជើងទាឆុត,Teeth Presser Foot and Needle Plate Kit, 齿形压脚与针板套件 | C23: តូច small​ 小 | D23: ='9-16'!F23 -> 3 | E23: =SUM(J23:U23) -> 0 | F23: =D23-E23 -> 3
A24: =IF(B24="","",COUNTA($B$3:B24)) -> 22 | B24: ដែកវាត់អំបោះ,Thread Tension Spring,线张力弹簧 | C24: តូច small​ 小 | D24: ='9-16'!F24 -> 23 | E24: =SUM(J24:U24) -> 1 | F24: =D24-E24 -> 22 | G24: ផ្សេងៗ​ Other 其他 | L24: 1
A25: =IF(B25="","",COUNTA($B$3:B25)) -> 23 | B25: ឈើកាវក្រោម,Upper looper, 上弯针 | C25: តូច small​ 小 | D25: ='9-16'!F25 -> 10 | E25: =SUM(J25:U25) -> 0 | F25: =D25-E25 -> 10
A26: =IF(B26="","",COUNTA($B$3:B26)) -> 24 | B26: ឈើកាវលើ, Lower Looper,下弯针 | C26: តូច small​ 小 | D26: ='9-16'!F26 -> 0 | E26: =SUM(J26:U26) -> 0 | F26: =D26-E26 -> 0
A27: =IF(B27="","",COUNTA($B$3:B27)) -> 25 | B27: ដងជើងទា,calcador overlock,包缝压脚 | C27: តូច small​ 小 | D27: ='9-16'!F27 -> 1 | E27: =SUM(J27:U27) -> 0 | F27: =D27-E27 -> 1
A28: =IF(B28="","",COUNTA($B$3:B28)) -> 26 | B28: ធ្មេញក្រោយ,God feed Overlock Machine,差动送料包缝机 | C28: តូច small​ 小 | D28: ='9-16'!F28 -> 0 | E28: =SUM(J28:U28) -> 0 | F28: =D28-E28 -> 0
A29: =IF(B29="","",COUNTA($B$3:B29)) -> 27 | B29: សន្ទះធ្មេញ, Needle Plate Fit,针板适配 | C29: តូច small​ 小 | D29: ='9-16'!F29 -> 9 | E29: =SUM(J29:U29) -> 0 | F29: =D29-E29 -> 9
A30: =IF(B30="","",COUNTA($B$3:B30)) -> 28 | B30: កាំបិតក្រោម,Lower Bottom Knife to Fit Overlock Machine,降低包缝机下刀位置 | C30: តូច small​ 小 | D30: ='9-16'!F30 -> 4 | E30: =SUM(J30:U30) -> 0 | F30: =D30-E30 -> 4
A31: =IF(B31="","",COUNTA($B$3:B31)) -> 29 | B31: កាំបិតលើ,Top Knife for Overlock,包缝机上刀 | C31: តូច small​ 小 | D31: ='9-16'!F31 -> 0 | E31: =SUM(J31:U31) -> 0 | F31: =D31-E31 -> 0
A32: =IF(B32="","",COUNTA($B$3:B32)) -> 30 | B32: ដងម្ជុល,Needle Clamp Holder Fitsr,适配机针夹持器 | C32: តូច small​ 小 | D32: ='9-16'!F32 -> 8 | E32: =SUM(J32:U32) -> 0 | F32: =D32-E32 -> 8
A33: =IF(B33="","",COUNTA($B$3:B33)) -> 31 | B33: ឈើកាវផ្កាដូង,Chainstitch Looper 5 Thread,五线链式缝弯针 | C33: តូច small​ 小 | D33: ='9-16'!F33 -> 0 | E33: =SUM(J33:U33) -> 0 | F33: =D33-E33 -> 0
A34: =IF(B34="","",COUNTA($B$3:B34)) -> 32 | B34: រុន្ធម្ជុលសាប់,Needle Hole Guide Bartack Machine, 针孔定位套结机 | C34: តូច small​ 小 | D34: ='9-16'!F34 -> 7 | E34: =SUM(J34:U34) -> 0 | F34: =D34-E34 -> 7
A35: =IF(B35="","",COUNTA($B$3:B35)) -> 33 | B35: សំបុកសាប់, Shuttle Hook Fit Bartack Machine, 适用于套结机的摆梭旋梭 | C35: តូច small​ 小 | D35: ='9-16'!F35 -> 0 | E35: =SUM(J35:U35) -> 0 | F35: =D35-E35 -> 0
A36: =IF(B36="","",COUNTA($B$3:B36)) -> 34 | B36: ដែកបុកកាក់, Thread Tension Release Pin, 线张力释放销 | C36: តូច small​ 小 | D36: ='9-16'!F36 -> 8 | E36: =SUM(J36:U36) -> 0 | F36: =D36-E36 -> 8
... A80: =IF(B80="","",COUNTA($B$3:B80)) -> 78 | B80: កាំបិតក្រោម, Bottom Thread Trimmer, 底线切线器 | C80: តូច small​ 小 | D80: ='9-16'!F80 -> 1 | E80: =SUM(J80:U80) -> 0 | F80: =D80-E80 -> 1
A81: =IF(B81="","",COUNTA($B$3:B81)) -> 79 | B81: ជើងវ៉ៃអំបោះសាប់, Fly Feather, 飞羽 | C81: តូច small​ 小 | D81: 12 | E81: =SUM(J81:U81) -> 1 | F81: =D81-E81 -> 11 | G81: បាក់​ Broken 破碎的 | S81: 1
A82: =IF(B82="","",COUNTA($B$3:B82)) -> 80 | B82: ប្រេងម៉ាស៊ីនខ្យល់ Air_Compressor Oil 空气压缩机油 | C82: ធំ Big 大的 | D82: 1 | F82: 1
D84: =SUM(D3:D83) -> 788 | E84: =SUM(E3:E83) -> 7 | F84: =SUM(F3:F83) -> 781

Sheet 9-18
B1: ​​​ របាយការណ៏ដូរ​បន្លាស់ប្រចាំថ្ងៃ Daily Spare Part Change Report 每日备件更换报告 | H1: 46283 | K1: ការផ្លាស់ប្តូរគ្រឿងបន្លាស់សម្រាប់ខ្សែសង្វាក់ផលិតកម្មដេរ, Spare Part Change For Sewing Line , 缝纫线备件更换
A2: លរ​ No. 数字 | B2: ប្រភេទគ្រឿងបន្លាស់ Sparepart Type 备件类型 | C2: ទំហំ​ SIZE 尺寸 | D2: តុល្យភាព Closing Balance 期末余额 | E2: ទទួល​ Received ​已收到 | F2: ម្ជុលដែលបានផ្តល់ជូន, Issued Needle, 已发放的针头 | G2: ចំនួននៅសល់ Opening Balance 未结余额2 | H2: សំគាល់ Remark 评论 | K2: # 1 | L2: # 2 | M2: # 3 | N2: # 4 | O2: # 5 | P2: # 6 | Q2: # 7 | R2: # 8 | S2: # 9 | T2: # 10 | U2: # 11 | V2: # 12
A3: =IF(B3="","",COUNTA($B$3:B3)) -> 1 | B3: សំបុកម្ជុល១ Single Needle Rotary Hook 单针旋梭 | C3: តូច small​ 小 | D3: ='9-17'!F3+E3 -> 2 | F3: =SUM(K3:V3) -> 0 | G3: =D3-F3 -> 2 | Y3: ខូច​ Damage 损害
A4: =IF(B4="","",COUNTA($B$3:B4)) -> 2 | B4: ធ្មេញរង្វើល Feed Dog 送布牙 | C4: តូច small​ 小 | D4: ='9-17'!F4+E4 -> 54 | F4: =SUM(K4:V4) -> 1 | G4: =D4-F4 -> 53 | H4: ខូច​ Damage 损害 | M4: 1 | Y4: បាក់​ Broken 破碎的
A5: =IF(B5="","",COUNTA($B$3:B5)) -> 3 | B5: ធ្មេញញឺក Feed Dog fits适用于送布牙 | C5: តូច small​ 小 | D5: ='9-17'!F5+E5 -> 8 | F5: =SUM(K5:V5) -> 0 | G5: =D5-F5 -> 8 | Y5: ប្តូរម៉ូដ Change Style, 更改样式
A6: =IF(B6="","",COUNTA($B$3:B6)) -> 4 | B6: សន្ទះធ្មេញ Needle Plate 针板 | C6: តូច small​ 小 | D6: ='9-17'!F6+E6 -> 11 | F6: =SUM(K6:V6) -> 0 | G6: =D6-F6 -> 11 | Y6: បាត់​ Lost 迷失
A7: =IF(B7="","",COUNTA($B$3:B7)) -> 5 | B7: សន្ទះធ្មេញទុន Needle Plate 针板 | C7: តូច small​ 小 | D7: ='9-17'!F7+E7 -> 3 | F7: =SUM(K7:V7) -> 0 | G7: =D7-F7 -> 3 | Y7: ផ្សេងៗ​ Other 其他
A8: =IF(B8="","",COUNTA($B$3:B8)) -> 6 | B8: កាំបិទលើJ Fixed Knife for JUKI JUKI用固定刀 | C8: តូច small​ 小 | D8: ='9-17'!F8+E8 -> 19 | F8: =SUM(K8:V8) -> 0 | G8: =D8-F8 -> 19
A9: =IF(B9="","",COUNTA($B$3:B9)) -> 7 | B9: កាំបិទក្រោមS, Thread Cutter Blade For Sirubar, Sirubar 切线刀片 | C9: តូច small​ 小 | D9: ='9-17'!F9+E9 -> 13 | F9: =SUM(K9:V9) -> 0 | G9: =D9-F9 -> 13
A10: =IF(B10="","",COUNTA($B$3:B10)) -> 8 | B10: សន្លឺកស្រូវJ Thread Guide For JUKI,JUKI 穿线导向器 | C10: តូច small​ 小 | D10: ='9-17'!F10+E10 -> 2 | F10: =SUM(K10:V10) -> 0 | G10: =D10-F10 -> 2
A11: =IF(B11="","",COUNTA($B$3:B11)) -> 9 | B11: សន្លឺកស្រូវS Thread Finger For Sirubar,适用于 Siruba 的过线指 | C11: តូច small​ 小 | D11: ='9-17'!F11+E11 -> 4 | F11: =SUM(K11:V11) -> 0 | G11: =D11-F11 -> 4
A12: =IF(B12="","",COUNTA($B$3:B12)) -> 10 | B12: កាំបិទលើS Fixed Knif For Sirubar,Sirubar 固定刀片 | C12: តូច small​ 小 | D12: ='9-17'!F12+E12 -> 0 | F12: =SUM(K12:V12) -> 0 | G12: =D12-F12 -> 0
A13: =IF(B13="","",COUNTA($B$3:B13)) -> 11 | B13: កាំបិទក្រោមS,Movable Knife For Sirubar,Siruba 动刀 Sirubar | C13: តូច small​ 小 | D13: ='9-17'!F13+E13 -> 0 | F13: =SUM(K13:V13) -> 0 | G13: =D13-F13 -> 0
A14: =IF(B14="","",COUNTA($B$3:B14)) -> 12 | B14: ដែកបុកកាក់ Dowel Pin,定位销 | C14: តូច small​ 小 | D14: ='9-17'!F14+E14 -> 7 | F14: =SUM(K14:V14) -> 0 | G14: =D14-F14 -> 7
A15: =IF(B15="","",COUNTA($B$3:B15)) -> 13 | B15: ផ្ទាំងបញ្ជាខៀវJ,Blue control Panel JUKI,JUKI 蓝色控制面板 | C15: តូច small​ 小 | D15: ='9-17'!F15+E15 -> 5 | F15: =SUM(K15:V15) -> 0 | G15: =D15-F15 -> 5
A16: =IF(B16="","",COUNTA($B$3:B16)) -> 14 | B16: ផ្ទាំងបញ្ជាសJ White color control Panel JUKI,JUKI 白色控制面板 | C16: តូច small​ 小 | D16: ='9-17'!F16+E16 -> 3 | F16: =SUM(K16:V16) -> 0 | G16: =D16-F16 -> 3
A17: =IF(B17="","",COUNTA($B$3:B17)) -> 15 | B17: ផ្ទាំងបញ្ជាជំនាន់ចាស់J, Old Verson Board JUKI,JUKI 旧版电路板 | C17: តូច small​ 小 | D17: ='9-17'!F17+E17 -> 3 | F17: =SUM(K17:V17) -> 0 | G17: =D17-F17 -> 3
A18: =IF(B18="","",COUNTA($B$3:B18)) -> 16 | B18: ខ្សែរទាញកាក់,CABLE ASSY, HOOD LOCK CONTROL,发动机罩锁控制拉索组件 | C18: តូច small​ 小 | D18: ='9-17'!F18+E18 -> 2 | F18: =SUM(K18:V18) -> 0 | G18: =D18-F18 -> 2
A19: =IF(B19="","",COUNTA($B$3:B19)) -> 17 | B19: ជ័រខារអំបោះ,Bobbin winder rubber ring,绕线器橡胶圈 | C19: តូច small​ 小 | D19: ='9-17'!F19+E19 -> 41 | F19: =SUM(K19:V19) -> 0 | G19: =D19-F19 -> 41
... A68: =IF(B68="","",COUNTA($B$3:B68)) -> 66 | B68: ជ័រកាថ502,Glue 502, 胶水 | C68: ធំ Big 大的 | D68: ='9-17'!F68+E68 -> 30 | F68: =SUM(K68:V68) -> 0 | G68: =D68-F68 -> 30
A69: =IF(B69="","",COUNTA($B$3:B69)) -> 67 | B69: ឡតម៉ាស៊ីនផុង, Coupling Overlock, 包缝接合 | C69: តូច small​ 小 | D69: ='9-17'!F69+E69 -> 1 | F69: =SUM(K69:V69) -> 1 | G69: =D69-F69 -> 0 | H69: ខូច​ Damage 损害 | R69: 1
A70: =IF(B70="","",COUNTA($B$3:B70)) -> 68 | B70: ឆ្នាំងអ៊ុត, Iron, 铁 | C70: តូច small​ 小 | D70: ='9-17'!F70+E70 -> 0 | F70: =SUM(K70:V70) -> 0 | G70: =D70-F70 -> 0
A71: =IF(B71="","",COUNTA($B$3:B71)) -> 69 | B71: ទួណឺវីស, screwdriver, 螺丝刀 | C71: តូច small​ 小 | D71: ='9-17'!F71+E71 -> 0 | F71: =SUM(K71:V71) -> 0 | G71: =D71-F71 -> 0
A72: =IF(B72="","",COUNTA($B$3:B72)) -> 70 | B72: សោគាម៉ាស៊ីនម្ជុល១, SINGER BOBBIN CASE | C72: តូច small​ 小 | D72: ='9-17'!F72+E72 -> 14 | F72: =SUM(K72:V72) -> 0 | G72: =D72-F72 -> 14
A73: =IF(B73="","",COUNTA($B$3:B73)) -> 71 | B73: ដងចាប់ពុម្ភ, Sewing Gauge, 缝纫量规 | C73: តូច small​ 小 | D73: ='9-17'!F73+E73 -> 38 | F73: =SUM(K73:V73) -> 0 | G73: =D73-F73 -> 38
A74: =IF(B74="","",COUNTA($B$3:B74)) -> 72 | B74: កន្រ្តៃកាត់អំបោះ ,Sewing Scissors Yarn Thread Cutter, 缝纫剪刀/纱线剪 | C74: តូច small​ 小 | D74: ='9-17'!F74+E74 -> 5 | F74: =SUM(K74:V74) -> 0 | G74: =D74-F74 -> 5
A75: =IF(B75="","",COUNTA($B$3:B75)) -> 73 | B75: ប៉ាដាង​#6202, Bearing #6202, 轴承 #6202 | C75: តូច small​ 小 | D75: ='9-17'!F75+E75 -> 185 | F75: =SUM(K75:V75) -> 0 | G75: =D75-F75 -> 185
A76: =IF(B76="","",COUNTA($B$3:B76)) -> 74 | B76: កុងតាក់តូច, MINI ROCKER Switch , 迷你船型开关 | C76: តូច small​ 小 | D76: ='9-17'!F76+E76 -> 4 | F76: =SUM(K76:V76) -> 0 | G76: =D76-F76 -> 4
A77: =IF(B77="","",COUNTA($B$3:B77)) -> 75 | B77: ដីសខ្លាឃ្មុំ, Panda Garment Chalk, 熊猫牌服装粉笔 | C77: តូច small​ 小 | D77: ='9-17'!F77+E77 -> 8 | F77: =SUM(K77:V77) -> 0 | G77: =D77-F77 -> 8
A78: =IF(B78="","",COUNTA($B$3:B78)) -> 76 | B78: ដីសពណ៌, Color Chalk ,彩色粉笔 | C78: តូច small​ 小 | D78: ='9-17'!F78+E78 -> 19 | F78: =SUM(K78:V78) -> 0 | G78: =D78-F78 -> 19
A79: =IF(B79="","",COUNTA($B$3:B79)) -> 77 | B79: កន្រ្តៃលើ, Upper Thread Trimming, 面线剪线 | C79: តូច small​ 小 | D79: ='9-17'!F79+E79 -> 8 | F79: =SUM(K79:V79) -> 0 | G79: =D79-F79 -> 8
A80: =IF(B80="","",COUNTA($B$3:B80)) -> 78 | B80: កាំបិតក្រោម, Bottom Thread Trimmer, 底线切线器 | C80: តូច small​ 小 | D80: ='9-17'!F80+E80 -> 1 | F80: =SUM(K80:V80) -> 0 | G80: =D80-F80 -> 1
A81: =IF(B81="","",COUNTA($B$3:B81)) -> 79 | B81: ជើងវ៉ៃអំបោះសាប់, Fly Feather, 飞羽 | C81: តូច small​ 小 | D81: 11 | F81: =SUM(K81:V81) -> 1 | G81: =D81-F81 -> 10 | H81: បាក់​ Broken 破碎的 | O81: 1
A82: =IF(B82="","",COUNTA($B$3:B82)) -> 80 | B82: ប្រេងម៉ាស៊ីនខ្យល់ Air_Compressor Oil 空气压缩机油 | C82: ធំ Big 大的 | D82: 1 | G82: =D82-F82 -> 1
D84: =SUM(D3:D83) -> 781 | E84: =SUM(E3:E83) -> 0 | F84: =SUM(F3:F83) -> 3 | G84: =SUM(G3:G83) -> 778

Sheet 9-19
B1: ​​​ របាយការណ៏ដូរ​បន្លាស់ប្រចាំថ្ងៃ Daily Spare Part Change Report 每日备件更换报告 | H1: 46284 | K1: ការផ្លាស់ប្តូរគ្រឿងបន្លាស់សម្រាប់ខ្សែសង្វាក់ផលិតកម្មដេរ, Spare Part Change For Sewing Line , 缝纫线备件更换
A2: លរ​ No. 数字 | B2: ប្រភេទគ្រឿងបន្លាស់ Sparepart Type 备件类型 | C2: ទំហំ​ SIZE 尺寸 | D2: តុល្យភាព Closing Balance 期末余额 | E2: ទទួល​ Received ​已收到 | F2: ម្ជុលដែលបានផ្តល់ជូន, Issued Needle, 已发放的针头 | G2: ចំនួននៅសល់ Opening Balance 未结余额2 | H2: សំគាល់ Remark 评论 | K2: # 1 | L2: # 2 | M2: # 3 | N2: # 4 | O2: # 5 | P2: # 6 | Q2: # 7 | R2: # 8 | S2: # 9 | T2: # 10 | U2: # 11 | V2: # 12
A3: =IF(B3="","",COUNTA($B$3:B3)) -> 1 | B3: សំបុកម្ជុល១ Single Needle Rotary Hook 单针旋梭 | C3: តូច small​ 小 | D3: ='9-18'!G3+E3 -> 12 | E3: 10 | F3: =SUM(K3:V3) -> 0 | G3: =D3-F3 -> 12 | Y3: ខូច​ Damage 损害
A4: =IF(B4="","",COUNTA($B$3:B4)) -> 2 | B4: ធ្មេញរង្វើល Feed Dog 送布牙 | C4: តូច small​ 小 | D4: ='9-18'!G4+E4 -> 53 | F4: =SUM(K4:V4) -> 0 | G4: =D4-F4 -> 53 | Y4: បាក់​ Broken 破碎的
A5: =IF(B5="","",COUNTA($B$3:B5)) -> 3 | B5: ធ្មេញញឺក Feed Dog fits适用于送布牙 | C5: តូច small​ 小 | D5: ='9-18'!G5+E5 -> 8 | F5: =SUM(K5:V5) -> 0 | G5: =D5-F5 -> 8 | Y5: ប្តូរម៉ូដ Change Style, 更改样式
A6: =IF(B6="","",COUNTA($B$3:B6)) -> 4 | B6: សន្ទះធ្មេញ Needle Plate 针板 | C6: តូច small​ 小 | D6: ='9-18'!G6+E6 -> 11 | F6: =SUM(K6:V6) -> 1 | G6: =D6-F6 -> 10 | H6: ខូច​ Damage 损害 | Q6: 1 | Y6: បាត់​ Lost 迷失
A7: =IF(B7="","",COUNTA($B$3:B7)) -> 5 | B7: សន្ទះធ្មេញទុន Needle Plate 针板 | C7: តូច small​ 小 | D7: ='9-18'!G7+E7 -> 3 | F7: =SUM(K7:V7) -> 0 | G7: =D7-F7 -> 3 | Y7: ផ្សេងៗ​ Other 其他
A8: =IF(B8="","",COUNTA($B$3:B8)) -> 6 | B8: កាំបិទលើJ Fixed Knife for JUKI JUKI用固定刀 | C8: តូច small​ 小 | D8: ='9-18'!G8+E8 -> 19 | F8: =SUM(K8:V8) -> 0 | G8: =D8-F8 -> 19
A9: =IF(B9="","",COUNTA($B$3:B9)) -> 7 | B9: កាំបិទក្រោមS, Thread Cutter Blade For Sirubar, Sirubar 切线刀片 | C9: តូច small​ 小 | D9: ='9-18'!G9+E9 -> 13 | F9: =SUM(K9:V9) -> 0 | G9: =D9-F9 -> 13
A10: =IF(B10="","",COUNTA($B$3:B10)) -> 8 | B10: សន្លឺកស្រូវJ Thread Guide For JUKI,JUKI 穿线导向器 | C10: តូច small​ 小 | D10: ='9-18'!G10+E10 -> 2 | F10: =SUM(K10:V10) -> 0 | G10: =D10-F10 -> 2
A11: =IF(B11="","",COUNTA($B$3:B11)) -> 9 | B11: សន្លឺកស្រូវS Thread Finger For Sirubar,适用于 Siruba 的过线指 | C11: តូច small​ 小 | D11: ='9-18'!G11+E11 -> 4 | F11: =SUM(K11:V11) -> 0 | G11: =D11-F11 -> 4
A12: =IF(B12="","",COUNTA($B$3:B12)) -> 10 | B12: កាំបិទលើS Fixed Knif For Sirubar,Sirubar 固定刀片 | C12: តូច small​ 小 | D12: ='9-18'!G12+E12 -> 10 | E12: 10 | F12: =SUM(K12:V12) -> 0 | G12: =D12-F12 -> 10
A13: =IF(B13="","",COUNTA($B$3:B13)) -> 11 | B13: កាំបិទក្រោមS,Movable Knife For Sirubar,Siruba 动刀 Sirubar | C13: តូច small​ 小 | D13: ='9-18'!G13+E13 -> 10 | E13: 10 | F13: =SUM(K13:V13) -> 0 | G13: =D13-F13 -> 10
A14: =IF(B14="","",COUNTA($B$3:B14)) -> 12 | B14: ដែកបុកកាក់ Dowel Pin,定位销 | C14: តូច small​ 小 | D14: ='9-18'!G14+E14 -> 7 | F14: =SUM(K14:V14) -> 0 | G14: =D14-F14 -> 7
A15: =IF(B15="","",COUNTA($B$3:B15)) -> 13 | B15: ផ្ទាំងបញ្ជាខៀវJ,Blue control Panel JUKI,JUKI 蓝色控制面板 | C15: តូច small​ 小 | D15: ='9-18'!G15+E15 -> 5 | F15: =SUM(K15:V15) -> 0 | G15: =D15-F15 -> 5
A16: =IF(B16="","",COUNTA($B$3:B16)) -> 14 | B16: ផ្ទាំងបញ្ជាសJ White color control Panel JUKI,JUKI 白色控制面板 | C16: តូច small​ 小 | D16: ='9-18'!G16+E16 -> 3 | F16: =SUM(K16:V16) -> 0 | G16: =D16-F16 -> 3
A17: =IF(B17="","",COUNTA($B$3:B17)) -> 15 | B17: ផ្ទាំងបញ្ជាជំនាន់ចាស់J, Old Verson Board JUKI,JUKI 旧版电路板 | C17: តូច small​ 小 | D17: ='9-18'!G17+E17 -> 3 | F17: =SUM(K17:V17) -> 0 | G17: =D17-F17 -> 3
A18: =IF(B18="","",COUNTA($B$3:B18)) -> 16 | B18: ខ្សែរទាញកាក់,CABLE ASSY, HOOD LOCK CONTROL,发动机罩锁控制拉索组件 | C18: តូច small​ 小 | D18: ='9-18'!G18+E18 -> 2 | F18: =SUM(K18:V18) -> 0 | G18: =D18-F18 -> 2
A19: =IF(B19="","",COUNTA($B$3:B19)) -> 17 | B19: ជ័រខារអំបោះ,Bobbin winder rubber ring,绕线器橡胶圈 | C19: តូច small​ 小 | D19: ='9-18'!G19+E19 -> 41 | F19: =SUM(K19:V19) -> 0 | G19: =D19-F19 -> 41
A20: =IF(B20="","",COUNTA($B$3:B20)) -> 18 | B20: កាក់ធំ,Thread Tention Assembly,张力调节组件 | C20: ធំ Big 大的 | D20: ='9-18'!G20+E20 -> 1 | F20: =SUM(K20:V20) -> 0 | G20: =D20-F20 -> 1
A21: =IF(B21="","",COUNTA($B$3:B21)) -> 19 | B21: កាក់តូច,Thread Tension Assembly Small,小型线张力组件 | C21: តូច small​ 小 | D21: ='9-18'!G21+E21 -> 19 | F21: =SUM(K21:V21) -> 0 | G21: =D21-F21 -> 19
A22: =IF(B22="","",COUNTA($B$3:B22)) -> 20 | B22: ដងម្ជុល,Needle Bar,针杆 | C22: តូច small​ 小 | D22: ='9-18'!G22+E22 -> 5 | F22: =SUM(K22:V22) -> 0 | G22: =D22-F22 -> 5
A23: =IF(B23="","",COUNTA($B$3:B23)) -> 21 | B23: ជើងទាឆុត,Teeth Presser Foot and Needle Plate Kit, 齿形压脚与针板套件 | C23: តូច small​ 小 | D23: ='9-18'!G23+E23 -> 3 | F23: =SUM(K23:V23) -> 0 | G23: =D23-F23 -> 3
A24: =IF(B24="","",COUNTA($B$3:B24)) -> 22 | B24: ដែកវាត់អំបោះ,Thread Tension Spring,线张力弹簧 | C24: តូច small​ 小 | D24: ='9-18'!G24+E24 -> 22 | F24: =SUM(K24:V24) -> 0 | G24: =D24-F24 -> 22
A25: =IF(B25="","",COUNTA($B$3:B25)) -> 23 | B25: ឈើកាវក្រោម,Upper looper, 上弯针 | C25: តូច small​ 小 | D25: ='9-18'!G25+E25 -> 10 | F25: =SUM(K25:V25) -> 0 | G25: =D25-F25 -> 10
... A27: =IF(B27="","",COUNTA($B$3:B27)) -> 25 | B27: ដងជើងទា,calcador overlock,包缝压脚 | C27: តូច small​ 小 | D27: ='9-18'!G27+E27 -> 1 | F27: =SUM(K27:V27) -> 0 | G27: =D27-F27 -> 1
A28: =IF(B28="","",COUNTA($B$3:B28)) -> 26 | B28: ធ្មេញក្រោយ,God feed Overlock Machine,差动送料包缝机 | C28: តូច small​ 小 | D28: ='9-18'!G28+E28 -> 10 | E28: 10 | F28: =SUM(K28:V28) -> 0 | G28: =D28-F28 -> 10
A29: =IF(B29="","",COUNTA($B$3:B29)) -> 27 | B29: សន្ទះធ្មេញ, Needle Plate Fit,针板适配 | C29: តូច small​ 小 | D29: ='9-18'!G29+E29 -> 9 | F29: =SUM(K29:V29) -> 0 | G29: =D29-F29 -> 9
A30: =IF(B30="","",COUNTA($B$3:B30)) -> 28 | B30: កាំបិតក្រោម,Lower Bottom Knife to Fit Overlock Machine,降低包缝机下刀位置 | C30: តូច small​ 小 | D30: ='9-18'!G30+E30 -> 4 | F30: =SUM(K30:V30) -> 0 | G30: =D30-F30 -> 4
A31: =IF(B31="","",COUNTA($B$3:B31)) -> 29 | B31: កាំបិតលើ,Top Knife for Overlock,包缝机上刀 | C31: តូច small​ 小 | D31: ='9-18'!G31+E31 -> 20 | E31: 20 | F31: =SUM(K31:V31) -> 0 | G31: =D31-F31 -> 20
A32: =IF(B32="","",COUNTA($B$3:B32)) -> 30 | B32: ដងម្ជុល,Needle Clamp Holder Fitsr,适配机针夹持器 | C32: តូច small​ 小 | D32: ='9-18'!G32+E32 -> 8 | F32: =SUM(K32:V32) -> 0 | G32: =D32-F32 -> 8
A33: =IF(B33="","",COUNTA($B$3:B33)) -> 31 | B33: ឈើកាវផ្កាដូង,Chainstitch Looper 5 Thread,五线链式缝弯针 | C33: តូច small​ 小 | D33: ='9-18'!G33+E33 -> 5 | E33: 5 | F33: =SUM(K33:V33) -> 0 | G33: =D33-F33 -> 5
A34: =IF(B34="","",COUNTA($B$3:B34)) -> 32 | B34: រុន្ធម្ជុលសាប់,Needle Hole Guide Bartack Machine, 针孔定位套结机 | C34: តូច small​ 小 | D34: ='9-18'!G34+E34 -> 7 | F34: =SUM(K34:V34) -> 0 | G34: =D34-F34 -> 7
A35: =IF(B35="","",COUNTA($B$3:B35)) -> 33 | B35: សំបុកសាប់, Shuttle Hook Fit Bartack Machine, 适用于套结机的摆梭旋梭 | C35: តូច small​ 小 | D35: ='9-18'!G35+E35 -> 10 | E35: 10 | F35: =SUM(K35:V35) -> 0 | G35: =D35-F35 -> 10
A36: =IF(B36="","",COUNTA($B$3:B36)) -> 34 | B36: ដែកបុកកាក់, Thread Tension Release Pin, 线张力释放销 | C36: តូច small​ 小 | D36: ='9-18'!G36+E36 -> 8 | F36: =SUM(K36:V36) -> 0 | G36: =D36-F36 -> 8
A37: =IF(B37="","",COUNTA($B$3:B37)) -> 35 | B37: កាំបិតក្រោមសាប់, Movable Knife Bartack Machine, 动刀式套结机 | C37: តូច small​ 小 | D37: ='9-18'!G37+E37 -> 2 | F37: =SUM(K37:V37) -> 0 | G37: =D37-F37 -> 2
A38: =IF(B38="","",COUNTA($B$3:B38)) -> 36 | B38: កាំបិតលើសាប់, Fixed Knife Bartack Machine, 固定刀片式套结机 | C38: តូច small​ 小 | D38: ='9-18'!G38+E38 -> 1 | F38: =SUM(K38:V38) -> 0 | G38: =D38-F38 -> 1
A39: =IF(B39="","",COUNTA($B$3:B39)) -> 37 | B39: ជើងទាសាប់, work clamp set bartack machine, 套结机工件夹具组 | C39: តូច small​ 小 | D39: ='9-18'!G39+E39 -> 3 | F39: =SUM(K39:V39) -> 0 | G39: =D39-F39 -> 3
A40: =IF(B40="","",COUNTA($B$3:B40)) -> 38 | B40: សំបុកម៉ាស៊ីនស្រេះ Buttonhole ​Rotary Hook 锁眼旋梭 | C40: តូច small​ 小 | D40: ='9-18'!G40+E40 -> 0 | F40: =SUM(K40:V40) -> 0 | G40: =D40-F40 -> 0
A41: =IF(B41="","",COUNTA($B$3:B41)) -> 39 | B41: ដងកាំបិតបុក, Needle Bar Buttonhole Machine, 针杆式锁眼机 | C41: តូច small​ 小 | D41: ='9-18'!G41+E41 -> 2 | F41: =SUM(K41:V41) -> 0 | G41: =D41-F41 -> 2
...

Sheet 9-21
