Workbook

Sheet SMV
A4: Berendsen SMV
A5: Nº | B5: STYLE Nº | D5: Current SMV VRT | E5: New SMV VRT | F5: OLD SMV VRT | G5: SMV RCI | H5: QC Cut Pcs (SMV Fix) | I5: Garment (SMV Fix)
A6: 1 | B6: 122 | C6: =(D6*65)/100 -> 0 | E6: =SUM(H6:I6)+D6 -> 0.97208979 | G6: 49.5 | H6: 0.252504 | I6: 0.71958579
A7: =A6+1 -> 2 | B7: 267 | C7: =(D7*65)/100 -> 0 | E7: =SUM(H7:I7)+D7 -> 0.97208979 | G7: 31.5 | H7: 0.252504 | I7: 0.71958579
A8: =A7+1 -> 3 | B8: 269 | C8: =(D8*65)/100 -> 15.51225 | D8: =G8*1.11 -> 23.865 | E8: =SUM(H8:I8)+D8 -> 24.83709 | G8: 21.5 | H8: 0.252504 | I8: 0.71958579 | N8: Time 1.11 of BSO Minute
A9: =A8+1 -> 4 | B9: 706 | C9: =(D9*65)/100 -> 0 | E9: =SUM(H9:I9)+D9 -> 0.97208979 | G9: 29 | H9: 0.252504 | I9: 0.71958579
A10: =A9+1 -> 5 | B10: 828 | C10: =(D10*65)/100 -> 0 | E10: =SUM(H10:I10)+D10 -> 0.97208979 | G10: 46 | H10: 0.252504 | I10: 0.71958579
A11: =A10+1 -> 6 | B11: 413-A | C11: =(D11*65)/100 -> 0 | E11: =SUM(H11:I11)+D11 -> 0.97208979 | G11: 21.5 | H11: 0.252504 | I11: 0.71958579
A12: =A11+1 -> 7 | B12: 515-1 | C12: =(D12*65)/100 -> 17.316 | D12: =G12*1.11 -> 26.64 | E12: =SUM(H12:I12)+D12 -> 27.61209 | G12: 24 | H12: 0.252504 | I12: 0.71958579 | N12: Time 1.11 of BSO Minute
A13: =A12+1 -> 8 | B13: H101 | C13: =(D13*65)/100 -> 0 | E13: =SUM(H13:I13)+D13 -> 0.97208979 | G13: 64 | H13: 0.252504 | I13: 0.71958579
A14: =A13+1 -> 9 | B14: H111-1 | C14: =(D14*65)/100 -> 45.81525 | D14: =G14*1.11 -> 70.485 | E14: =SUM(H14:I14)+D14 -> 71.45709 | G14: 63.5 | H14: 0.252504 | I14: 0.71958579
A15: =A14+1 -> 10 | B15: H127 | C15: =(D15*65)/100 -> 28.49925 | D15: =G15*1.11 -> 43.845 | E15: =SUM(H15:I15)+D15 -> 44.81709 | G15: 39.5 | H15: 0.252504 | I15: 0.71958579
A16: =A15+1 -> 11 | B16: H127-6 | C16: =(D16*65)/100 -> 0 | E16: =SUM(H16:I16)+D16 -> 0.97208979 | G16: 43 | H16: 0.252504 | I16: 0.71958579
A17: =A16+1 -> 12 | B17: H135 | C17: =(D17*65)/100 -> 0 | E17: =SUM(H17:I17)+D17 -> 0.97208979 | G17: 67.5 | H17: 0.252504 | I17: 0.71958579
A18: =A17+1 -> 13 | B18: H137 | C18: =(D18*65)/100 -> 0 | E18: =SUM(H18:I18)+D18 -> 0.97208979 | G18: 43.5 | H18: 0.252504 | I18: 0.71958579
A19: =A18+1 -> 14 | B19: H139 | C19: =(D19*65)/100 -> 30.66375 | D19: =G19*1.11 -> 47.175 | E19: =SUM(H19:I19)+D19 -> 48.14709 | G19: 42.5 | H19: 0.252504 | I19: 0.71958579 | N19: Time 1.11 of BSO Minute
A20: =A19+1 -> 15 | B20: H202-3 | C20: =(D20*65)/100 -> 25.61325 | D20: =G20*1.11 -> 39.405 | E20: =SUM(H20:I20)+D20 -> 40.37709 | G20: 35.5 | H20: 0.252504 | I20: 0.71958579 | N20: Time 1.11 of BSO Minute
A21: =A20+1 -> 16 | B21: H207-B | C21: =(D21*65)/100 -> 36.43575 | D21: =G21*1.11 -> 56.055 | E21: =SUM(H21:I21)+D21 -> 57.02709 | G21: 50.5 | H21: 0.252504 | I21: 0.71958579 | N21: Time 1.11 of BSO Minute
A22: =A21+1 -> 17 | B22: H208 | C22: =(D22*65)/100 -> 0 | E22: =SUM(H22:I22)+D22 -> 0.97208979 | G22: 42 | H22: 0.252504 | I22: 0.71958579
A23: =A22+1 -> 18 | B23: H208-N | C23: =(D23*65)/100 -> 31.746 | D23: =G23*1.11 -> 48.84 | E23: =SUM(H23:I23)+D23 -> 49.81209 | G23: 44 | H23: 0.252504 | I23: 0.71958579 | N23: Time 1.11 of BSO Minute
A24: =A23+1 -> 19 | B24: H209 | C24: =(D24*65)/100 -> 0 | E24: =SUM(H24:I24)+D24 -> 0.97208979 | G24: 18.5 | H24: 0.252504 | I24: 0.71958579
A25: =A24+1 -> 20 | B25: H209-4 | C25: =(D25*65)/100 -> 0 | E25: =SUM(H25:I25)+D25 -> 0.97208979 | G25: 27.5 | H25: 0.252504 | I25: 0.71958579
A26: =A25+1 -> 21 | B26: H218 | C26: =(D26*65)/100 -> 15.873 | D26: =G26*1.11 -> 24.42 | E26: =SUM(H26:I26)+D26 -> 25.39209 | G26: 22 | H26: 0.252504 | I26: 0.71958579 | N26: Time 1.11 of BSO Minute
A27: =A26+1 -> 22 | B27: H220-1 | C27: =(D27*65)/100 -> 0 | E27: =SUM(H27:I27)+D27 -> 0.97208979 | G27: 46.5 | H27: 0.252504 | I27: 0.71958579
A28: =A27+1 -> 23 | B28: H222-3 | C28: =(D28*65)/100 -> 17.316 | D28: =G28*1.11 -> 26.64 | E28: =SUM(H28:I28)+D28 -> 27.61209 | G28: 24 | H28: 0.252504 | I28: 0.71958579 | N28: Time 1.11 of BSO Minute
A29: =A28+1 -> 24 | B29: H222-4 | C29: =(D29*65)/100 -> 28.1385 | D29: =G29*1.11 -> 43.29 | E29: =SUM(H29:I29)+D29 -> 44.26209 | G29: 39 | H29: 0.252504 | I29: 0.71958579 | N29: Time 1.11 of BSO Minute
A30: =A29+1 -> 25 | B30: H222-6 | C30: =(D30*65)/100 -> 31.38525 | D30: =G30*1.11 -> 48.285 | E30: =SUM(H30:I30)+D30 -> 49.25709 | G30: 43.5 | H30: 0.252504 | I30: 0.71958579 | N30: Time 1.11 of BSO Minute
A31: =A30+1 -> 26 | B31: H223-1 | C31: =(D31*65)/100 -> 9.01875 | D31: =G31*1.11 -> 13.875 | E31: =SUM(H31:I31)+D31 -> 14.84709 | G31: 12.5 | H31: 0.252504 | I31: 0.71958579 | N31: Time 1.11 of BSO Minute
A32: =A31+1 -> 27 | B32: H224 | C32: =(D32*65)/100 -> 12.987 | D32: =G32*1.11 -> 19.98 | E32: =SUM(H32:I32)+D32 -> 20.95209 | G32: 18 | H32: 0.252504 | I32: 0.71958579 | N32: Time 1.11 of BSO Minute
A33: =A32+1 -> 28 | B33: H224-2 | C33: =(D33*65)/100 -> 17.316 | D33: =G33*1.11 -> 26.64 | E33: =SUM(H33:I33)+D33 -> 27.61209 | G33: 24 | H33: 0.252504 | I33: 0.71958579 | N33: Time 1.11 of BSO Minute
A34: =A33+1 -> 29 | B34: H225 | C34: =(D34*65)/100 -> 0 | E34: =SUM(H34:I34)+D34 -> 0.97208979 | G34: 16 | H34: 0.252504 | I34: 0.71958579
A35: =A34+1 -> 30 | B35: H225-2 | C35: =(D35*65)/100 -> 13.7085 | D35: =G35*1.11 -> 21.09 | E35: =SUM(H35:I35)+D35 -> 22.06209 | G35: 19 | H35: 0.252504 | I35: 0.71958579 | N35: Time 1.11 of BSO Minute
A36: =A35+1 -> 31 | B36: H228 | C36: =(D36*65)/100 -> 55.5555 | D36: =G36*1.11 -> 85.47 | E36: =SUM(H36:I36)+D36 -> 86.44209 | G36: 77 | H36: 0.252504 | I36: 0.71958579 | N36: Time 1.11 of BSO Minute
A37: =A36+1 -> 32 | B37: H230 | C37: =(D37*65)/100 -> 37.518 | D37: =G37*1.11 -> 57.72 | E37: =SUM(H37:I37)+D37 -> 58.69209 | G37: 52 | H37: 0.252504 | I37: 0.71958579 | N37: Time 1.11 of BSO Minute
A38: =A37+1 -> 33 | B38: H230-1 | C38: =(D38*65)/100 -> 36.7965 | D38: =G38*1.11 -> 56.61 | E38: =SUM(H38:I38)+D38 -> 57.58209 | G38: 51 | H38: 0.252504 | I38: 0.71958579 | N38: Time 1.11 of BSO Minute
A39: =A38+1 -> 34 | B39: H233 | C39: =(D39*65)/100 -> 0 | E39: =SUM(H39:I39)+D39 -> 0.97208979 | G39: 20.5 | H39: 0.252504 | I39: 0.71958579
A40: =A39+1 -> 35 | B40: H238 | C40: =(D40*65)/100 -> 36.7965 | D40: =G40*1.11 -> 56.61 | E40: =SUM(H40:I40)+D40 -> 57.58209 | G40: 51 | H40: 0.252504 | I40: 0.71958579 | N40: Time 1.11 of BSO Minute
A41: =A40+1 -> 36 | B41: H238-1 | C41: =(D41*65)/100 -> 36.7965 | D41: =G41*1.11 -> 56.61 | E41: =SUM(H41:I41)+D41 -> 57.58209 | G41: 51 | H41: 0.252504 | I41: 0.71958579 | N41: Time 1.11 of BSO Minute
A42: =A41+1 -> 37 | B42: H243-1 | C42: =(D42*65)/100 -> 12.987 | D42: =G42*1.11 -> 19.98 | E42: =SUM(H42:I42)+D42 -> 20.95209 | G42: 18 | H42: 0.252504 | I42: 0.71958579 | N42: Time 1.11 of BSO Minute
A43: =A42+1 -> 38 | B43: H250 | C43: =(D43*65)/100 -> 47.25825 | D43: =G43*1.11 -> 72.705 | E43: =SUM(H43:I43)+D43 -> 73.67709 | G43: 65.5 | H43: 0.252504 | I43: 0.71958579 | N43: Time 1.11 of BSO Minute
...

Sheet Weekly Inspection Report
A1: VANTAGE RIVER TEXTILES CO., LTD
A3: WEEKLY END-LINE INSPECTION REPORT
A4: Line# | B4: Defect Type | C4: Defect Code | D4: =D5 -> 46279 | E4: =E5 -> 46280 | F4: =F5 -> 46281 | G4: =G5 -> 46282 | H4: =H5 -> 46283 | I4: =I5 -> 46284 | J4: =J5 -> 46285 | K4: Total Defect by Type | L4: Comment
D5: 46279 | E5: =D5+1 -> 46280 | F5: =E5+1 -> 46281 | G5: =F5+1 -> 46282 | H5: =G5+1 -> 46283 | I5: =H5+1 -> 46284 | J5: =I5+1 -> 46285
A6: LINE 1 | B6: Dropped Stitch | C6: S04 | D6: 5 | E6: 1 | F6: 4 | G6: 3 | H6: 3 | I6: 3 | K6: =IF(AND(D6="",E6="",F6="",G6="",H6="",I6="",J6=""),"",SUM(D6:J6)) -> 19
B7: Shading | C7: A06 | K7: =IF(AND(D7="",E7="",F7="",G7="",H7="",I7="",J7=""),"",SUM(D7:J7))
B8: Poor trimming | C8: A09 | D8: 2 | E8: 4 | F8: 2 | G8: 3 | H8: 1 | I8: 1 | K8: =IF(AND(D8="",E8="",F8="",G8="",H8="",I8="",J8=""),"",SUM(D8:J8)) -> 13
B9: Non symtric parts | C9: A10 | F9: 1 | G9: 1 | K9: =IF(AND(D9="",E9="",F9="",G9="",H9="",I9="",J9=""),"",SUM(D9:J9)) -> 2
B10: Sweep Bowing | C10: S10 | D10: 1 | E10: 1 | G10: 1 | K10: =IF(AND(D10="",E10="",F10="",G10="",H10="",I10="",J10=""),"",SUM(D10:J10)) -> 3
B11: Skipped stitch | C11: S03 | E11: 3 | G11: 1 | H11: 2 | I11: 2 | K11: =IF(AND(D11="",E11="",F11="",G11="",H11="",I11="",J11=""),"",SUM(D11:J11)) -> 8
B12: Puckering or twisted | C12: S07 | D12: 2 | E12: 1 | F12: 1 | G12: 1 | H12: 1 | I12: 1 | K12: =IF(AND(D12="",E12="",F12="",G12="",H12="",I12="",J12=""),"",SUM(D12:J12)) -> 7
B13: Broken stitch | C13: S02 | D13: 1 | F13: 3 | I13: 2 | K13: =IF(AND(D13="",E13="",F13="",G13="",H13="",I13="",J13=""),"",SUM(D13:J13)) -> 6
B14: No Backtack | C14: S13 | D14: 1 | E14: 2 | K14: =IF(AND(D14="",E14="",F14="",G14="",H14="",I14="",J14=""),"",SUM(D14:J14)) -> 3
B15: Raw Edges | C15: S11 | K15: =IF(AND(D15="",E15="",F15="",G15="",H15="",I15="",J15=""),"",SUM(D15:J15))
B16: Incorrect stitch count | C16: A07 | K16: =IF(AND(D16="",E16="",F16="",G16="",H16="",I16="",J16=""),"",SUM(D16:J16))
B17: Incorrect seam allowance | C17: S06 | D17: 2 | K17: =IF(AND(D17="",E17="",F17="",G17="",H17="",I17="",J17=""),"",SUM(D17:J17)) -> 2
B18: Missing ops | C18: A17 | G18: 1 | H18: 2 | K18: =IF(AND(D18="",E18="",F18="",G18="",H18="",I18="",J18=""),"",SUM(D18:J18)) -> 3
B19: Wrong label | C19: L01 | K19: =IF(AND(D19="",E19="",F19="",G19="",H19="",I19="",J19=""),"",SUM(D19:J19))
B20: Head Prominent | C20: A15 | K20: =IF(AND(D20="",E20="",F20="",G20="",H20="",I20="",J20=""),"",SUM(D20:J20))
B21: Double stitches | C21: S14 | E21: 2 | K21: =IF(AND(D21="",E21="",F21="",G21="",H21="",I21="",J21=""),"",SUM(D21:J21)) -> 2
B22: Stain & Dirty from sewing | C22: A11 | D22: 2 | E22: 2 | F22: 1 | G22: 2 | H22: 3 | I22: 4 | K22: =IF(AND(D22="",E22="",F22="",G22="",H22="",I22="",J22=""),"",SUM(D22:J22)) -> 14
B23: Stain & Dirty from dyeing | C23: A11 | G23: 1 | H23: 1 | K23: =IF(AND(D23="",E23="",F23="",G23="",H23="",I23="",J23=""),"",SUM(D23:J23)) -> 2
B24: Fabric damage | C24: F01 | K24: =IF(AND(D24="",E24="",F24="",G24="",H24="",I24="",J24=""),"",SUM(D24:J24))
B25: Sewing damage | C25: F01 | K25: =IF(AND(D25="",E25="",F25="",G25="",H25="",I25="",J25=""),"",SUM(D25:J25))
C26: =IF(B26="","",VLOOKUP(B26,SMV!$B$6:$D$1037,2,FALSE)) | I26: 13 | K26: =IF(AND(D26="",E26="",F26="",G26="",H26="",I26="",J26=""),"",SUM(D26:J26)) -> 13
B27: Total Rejected | D27: =IF(AND(D6="",D7="",D8="",D9="",D19="",D20="",D21="",D22="",D23="",D24="",D25="",D26=""),"",SUM(D6:D26)) -> 16 | E27: =IF(AND(E6="",E7="",E8="",E9="",E19="",E20="",E21="",E22="",E23="",E24="",E25="",E26=""),"",SUM(E6:E26)) -> 16 | F27: =IF(AND(F6="",F7="",F8="",F9="",F19="",F20="",F21="",F22="",F23="",F24="",F25="",F26=""),"",SUM(F6:F26)) -> 12 | G27: =IF(AND(G6="",G7="",G8="",G9="",G19="",G20="",G21="",G22="",G23="",G24="",G25="",G26=""),"",SUM(G6:G26)) -> 14 | H27: =IF(AND(H6="",H7="",H8="",H9="",H19="",H20="",H21="",H22="",H23="",H24="",H25="",H26=""),"",SUM(H6:H26)) -> 13 | I27: =SUM(I6:I25) -> 13 | J27: =IF(AND(J6="",J7="",J8="",J9="",J19="",J20="",J26=""),"",SUM(J6:J26)) | K27: =SUM(D27:I27) -> 84
B28: Inspected Qty | D28: ='DAILY SUMMARY'!C2 -> 216 | E28: ='DAILY SUMMARY'!C8 -> 216 | F28: ='DAILY SUMMARY'!C14 -> 212 | G28: ='DAILY SUMMARY'!C20 -> 219 | H28: ='DAILY SUMMARY'!C26 -> 263 | I28: ='DAILY SUMMARY'!C32 -> 313 | J28: ='DAILY SUMMARY'!#REF! -> #REF! | K28: =SUM(D28:I28) -> 1439
B29: Actual Output Qty | D29: ='DAILY SUMMARY'!C3 -> 200 | E29: ='DAILY SUMMARY'!C9 -> 0 | F29: ='DAILY SUMMARY'!C15 -> 150 | G29: ='DAILY SUMMARY'!C21 -> 205 | H29: ='DAILY SUMMARY'!C27 -> 250 | I29: ='DAILY SUMMARY'!C33 -> 300 | J29: ='DAILY SUMMARY'!#REF! -> #REF! | K29: =SUM(D29:I29) -> 1105 | L29: Totals weekly semi-finish products by line = 250pcs
B30: %Total Reject | D30: ='DAILY SUMMARY'!C5 -> 0.074074074 | E30: ='DAILY SUMMARY'!C11 -> 0.074074074 | F30: ='DAILY SUMMARY'!C17 -> 0.056603774 | G30: ='DAILY SUMMARY'!C23 -> 0.063926941 | H30: ='DAILY SUMMARY'!C29 -> 0.049429658 | I30: ='DAILY SUMMARY'!C35 -> 0.041533546 | J30: ='DAILY SUMMARY'!#REF! -> #REF! | K30: =AVERAGE(D30:I30) -> 0.059940344
B31: %Efficiency | D31: ='DAILY SUMMARY'!C6 -> 0.35021552 | E31: ='DAILY SUMMARY'!C12 -> 0 | F31: ='DAILY SUMMARY'!C18 -> 0.26266164 | G31: ='DAILY SUMMARY'!C24 -> 0.38787076 | H31: ='DAILY SUMMARY'!C30 -> 0.45611979 | I31: ='DAILY SUMMARY'!C36 -> 0.54734375 | J31: ='DAILY SUMMARY'!#REF! -> #REF! | K31: =AVERAGE(D31:I31) -> 0.33403524
A32: LINE 2 | B32: Dropped Stitch | C32: S04 | D32: 3 | E32: 4 | F32: 1 | G32: 3 | H32: 1 | I32: 2 | K32: =IF(AND(D32="",E32="",F32="",G32="",H32="",I32="",J32=""),"",SUM(D32:J32)) -> 14
B33: Shading | C33: A06 | K33: =IF(AND(D33="",E33="",F33="",G33="",H33="",I33="",J33=""),"",SUM(D33:J33))
B34: Poor trimming | C34: A09 | D34: 5 | E34: 4 | F34: 6 | G34: 4 | H34: 7 | I34: 4 | K34: =IF(AND(D34="",E34="",F34="",G34="",H34="",I34="",J34=""),"",SUM(D34:J34)) -> 30
B35: Non symtric parts | C35: A10 | D35: 6 | E35: 2 | F35: 4 | G35: 4 | H35: 2 | I35: 2 | K35: =IF(AND(D35="",E35="",F35="",G35="",H35="",I35="",J35=""),"",SUM(D35:J35)) -> 20
B36: Sweep Bowing | C36: S10 | D36: 2 | E36: 1 | F36: 4 | G36: 1 | H36: 1 | I36: 5 | K36: =IF(AND(D36="",E36="",F36="",G36="",H36="",I36="",J36=""),"",SUM(D36:J36)) -> 14
B37: Skipped stitch | C37: S03 | D37: 1 | E37: 1 | F37: 2 | G37: 3 | H37: 1 | I37: 1 | K37: =IF(AND(D37="",E37="",F37="",G37="",H37="",I37="",J37=""),"",SUM(D37:J37)) -> 9
B38: Puckering or twisted | C38: S07 | E38: 4 | F38: 1 | H38: 5 | I38: 1 | K38: =IF(AND(D38="",E38="",F38="",G38="",H38="",I38="",J38=""),"",SUM(D38:J38)) -> 11
B39: Broken stitch | C39: S02 | D39: 2 | E39: 1 | F39: 1 | G39: 2 | H39: 5 | I39: 1 | K39: =IF(AND(D39="",E39="",F39="",G39="",H39="",I39="",J39=""),"",SUM(D39:J39)) -> 12
B40: No Backtack | C40: S13 | D40: 4 | E40: 1 | F40: 4 | G40: 1 | I40: 3 | K40: =IF(AND(D40="",E40="",F40="",G40="",H40="",I40="",J40=""),"",SUM(D40:J40)) -> 13
B41: Raw Edges | C41: S11 | D41: 1 | F41: 1 | G41: 1 | H41: 1 | I41: 3 | K41: =IF(AND(D41="",E41="",F41="",G41="",H41="",I41="",J41=""),"",SUM(D41:J41)) -> 7
...

Sheet Weekly Summary
B1: WEEKLY END-LINE INSPECTION SUMMARY REPORT
B3: DATE | C3: ='Weekly Inspection Report'!D5 -> 46279 | G3: ='Weekly Inspection Report'!E5 -> 46280 | K3: ='Weekly Inspection Report'!F5 -> 46281 | O3: ='Weekly Inspection Report'!G5 -> 46282 | S3: ='Weekly Inspection Report'!H5 -> 46283 | W3: ='Weekly Inspection Report'!I5 -> 46284 | AA3: Total | AE3: Average Eff (%)
B4: LINE | C4: =C3 -> 46279 | G4: =G3 -> 46280 | K4: =K3 -> 46281 | O4: =O3 -> 46282 | S4: =S3 -> 46283 | W4: =W3 -> 46284
C5: Inspected | D5: Actual Output | E5: Rejected | F5: Rejected % | G5: Inspected | H5: Actual Output | I5: Rejected | J5: Rejected % | K5: Inspected | L5: Actual Output | M5: Rejected | N5: Rejected % | O5: Inspected | P5: Actual Output | Q5: Rejected | R5: Rejected % | S5: Inspected | T5: Actual Output | U5: Rejected | V5: Rejected % | W5: Inspected | X5: Actual Output | Y5: Rejected | Z5: Rejected % | AA5: Inspected | AB5: Actual Output | AC5: Rejected | AD5: Rejected %
B6: Line 1 | C6: ='Weekly Inspection Report'!D28 -> 216 | D6: ='Weekly Inspection Report'!D29 -> 200 | E6: ='Weekly Inspection Report'!D27 -> 16 | F6: ='Weekly Inspection Report'!D30 -> 0.074074074 | G6: ='Weekly Inspection Report'!E28 -> 216 | H6: ='Weekly Inspection Report'!E29 -> 0 | I6: ='Weekly Inspection Report'!E27 -> 16 | J6: ='Weekly Inspection Report'!E30 -> 0.074074074 | K6: ='Weekly Inspection Report'!F28 -> 212 | L6: ='Weekly Inspection Report'!F29 -> 150 | M6: ='Weekly Inspection Report'!F27 -> 12 | N6: ='Weekly Inspection Report'!F30 -> 0.056603774 | O6: ='Weekly Inspection Report'!G28 -> 219 | P6: ='Weekly Inspection Report'!G29 -> 205 | Q6: ='Weekly Inspection Report'!G27 -> 14 | R6: ='Weekly Inspection Report'!G30 -> 0.063926941 | S6: ='Weekly Inspection Report'!H28 -> 263 | T6: ='Weekly Inspection Report'!H29 -> 250 | U6: ='Weekly Inspection Report'!H27 -> 13 | V6: ='Weekly Inspection Report'!H30 -> 0.049429658 | W6: ='Weekly Inspection Report'!I28 -> 313 | X6: ='Weekly Inspection Report'!I29 -> 300 | Y6: ='Weekly Inspection Report'!I27 -> 13 | Z6: ='Weekly Inspection Report'!I30 -> 0.041533546 | AA6: =SUM(C6,G6,K6,O6,S6,W6) -> 1439 | AB6: =SUM(D6,H6,L6,P6,T6,X6) -> 1105 | AC6: =SUM(E6,I6,M6,Q6,U6,Y6) -> 84 | AD6: =AVERAGE(F6,J6,N6,R6,V6,Z6) -> 0.059940344 | AE6: ='Weekly Inspection Report'!K31 -> 0.33403524
B7: Line 2 | C7: ='Weekly Inspection Report'!D54 -> 677 | D7: ='Weekly Inspection Report'!D55 -> 642 | E7: ='Weekly Inspection Report'!D53 -> 35 | F7: ='Weekly Inspection Report'!D56 -> 0.051698671 | G7: ='Weekly Inspection Report'!E54 -> 495 | H7: ='Weekly Inspection Report'!E55 -> 468 | I7: ='Weekly Inspection Report'!E53 -> 27 | J7: ='Weekly Inspection Report'!E56 -> 0.054545455 | K7: ='Weekly Inspection Report'!F54 -> 767 | L7: ='Weekly Inspection Report'!F55 -> 732 | M7: ='Weekly Inspection Report'!F53 -> 35 | N7: ='Weekly Inspection Report'!F56 -> 0.045632334 | O7: ='Weekly Inspection Report'!G54 -> 649 | P7: ='Weekly Inspection Report'!G55 -> 624 | Q7: ='Weekly Inspection Report'!G53 -> 25 | R7: ='Weekly Inspection Report'!G56 -> 0.038520801 | S7: ='Weekly Inspection Report'!H54 -> 681 | T7: ='Weekly Inspection Report'!H55 -> 648 | U7: ='Weekly Inspection Report'!H53 -> 33 | V7: ='Weekly Inspection Report'!H56 -> 0.04845815 | W7: ='Weekly Inspection Report'!I54 -> 711 | X7: ='Weekly Inspection Report'!I55 -> 678 | Y7: ='Weekly Inspection Report'!I53 -> 33 | Z7: ='Weekly Inspection Report'!I56 -> 0.046413502 | AA7: =SUM(C7,G7,K7,O7,S7,W7) -> 3980 | AB7: =SUM(D7,H7,L7,P7,T7,X7) -> 3792 | AC7: =SUM(E7,I7,M7,Q7,U7,Y7) -> 188 | AD7: =AVERAGE(F7,J7,N7,R7,V7,Z7) -> 0.047544819 | AE7: ='Weekly Inspection Report'!K57 -> 0.3502676
B8: Line 3 | C8: ='Weekly Inspection Report'!D80 -> 372 | D8: ='Weekly Inspection Report'!D81 -> 350 | E8: ='Weekly Inspection Report'!D79 -> 22 | F8: ='Weekly Inspection Report'!D82 -> 0.059139785 | G8: ='Weekly Inspection Report'!E80 -> 372 | H8: ='Weekly Inspection Report'!E81 -> 350 | I8: ='Weekly Inspection Report'!E79 -> 22 | J8: ='Weekly Inspection Report'!E82 -> 0.059139785 | K8: ='Weekly Inspection Report'!F80 -> 372 | L8: ='Weekly Inspection Report'!F81 -> 350 | M8: ='Weekly Inspection Report'!F79 -> 22 | N8: ='Weekly Inspection Report'!F82 -> 0.059139785 | O8: ='Weekly Inspection Report'!G80 -> 425 | P8: ='Weekly Inspection Report'!G81 -> 404 | Q8: ='Weekly Inspection Report'!G79 -> 21 | R8: ='Weekly Inspection Report'!G82 -> 0.049411765 | S8: ='Weekly Inspection Report'!H80 -> 344 | T8: ='Weekly Inspection Report'!H81 -> 325 | U8: ='Weekly Inspection Report'!H79 -> 19 | V8: ='Weekly Inspection Report'!H82 -> 0.055232558 | W8: ='Weekly Inspection Report'!I80 -> 343 | X8: ='Weekly Inspection Report'!I81 -> 325 | Y8: ='Weekly Inspection Report'!I79 -> 18 | Z8: ='Weekly Inspection Report'!I82 -> 0.052478134 | AA8: =SUM(C8,G8,K8,O8,S8,W8) -> 2228 | AB8: =SUM(D8,H8,L8,P8,T8,X8) -> 2104 | AC8: =SUM(E8,I8,M8,Q8,U8,Y8) -> 124 | AD8: =AVERAGE(F8,J8,N8,R8,V8,Z8) -> 0.055756969 | AE8: ='Weekly Inspection Report'!K83 -> 0.41946376
B9: Line 4 | C9: ='Weekly Inspection Report'!D106 -> 267 | D9: ='Weekly Inspection Report'!D107 -> 252 | E9: ='Weekly Inspection Report'!D105 -> 15 | F9: ='Weekly Inspection Report'!D108 -> 0.056179775 | G9: ='Weekly Inspection Report'!E106 -> 143 | H9: ='Weekly Inspection Report'!E107 -> 132 | I9: ='Weekly Inspection Report'!E105 -> 11 | J9: ='Weekly Inspection Report'!E108 -> 0.076923077 | K9: ='Weekly Inspection Report'!F106 -> 258 | L9: ='Weekly Inspection Report'!F107 -> 240 | M9: ='Weekly Inspection Report'!F105 -> 18 | N9: ='Weekly Inspection Report'!F108 -> 0.069767442 | O9: ='Weekly Inspection Report'!G106 -> 283 | P9: ='Weekly Inspection Report'!G107 -> 264 | Q9: ='Weekly Inspection Report'!G105 -> 19 | R9: ='Weekly Inspection Report'!G108 -> 0.067137809 | S9: ='Weekly Inspection Report'!H106 -> 268 | T9: ='Weekly Inspection Report'!H107 -> 252 | U9: ='Weekly Inspection Report'!H105 -> 16 | V9: ='Weekly Inspection Report'!H108 -> 0.059701493 | W9: ='Weekly Inspection Report'!I106 -> 508 | X9: ='Weekly Inspection Report'!I107 -> 480 | Y9: ='Weekly Inspection Report'!I105 -> 28 | Z9: ='Weekly Inspection Report'!I108 -> 0.05511811 | AA9: =SUM(C9,G9,K9,O9,S9,W9) -> 1727 | AB9: =SUM(D9,H9,L9,P9,T9,X9) -> 1620 | AC9: =SUM(E9,I9,M9,Q9,U9,Y9) -> 107 | AD9: =AVERAGE(F9,J9,N9,R9,V9,Z9) -> 0.064137951 | AE9: ='Weekly Inspection Report'!K109 -> 0.21747179
B10: Line 5 | C10: ='Weekly Inspection Report'!D132 -> 1002 | D10: ='Weekly Inspection Report'!D133 -> 936 | E10: ='Weekly Inspection Report'!D131 -> 66 | F10: ='Weekly Inspection Report'!D134 -> 0.065868263 | G10: ='Weekly Inspection Report'!E132 -> 884 | H10: ='Weekly Inspection Report'!E133 -> 864 | I10: ='Weekly Inspection Report'!E131 -> 20 | J10: ='Weekly Inspection Report'!E134 -> 0.022624434 | K10: ='Weekly Inspection Report'!F132 -> 882 | L10: ='Weekly Inspection Report'!F133 -> 864 | M10: ='Weekly Inspection Report'!F131 -> 18 | N10: ='Weekly Inspection Report'!F134 -> 0.020408163 | O10: ='Weekly Inspection Report'!G132 -> 879 | P10: ='Weekly Inspection Report'!G133 -> 864 | Q10: ='Weekly Inspection Report'!G131 -> 15 | R10: ='Weekly Inspection Report'!G134 -> 0.017064846 | S10: ='Weekly Inspection Report'!H132 -> 820 | T10: ='Weekly Inspection Report'!H133 -> 792 | U10: ='Weekly Inspection Report'!H131 -> 28 | V10: ='Weekly Inspection Report'!H134 -> 0.034146341 | W10: ='Weekly Inspection Report'!I132 -> 744 | X10: ='Weekly Inspection Report'!I133 -> 720 | Y10: ='Weekly Inspection Report'!I131 -> 24 | Z10: ='Weekly Inspection Report'!I134 -> 0.032258065 | AA10: =SUM(C10,G10,K10,O10,S10,W10) -> 5211 | AB10: =SUM(D10,H10,L10,P10,T10,X10) -> 5040 | AC10: =SUM(E10,I10,M10,Q10,U10,Y10) -> 171 | AD10: =AVERAGE(F10,J10,N10,R10,V10,Z10) -> 0.032061686 | AE10: ='Weekly Inspection Report'!K135 -> 0.41344302
B11: Line 6 | C11: ='Weekly Inspection Report'!D158 -> 346 | D11: ='Weekly Inspection Report'!D159 -> 324 | E11: ='Weekly Inspection Report'!D157 -> 22 | F11: ='Weekly Inspection Report'!D160 -> 0.063583815 | G11: ='Weekly Inspection Report'!E158 -> 114 | H11: ='Weekly Inspection Report'!E159 -> 108 | I11: ='Weekly Inspection Report'!E157 -> 6 | J11: ='Weekly Inspection Report'!E160 -> 0.052631579 | K11: ='Weekly Inspection Report'!F158 -> 90 | L11: ='Weekly Inspection Report'!F159 -> 84 | M11: ='Weekly Inspection Report'!F157 -> 6 | N11: ='Weekly Inspection Report'!F160 -> 0.066666667 | O11: ='Weekly Inspection Report'!G158 -> 104 | P11: ='Weekly Inspection Report'!G159 -> 96 | Q11: ='Weekly Inspection Report'!G157 -> 8 | R11: ='Weekly Inspection Report'!G160 -> 0.076923077 | S11: ='Weekly Inspection Report'!H158 -> 104 | T11: ='Weekly Inspection Report'!H159 -> 96 | U11: ='Weekly Inspection Report'!H157 -> 8 | V11: ='Weekly Inspection Report'!H160 -> 0.076923077 | W11: ='Weekly Inspection Report'!I158 -> 117 | X11: ='Weekly Inspection Report'!I159 -> 108 | Y11: ='Weekly Inspection Report'!I157 -> 9 | Z11: ='Weekly Inspection Report'!I160 -> 0.076923077 | AA11: =SUM(C11,G11,K11,O11,S11,W11) -> 875 | AB11: =SUM(D11,H11,L11,P11,T11,X11) -> 816 | AC11: =SUM(E11,I11,M11,Q11,U11,Y11) -> 59 | AD11: =AVERAGE(F11,J11,N11,R11,V11,Z11) -> 0.068941882 | AE11: ='Weekly Inspection Report'!K161 -> 0.15645774
B12: Line 7 | C12: ='Weekly Inspection Report'!D184 -> 0 | D12: ='Weekly Inspection Report'!D185 -> 0 | E12: ='Weekly Inspection Report'!D183 | F12: ='Weekly Inspection Report'!D186 -> 0 | G12: ='Weekly Inspection Report'!E184 -> 51 | H12: ='Weekly Inspection Report'!E185 -> 48 | I12: ='Weekly Inspection Report'!E183 -> 3 | J12: ='Weekly Inspection Report'!E186 -> 0.058823529 | K12: ='Weekly Inspection Report'!F184 -> 89 | L12: ='Weekly Inspection Report'!F185 -> 84 | M12: ='Weekly Inspection Report'!F183 -> 5 | N12: ='Weekly Inspection Report'!F186 -> 0.056179775 | O12: ='Weekly Inspection Report'!G184 -> 138 | P12: ='Weekly Inspection Report'!G185 -> 132 | Q12: ='Weekly Inspection Report'!G183 -> 6 | R12: ='Weekly Inspection Report'!G186 -> 0.043478261 | S12: ='Weekly Inspection Report'!H184 -> 212 | T12: ='Weekly Inspection Report'!H185 -> 204 | U12: ='Weekly Inspection Report'!H183 -> 8 | V12: ='Weekly Inspection Report'!H186 -> 0.037735849 | W12: ='Weekly Inspection Report'!I184 -> 113 | X12: ='Weekly Inspection Report'!I185 -> 108 | Y12: ='Weekly Inspection Report'!I183 -> 5 | Z12: ='Weekly Inspection Report'!I186 -> 0.044247788 | AA12: =SUM(C12,G12,K12,O12,S12,W12) -> 603 | AB12: =SUM(D12,H12,L12,P12,T12,X12) -> 576 | AC12: =SUM(E12,I12,M12,Q12,U12,Y12) -> 27 | AD12: =AVERAGE(F12,J12,N12,R12,V12,Z12) -> 0.040077534 | AE12: ='Weekly Inspection Report'!K187 -> 0.15987813
B13: Line 8 | C13: ='Weekly Inspection Report'!D210 -> 542 | D13: ='Weekly Inspection Report'!D211 -> 400 | E13: ='Weekly Inspection Report'!D209 -> 22 | F13: ='Weekly Inspection Report'!D212 -> 0.040590406 | G13: ='Weekly Inspection Report'!E210 -> 472 | H13: ='Weekly Inspection Report'!E211 -> 180 | I13: ='Weekly Inspection Report'!E209 -> 22 | J13: ='Weekly Inspection Report'!E212 -> 0.046610169 | K13: ='Weekly Inspection Report'!F210 -> 467 | L13: ='Weekly Inspection Report'!F211 -> 240 | M13: ='Weekly Inspection Report'!F209 -> 27 | N13: ='Weekly Inspection Report'!F212 -> 0.057815846 | O13: ='Weekly Inspection Report'!G210 -> 347 | P13: ='Weekly Inspection Report'!G211 -> 325 | Q13: ='Weekly Inspection Report'!G209 -> 22 | R13: ='Weekly Inspection Report'!G212 -> 0.063400576 | S13: ='Weekly Inspection Report'!H210 -> 472 | T13: ='Weekly Inspection Report'!H211 -> 440 | U13: ='Weekly Inspection Report'!H209 -> 32 | V13: ='Weekly Inspection Report'!H212 -> 0.06779661 | W13: ='Weekly Inspection Report'!I210 -> 450 | X13: ='Weekly Inspection Report'!I211 -> 425 | Y13: ='Weekly Inspection Report'!I209 -> 25 | Z13: ='Weekly Inspection Report'!I212 -> 0.055555556 | AA13: =SUM(C13,G13,K13,O13,S13,W13) -> 2750 | AB13: =SUM(D13,H13,L13,P13,T13,X13) -> 2010 | AC13: =SUM(E13,I13,M13,Q13,U13,Y13) -> 150 | AD13: =AVERAGE(F13,J13,N13,R13,V13,Z13) -> 0.055294861 | AE13: ='Weekly Inspection Report'!K213 -> 0.43220456
B14: Line 9 | C14: ='Weekly Inspection Report'!D236 -> 571 | D14: ='Weekly Inspection Report'!D237 -> 546 | E14: ='Weekly Inspection Report'!D235 -> 25 | F14: ='Weekly Inspection Report'!D238 -> 0.043782837 | G14: ='Weekly Inspection Report'!E236 -> 575 | H14: ='Weekly Inspection Report'!E237 -> 552 | I14: ='Weekly Inspection Report'!E235 -> 23 | J14: ='Weekly Inspection Report'!E238 -> 0.04 | K14: ='Weekly Inspection Report'!F236 -> 573 | L14: ='Weekly Inspection Report'!F237 -> 552 | M14: ='Weekly Inspection Report'!F235 -> 21 | N14: ='Weekly Inspection Report'!F238 -> 0.036649215 | O14: ='Weekly Inspection Report'!G236 -> 576 | P14: ='Weekly Inspection Report'!G237 -> 552 | Q14: ='Weekly Inspection Report'!G235 -> 24 | R14: ='Weekly Inspection Report'!G238 -> 0.041666667 | S14: ='Weekly Inspection Report'!H236 -> 576 | T14: ='Weekly Inspection Report'!H237 -> 552 | U14: ='Weekly Inspection Report'!H235 -> 24 | V14: ='Weekly Inspection Report'!H238 -> 0.041666667 | W14: ='Weekly Inspection Report'!I236 -> 647 | X14: ='Weekly Inspection Report'!I237 -> 625 | Y14: ='Weekly Inspection Report'!I235 -> 22 | Z14: ='Weekly Inspection Report'!I238 -> 0.034003091 | AA14: =SUM(C14,G14,K14,O14,S14,W14) -> 3518 | AB14: =SUM(D14,H14,L14,P14,T14,X14) -> 3379 | AC14: =SUM(E14,I14,M14,Q14,U14,Y14) -> 139 | AD14: =AVERAGE(F14,J14,N14,R14,V14,Z14) -> 0.039628079 | AE14: ='Weekly Inspection Report'!K239 -> 0.34114676
B15: Line 10 | C15: ='Weekly Inspection Report'!D262 -> 510 | D15: ='Weekly Inspection Report'!D263 -> 492 | E15: ='Weekly Inspection Report'!D261 -> 18 | F15: ='Weekly Inspection Report'!D264 -> 0.035294118 | G15: ='Weekly Inspection Report'!E262 -> 526 | H15: ='Weekly Inspection Report'!E263 -> 504 | I15: ='Weekly Inspection Report'!E261 -> 22 | J15: ='Weekly Inspection Report'!E264 -> 0.041825095 | K15: ='Weekly Inspection Report'!F262 -> 770 | L15: ='Weekly Inspection Report'!F263 -> 740 | M15: ='Weekly Inspection Report'!F261 -> 30 | N15: ='Weekly Inspection Report'!F264 -> 0.038961039 | O15: ='Weekly Inspection Report'!G262 -> 566 | P15: ='Weekly Inspection Report'!G263 -> 540 | Q15: ='Weekly Inspection Report'!G261 -> 26 | R15: ='Weekly Inspection Report'!G264 -> 0.045936396 | S15: ='Weekly Inspection Report'!H262 -> 849 | T15: ='Weekly Inspection Report'!H263 -> 820 | U15: ='Weekly Inspection Report'!H261 -> 29 | V15: ='Weekly Inspection Report'!H264 -> 0.034157833 | W15: ='Weekly Inspection Report'!I262 -> 995 | X15: ='Weekly Inspection Report'!I263 -> 960 | Y15: ='Weekly Inspection Report'!I261 -> 35 | Z15: ='Weekly Inspection Report'!I264 -> 0.035175879 | AA15: =SUM(C15,G15,K15,O15,S15,W15) -> 4216 | AB15: =SUM(D15,H15,L15,P15,T15,X15) -> 4056 | AC15: =SUM(E15,I15,M15,Q15,U15,Y15) -> 160 | AD15: =AVERAGE(F15,J15,N15,R15,V15,Z15) -> 0.038558393 | AE15: ='Weekly Inspection Report'!K265 -> 0.19017179
B16: Line 11 | C16: ='Weekly Inspection Report'!D288 -> 0 | D16: ='Weekly Inspection Report'!D289 -> 0 | E16: ='Weekly Inspection Report'!D287 | F16: ='Weekly Inspection Report'!D290 -> 0 | G16: ='Weekly Inspection Report'!E288 -> 0 | H16: ='Weekly Inspection Report'!E289 -> 0 | I16: ='Weekly Inspection Report'!E287 | J16: ='Weekly Inspection Report'!E290 -> 0 | K16: ='Weekly Inspection Report'!F288 -> 685 | L16: ='Weekly Inspection Report'!F289 -> 659 | M16: ='Weekly Inspection Report'!F287 -> 26 | N16: ='Weekly Inspection Report'!F290 -> 0.037956204 | O16: ='Weekly Inspection Report'!G288 -> 522 | P16: ='Weekly Inspection Report'!G289 -> 503 | Q16: ='Weekly Inspection Report'!G287 -> 19 | R16: ='Weekly Inspection Report'!G290 -> 0.036398467 | S16: ='Weekly Inspection Report'!H288 -> 597 | T16: ='Weekly Inspection Report'!H289 -> 568 | U16: ='Weekly Inspection Report'!H287 -> 29 | V16: ='Weekly Inspection Report'!H290 -> 0.048576214 | W16: ='Weekly Inspection Report'!I288 -> 465 | X16: ='Weekly Inspection Report'!I289 -> 436 | Y16: ='Weekly Inspection Report'!I287 -> 29 | Z16: ='Weekly Inspection Report'!I290 -> 0.062365591 | AA16: =SUM(C16,G16,K16,O16,S16,W16) -> 2269 | AB16: =SUM(D16,H16,L16,P16,T16,X16) -> 2166 | AC16: =SUM(E16,I16,M16,Q16,U16,Y16) -> 103 | AD16: =AVERAGE(F16,J16,N16,R16,V16,Z16) -> 0.030882746 | AE16: ='Weekly Inspection Report'!K291 -> 0.23649271
B17: Line 12
B18: Line 13
B19: Line 14
B20: Line 15
B21: Line 16
B22: Line 17
B23: Line 18
B24: Line 19 | AE24: ='Weekly Inspection Report'!K241
B25: Line 12 | C25: ='Weekly Inspection Report'!D314 -> 0 | D25: ='Weekly Inspection Report'!D315 -> 0 | E25: ='Weekly Inspection Report'!D313 | F25: ='Weekly Inspection Report'!D316 -> 0 | G25: ='Weekly Inspection Report'!E314 -> 0 | H25: ='Weekly Inspection Report'!E315 -> 0 | I25: ='Weekly Inspection Report'!E313 | J25: ='Weekly Inspection Report'!E316 -> 0 | K25: ='Weekly Inspection Report'!F314 -> 0 | L25: ='Weekly Inspection Report'!F315 -> 0 | M25: ='Weekly Inspection Report'!F313 -> 0 | N25: ='Weekly Inspection Report'!F316 -> 0 | O25: ='Weekly Inspection Report'!G314 -> 0 | P25: ='Weekly Inspection Report'!G315 -> 0 | Q25: ='Weekly Inspection Report'!G313 | R25: ='Weekly Inspection Report'!G316 -> 0 | S25: ='Weekly Inspection Report'!H314 -> 0 | T25: ='Weekly Inspection Report'!H315 -> 0 | U25: ='Weekly Inspection Report'!H313 | V25: ='Weekly Inspection Report'!H316 -> 0 | W25: ='Weekly Inspection Report'!I314 -> 0 | X25: ='Weekly Inspection Report'!I315 -> 0 | Y25: ='Weekly Inspection Report'!I313 | Z25: ='Weekly Inspection Report'!I316 -> 0 | AA25: =SUM(C25,G25,K25,O25,S25,W25) -> 0 | AB25: =SUM(D25,H25,L25,P25,T25,X25) -> 0 | AC25: =SUM(E25,I25,M25,Q25,U25,Y25) -> 0 | AD25: =SUM(F25,J25,N25,R25,V25,Z25) -> 0 | AE25: ='Weekly Inspection Report'!K316 -> 0
B26: SAMPLE LINE | C26: ='Weekly Inspection Report'!D340 -> 0 | D26: ='Weekly Inspection Report'!D341 -> 0 | E26: ='Weekly Inspection Report'!D339 -> 0 | F26: ='Weekly Inspection Report'!D342 -> 0 | G26: ='Weekly Inspection Report'!E340 -> 0 | H26: ='Weekly Inspection Report'!E341 -> 0 | I26: ='Weekly Inspection Report'!E339 -> 0 | J26: ='Weekly Inspection Report'!E342 -> 0 | K26: ='Weekly Inspection Report'!F340 -> 0 | L26: ='Weekly Inspection Report'!F341 -> 0 | M26: ='Weekly Inspection Report'!F339 -> 0 | N26: ='Weekly Inspection Report'!F342 -> 0 | O26: ='Weekly Inspection Report'!G340 -> 0 | P26: ='Weekly Inspection Report'!G341 -> 0 | Q26: ='Weekly Inspection Report'!G339 -> 0 | R26: ='Weekly Inspection Report'!G342 -> 0 | S26: ='Weekly Inspection Report'!H340 -> 0 | T26: ='Weekly Inspection Report'!H341 -> 0 | U26: ='Weekly Inspection Report'!H339 -> 0 | V26: ='Weekly Inspection Report'!H342 -> 0 | W26: ='Weekly Inspection Report'!I340 -> 0 | X26: ='Weekly Inspection Report'!I341 -> 0 | Y26: ='Weekly Inspection Report'!I339 -> 0 | Z26: ='Weekly Inspection Report'!I342 -> 0 | AA26: =SUM(C26,G26,K26,O26,S26,W26) -> 0 | AB26: =SUM(D26,H26,L26,P26,T26,X26) -> 0 | AC26: =SUM(E26,I26,M26,Q26,U26,Y26) -> 0 | AD26: ='Weekly Inspection Report'!K342 -> 0 | AE26: ='Weekly Inspection Report'!K343 -> 0
B27: Total | C27: =IF(AND(C6="",C7="",C8="",C9="",C10="",C11="",C12="",C13="",C14),"",SUM(C6:C26)) -> 4503 | D27: =IF(AND(D6="",D7="",D8="",D9="",D10="",D11="",D12="",D13="",D14),"",SUM(D6:D26)) -> 4142 | E27: =IF(AND(E6="",E7="",E8="",E9="",E10="",E11="",E12="",E13="",E14),"",SUM(E6:E26)) -> 241 | F27: =AVERAGE(F6:F26) -> 0.037708596 | G27: =IF(AND(G6="",G7="",G8="",G9="",G10="",G11="",G12="",G13="",G14),"",SUM(G6:G26)) -> 3848 | H27: =IF(AND(H6="",H7="",H8="",H9="",H10="",H11="",H12="",H13="",H14),"",SUM(H6:H26)) -> 3206 | I27: =IF(AND(I6="",I7="",I8="",I9="",I10="",I11="",I12="",I13="",I14),"",SUM(I6:I26)) -> 172 | J27: =AVERAGE(J6:J26) -> 0.040553631 | K27: =IF(AND(K6="",K7="",K8="",K9="",K10="",K11="",K12="",K13="",K14),"",SUM(K6:K26)) -> 5165 | L27: =IF(AND(L6="",L7="",L8="",L9="",L10="",L11="",L12="",L13="",L14),"",SUM(L6:L26)) -> 4695 | M27: =IF(AND(M6="",M7="",M8="",M9="",M10="",M11="",M12="",M13="",M14),"",SUM(M6:M26)) -> 220 | N27: =AVERAGE(N6:N25) -> 0.045481687 | O27: =IF(AND(O6="",O7="",O8="",O9="",O10="",O11="",O12="",O13="",O14),"",SUM(O6:O26)) -> 4708 | P27: =IF(AND(P6="",P7="",P8="",P9="",P10="",P11="",P12="",P13="",P14),"",SUM(P6:P26)) -> 4509 | Q27: =IF(AND(Q6="",Q7="",Q8="",Q9="",Q10="",Q11="",Q12="",Q13="",Q14),"",SUM(Q6:Q26)) -> 199 | R27: =AVERAGE(R6:R26) -> 0.041835816 | S27: =IF(AND(S6="",S7="",S8="",S9="",S10="",S11="",S12="",S13="",S14),"",SUM(S6:S26)) -> 5186 | T27: =IF(AND(T6="",T7="",T8="",T9="",T10="",T11="",T12="",T13="",T14),"",SUM(T6:T26)) -> 4947 | U27: =IF(AND(U6="",U7="",U8="",U9="",U10="",U11="",U12="",U13="",U14),"",SUM(U6:U26)) -> 239 | V27: =AVERAGE(V6:V26) -> 0.042601881 | W27: =IF(AND(W6="",W7="",W8="",W9="",W10="",W11="",W12="",W13="",W14),"",SUM(W6:W26)) -> 5406 | X27: =IF(AND(X6="",X7="",X8="",X9="",X10="",X11="",X12="",X13="",X14),"",SUM(X6:X26)) -> 5165 | Y27: =IF(AND(Y6="",Y7="",Y8="",Y9="",Y10="",Y11="",Y12="",Y13="",Y14),"",SUM(Y6:Y26)) -> 241 | Z27: =AVERAGE(Z6:Z25) -> 0.044672695 | AA27: =SUM(AA6:AA26) -> 28816 | AB27: =SUM(AB6:AB26) -> 26664 | AC27: =SUM(AC6:AC26) -> 1312 | AD27: =AVERAGE(AD6:AD26) -> 0.040986559 | AE27: =AVERAGE(AE6:AE26) -> 0.25007947

Sheet DAILY SUMMARY
A1: Monday | B1: LINE# | C1: A1 | D1: A2 | E1: A3 | F1: A4 | G1: A5 | H1: A6 | I1: A7 | J1: A8 | K1: A9 | L1: A10 | M1: A11 | N1: A12 | O1: SAMPLE LINE | P1: Total
B2: Inspect Qty | C2: 216 | D2: 677 | E2: 372 | F2: 267 | G2: 1002 | H2: 346 | I2: 0 | J2: 542 | K2: 571 | L2: 510 | M2: 0 | N2: 0 | O2: 0 | P2: 4503
B3: Actual Output Qty | C3: 200 | D3: 642 | E3: 350 | F3: 252 | G3: 936 | H3: 324 | I3: 0 | J3: 400 | K3: 546 | L3: 492 | M3: 0 | N3: 0 | O3: 0 | P3: 4142
B4: Reject Qty | C4: 16 | D4: 35 | E4: 22 | F4: 15 | G4: 66 | H4: 22 | I4: 0 | J4: 22 | K4: 25 | L4: 18 | M4: 0 | N4: 0 | O4: 0 | P4: 241
B5: %Total Reject | C5: 0.074074074 | D5: 0.051698671 | E5: 0.059139785 | F5: 0.056179775 | G5: 0.065868263 | H5: 0.063583815 | I5: 0 | J5: 0.040590406 | K5: 0.043782837 | L5: 0.035294118 | M5: 0 | N5: 0 | O5: 0 | P5: 0.037708596
B6: %Effeceincy | C6: 0.35021552 | D6: 0.32601562 | E6: 0.44762731 | F6: 0.252525 | G6: 0.375 | H6: 0.14428125 | I6: 0 | J6: 0.34717857 | K6: 0.28750201 | L6: 0.20466429 | M6: 0 | N6: 0 | O6: 0 | P6: 0.24863723
A7: Tueday | B7: LINE# | C7: A1 | D7: A2 | E7: A3 | F7: A4 | G7: A5 | H7: A6 | I7: A7 | J7: A8 | K7: A9 | L7: A10 | M7: A11 | N7: A12 | O7: SAMPLE LINE | P7: Total
B8: Inspect Qty | C8: 216 | D8: 495 | E8: 372 | F8: 143 | G8: 884 | H8: 114 | I8: 51 | J8: 472 | K8: 575 | L8: 526 | M8: 0 | N8: 0 | O8: 0 | P8: 3848
B9: Actual Output Qty | C9: 0 | D9: 468 | E9: 350 | F9: 132 | G9: 864 | H9: 108 | I9: 48 | J9: 180 | K9: 552 | L9: 504 | M9: 0 | N9: 0 | O9: 0 | P9: 3206
B10: Reject Qty | C10: 16 | D10: 27 | E10: 22 | F10: 11 | G10: 20 | H10: 6 | I10: 3 | J10: 22 | K10: 23 | L10: 22 | M10: 0 | N10: 0 | O10: 0 | P10: 172
B11: %Total Reject | C11: 0.074074074 | D11: 0.054545455 | E11: 0.059139785 | F11: 0.076923077 | G11: 0.022624434 | H11: 0.052631579 | I11: 0.058823529 | J11: 0.046610169 | K11: 0.04 | L11: 0.041825095 | M11: 0 | N11: 0 | O11: 0 | P11: 0.040553631
B12: %Effeceincy | C12: 0 | D12: 0.23765625 | E12: 0.43948864 | F12: 0.1112775 | G12: 0.32680556 | H12: 0.0463125 | I12: 0.092857143 | J12: 0.103175 | K12: 0.27535685 | L12: 0.20121983 | M12: 0 | N12: 0 | O12: 0 | P12: 0.16674084
A13: wednday | B13: LINE# | C13: A1 | D13: A2 | E13: A3 | F13: A4 | G13: A5 | H13: A6 | I13: A7 | J13: A8 | K13: A9 | L13: A10 | M13: A11 | N13: A21 | O13: SAMPLE LINE | P13: Total
B14: Inspect Qty | C14: 212 | D14: 767 | E14: 372 | F14: 258 | G14: 882 | H14: 90 | I14: 89 | J14: 467 | K14: 573 | L14: 770 | M14: 685 | N14: 0 | O14: 0 | P14: 5165
B15: Actual Output Qty | C15: 150 | D15: 732 | E15: 350 | F15: 240 | G15: 864 | H15: 84 | I15: 84 | J15: 240 | K15: 552 | L15: 740 | M15: 659 | N15: 0 | O15: 0 | P15: 4695
B16: Reject Qty | C16: 12 | D16: 35 | E16: 22 | F16: 18 | G16: 18 | H16: 6 | I16: 5 | J16: 27 | K16: 21 | L16: 30 | M16: 26 | N16: 0 | O16: 0 | P16: 220
B17: %Total Reject | C17: 0.056603774 | D17: 0.045632334 | E17: 0.059139785 | F17: 0.069767442 | G17: 0.020408163 | H17: 0.066666667 | I17: 0.056179775 | J17: 0.057815846 | K17: 0.036649215 | L17: 0.038961039 | M17: 0.037956204 | N17: 0 | O17: 0 | P17: 0.041983096
B18: %Effeceincy | C18: 0.26266164 | D18: 0.33872845 | E18: 0.43164062 | F18: 0.18438333 | G18: 0.36058394 | H18: 0.175 | I18: 0.1625 | J18: 0.13756667 | K18: 0.27535685 | L18: 0.15254226 | M18: 0.33188646 | N18: 0 | O18: 0 | P18: 0.25571366
A19: Thursday | B19: LINE# | C19: A1 | D19: A2 | E19: A3 | F19: A4 | G19: A5 | H19: A6 | I19: A7 | J19: A8 | K19: A9 | L19: A10 | M19: A11 | N19: A12 | O19: SAMPLE LINE | P19: Total
B20: Inspect Qty | C20: 219 | D20: 649 | E20: 425 | F20: 283 | G20: 879 | H20: 104 | I20: 138 | J20: 347 | K20: 576 | L20: 566 | M20: 522 | N20: 0 | O20: 0 | P20: 4708
B21: Actual Output Qty | C21: 205 | D21: 624 | E21: 404 | F21: 264 | G21: 864 | H21: 96 | I21: 132 | J21: 325 | K21: 552 | L21: 540 | M21: 503 | N21: 0 | O21: 0 | P21: 4509
B22: Reject Qty | C22: 14 | D22: 25 | E22: 21 | F22: 19 | G22: 15 | H22: 8 | I22: 6 | J22: 22 | K22: 24 | L22: 26 | M22: 19 | N22: 0 | O22: 0 | P22: 199
B23: %Total Reject | C23: 0.063926941 | D23: 0.038520801 | E23: 0.049411765 | F23: 0.067137809 | G23: 0.017064846 | H23: 0.076923077 | I23: 0.043478261 | J23: 0.063400576 | K23: 0.041666667 | L23: 0.045936396 | M23: 0.036398467 | N23: 0 | O23: 0 | P23: 0.041835816
B24: %Effeceincy | C24: 0.38787076 | D24: 0.29914224 | E24: 0.42503906 | F24: 0.2290032 | G24: 0.53463529 | H24: 0.18571429 | I24: 0.213125 | J24: 0.58013503 | K24: 0.40258519 | L24: 0.13831967 | M24: 0.38362083 | N24: 0 | O24: 0 | P24: 0.34356278
A25: Friday | B25: LINE# | C25: A1 | D25: A2 | E25: A3 | F25: A4 | G25: A5 | H25: A6 | I25: A7 | J25: A8 | K25: A9 | L25: A10 | M25: A11 | N25: A21 | O25: SAMPLE LINE | P25: Total
B26: Inspect Qty | C26: 263 | D26: 681 | E26: 344 | F26: 268 | G26: 820 | H26: 104 | I26: 212 | J26: 472 | K26: 576 | L26: 849 | M26: 597 | N26: 0 | O26: 0 | P26: 5186
B27: Actual Output Qty | C27: 250 | D27: 648 | E27: 325 | F27: 252 | G27: 792 | H27: 96 | I27: 204 | J27: 440 | K27: 552 | L27: 820 | M27: 568 | N27: 0 | O27: 0 | P27: 4947
B28: Reject Qty | C28: 13 | D28: 33 | E28: 19 | F28: 16 | G28: 28 | H28: 8 | I28: 8 | J28: 32 | K28: 24 | L28: 29 | M28: 29 | N28: 0 | O28: 0 | P28: 239
B29: %Total Reject | C29: 0.049429658 | D29: 0.04845815 | E29: 0.055232558 | F29: 0.059701493 | G29: 0.034146341 | H29: 0.076923077 | I29: 0.037735849 | J29: 0.06779661 | K29: 0.041666667 | L29: 0.034157833 | M29: 0.048576214 | N29: 0 | O29: 0 | P29: 0.042601881
B30: %Effeceincy | C30: 0.45611979 | D30: 0.42367241 | E30: 0.38997538 | F30: 0.21551673 | G30: 0.46285556 | H30: 0.18571429 | I30: 0.2890625 | J30: 0.68032738 | K30: 0.37482069 | L30: 0.19428472 | M30: 0.36304063 | N30: 0 | O30: 0 | P30: 0.36685364
A31: Saturday | B31: LINE# | C31: A1 | D31: A2 | E31: A3 | F31: A4 | G31: A5 | H31: A6 | I31: A7 | J31: A8 | K31: A9 | L31: A10 | M31: A11 | N31: A21 | O31: SAMPLE LINE | P31: Total
B32: Inspect Qty | C32: 313 | D32: 711 | E32: 343 | F32: 508 | G32: 744 | H32: 117 | I32: 113 | J32: 450 | K32: 647 | L32: 995 | M32: 465 | N32: 0 | O32: 0 | P32: 5406
B33: Actual Output Qty | C33: 300 | D33: 678 | E33: 325 | F33: 480 | G33: 720 | H33: 108 | I33: 108 | J33: 425 | K33: 625 | L33: 960 | M33: 436 | N33: 0 | O33: 0 | P33: 5165
B34: Reject Qty | C34: 13 | D34: 33 | E34: 18 | F34: 28 | G34: 24 | H34: 9 | I34: 5 | J34: 25 | K34: 22 | L34: 35 | M34: 29 | N34: 0 | O34: 0 | P34: 241
B35: %Total Reject | C35: 0.041533546 | D35: 0.046413502 | E35: 0.052478134 | F35: 0.05511811 | G35: 0.032258065 | H35: 0.076923077 | I35: 0.044247788 | J35: 0.055555556 | K35: 0.034003091 | L35: 0.035175879 | M35: 0.062365591 | N35: 0 | O35: 0 | P35: 0.041236334
B36: %Effeceincy | C36: 0.54734375 | D36: 0.47639063 | E36: 0.38301153 | F36: 0.312125 | G36: 0.42077778 | H36: 0.20172414 | I36: 0.20172414 | J36: 0.7448447 | K36: 0.43125898 | L36: 0.25 | M36: 0.34040833 | N36: 0 | O36: 0 | P36: 0.39178263
